Workbook

Sheet INFO
A1: KETERSEDIAAN AIR 15 HARIAN TAHUN 2025 - Bubi (Outlet)
A3: DAS / proyek | B3: Bubi
A4: Elemen | B4: Outlet
A5: Luas tangkapan (km²) | B5: 320.4808
A6: Periode simulasi | B6: 2001-01-01 00:00 s/d 2026-01-01 00:00 (interval 1440 menit)
A7: Data debit harian | B7: 01-01-2001 s/d 31-12-2025 (9131 hari)
A8: Tahun lengkap (dipakai Weibull) | B8: 2001, 2002, 2003, 2004, 2005, 2006, 2007, 2008, 2009, 2010, 2011, 2012, 2013, 2014, 2015, 2016, 2017, 2018, 2019, 2020, 2021, 2022, 2023, 2024, 2025
A9: Syarat tahun lengkap | B9: setiap periode 15 harian punya minimal 10 hari data
A10: Tahun tidak lengkap | B10: -
A11: Hujan | B11: Hujan satelit terkalibrasi - Kalibrasi, pos Gabungan Thiessen (3 pos), Quantile mapping, mutu Lemah
A12: Dibuat | B12: 14-10-2026 21:42 - HEC-HMS DAS Analyzer, menu Simulasi
A14: Catatan
A15: - KETERSEDIAAN_2025: debit rata-rata tiap 15 harian tahun 2025 (periode I = tanggal 1-15, periode II = tanggal 16 s/d akhir bulan) dan volumenya, dibandingkan dengan debit andalan 15 harian.
A16: - Debit andalan (Q50/Q80/Q90) dari lembar WEIBULL_15HARIAN: debit 15 harian semua tahun lengkap diurutkan, P = m/(n+1) (Weibull), diinterpolasi linier.
A17: - Volume (juta m³) = debit rata-rata x jumlah hari periode x 86.400 / 1.000.000.
A18: - Tahun ini lengkap.
A19: - Semua angka turunan adalah rumus Excel yang merujuk lembar DEBIT_HARIAN (angka biru = hasil simulasi).

Sheet KETERSEDIAAN_2025
A1: KETERSEDIAAN AIR 15 HARIAN TAHUN 2025 - Outlet
A2: Bubi · luas tangkapan 320.48 km² · debit rata-rata periode dari debit harian hasil simulasi
A3: Tahun | C3: 2025
A5: No | B5: Bulan | C5: Periode | D5: Tanggal | E5: Jumlah hari | F5: Hari berdata | G5: Debit rata-rata (m³/s) | H5: Volume (juta m³) | I5: Q80 andalan (m³/s) | J5: Q50 (m³/s) | K5: Q90 (m³/s) | L5: Terhadap Q80 | N5: Label grafik
A6: 1 | B6: Januari | C6: I | D6: 1-15 | E6: 15 | F6: =COUNTIFS(DEBIT_HARIAN!$B$6:$B$9136,$C$3,DEBIT_HARIAN!$C$6:$C$9136,1,DEBIT_HARIAN!$E$6:$E$9136,1) | G6: =IFERROR(AVERAGEIFS(DEBIT_HARIAN!$F$6:$F$9136,DEBIT_HARIAN!$B$6:$B$9136,$C$3,DEBIT_HARIAN!$C$6:$C$9136,1,DEBIT_HARIAN!$E$6:$E$9136,1),"") | H6: =IF(G6="","",G6*E6*86400/1000000) | I6: =WEIBULL_15HARIAN!C$7 | J6: =WEIBULL_15HARIAN!C$6 | K6: =WEIBULL_15HARIAN!C$8 | L6: =IF(OR(G6="",I6=""),"",IF(G6>=I6,"di atas Q80","di bawah Q80")) | N6: Jan I
A7: 2 | B7: Januari | C7: II | D7: =16&"-"&DAY(DATE($C$3,1+1,0)) | E7: =DAY(DATE($C$3,1+1,0))-15 | F7: =COUNTIFS(DEBIT_HARIAN!$B$6:$B$9136,$C$3,DEBIT_HARIAN!$C$6:$C$9136,1,DEBIT_HARIAN!$E$6:$E$9136,2) | G7: =IFERROR(AVERAGEIFS(DEBIT_HARIAN!$F$6:$F$9136,DEBIT_HARIAN!$B$6:$B$9136,$C$3,DEBIT_HARIAN!$C$6:$C$9136,1,DEBIT_HARIAN!$E$6:$E$9136,2),"") | H7: =IF(G7="","",G7*E7*86400/1000000) | I7: =WEIBULL_15HARIAN!D$7 | J7: =WEIBULL_15HARIAN!D$6 | K7: =WEIBULL_15HARIAN!D$8 | L7: =IF(OR(G7="",I7=""),"",IF(G7>=I7,"di atas Q80","di bawah Q80")) | N7: Jan II
A8: 3 | B8: Februari | C8: I | D8: 1-15 | E8: 15 | F8: =COUNTIFS(DEBIT_HARIAN!$B$6:$B$9136,$C$3,DEBIT_HARIAN!$C$6:$C$9136,2,DEBIT_HARIAN!$E$6:$E$9136,1) | G8: =IFERROR(AVERAGEIFS(DEBIT_HARIAN!$F$6:$F$9136,DEBIT_HARIAN!$B$6:$B$9136,$C$3,DEBIT_HARIAN!$C$6:$C$9136,2,DEBIT_HARIAN!$E$6:$E$9136,1),"") | H8: =IF(G8="","",G8*E8*86400/1000000) | I8: =WEIBULL_15HARIAN!E$7 | J8: =WEIBULL_15HARIAN!E$6 | K8: =WEIBULL_15HARIAN!E$8 | L8: =IF(OR(G8="",I8=""),"",IF(G8>=I8,"di atas Q80","di bawah Q80")) | N8: Feb I
A9: 4 | B9: Februari | C9: II | D9: =16&"-"&DAY(DATE($C$3,2+1,0)) | E9: =DAY(DATE($C$3,2+1,0))-15 | F9: =COUNTIFS(DEBIT_HARIAN!$B$6:$B$9136,$C$3,DEBIT_HARIAN!$C$6:$C$9136,2,DEBIT_HARIAN!$E$6:$E$9136,2) | G9: =IFERROR(AVERAGEIFS(DEBIT_HARIAN!$F$6:$F$9136,DEBIT_HARIAN!$B$6:$B$9136,$C$3,DEBIT_HARIAN!$C$6:$C$9136,2,DEBIT_HARIAN!$E$6:$E$9136,2),"") | H9: =IF(G9="","",G9*E9*86400/1000000) | I9: =WEIBULL_15HARIAN!F$7 | J9: =WEIBULL_15HARIAN!F$6 | K9: =WEIBULL_15HARIAN!F$8 | L9: =IF(OR(G9="",I9=""),"",IF(G9>=I9,"di atas Q80","di bawah Q80")) | N9: Feb II
A10: 5 | B10: Maret | C10: I | D10: 1-15 | E10: 15 | F10: =COUNTIFS(DEBIT_HARIAN!$B$6:$B$9136,$C$3,DEBIT_HARIAN!$C$6:$C$9136,3,DEBIT_HARIAN!$E$6:$E$9136,1) | G10: =IFERROR(AVERAGEIFS(DEBIT_HARIAN!$F$6:$F$9136,DEBIT_HARIAN!$B$6:$B$9136,$C$3,DEBIT_HARIAN!$C$6:$C$9136,3,DEBIT_HARIAN!$E$6:$E$9136,1),"") | H10: =IF(G10="","",G10*E10*86400/1000000) | I10: =WEIBULL_15HARIAN!G$7 | J10: =WEIBULL_15HARIAN!G$6 | K10: =WEIBULL_15HARIAN!G$8 | L10: =IF(OR(G10="",I10=""),"",IF(G10>=I10,"di atas Q80","di bawah Q80")) | N10: Mar I
A11: 6 | B11: Maret | C11: II | D11: =16&"-"&DAY(DATE($C$3,3+1,0)) | E11: =DAY(DATE($C$3,3+1,0))-15 | F11: =COUNTIFS(DEBIT_HARIAN!$B$6:$B$9136,$C$3,DEBIT_HARIAN!$C$6:$C$9136,3,DEBIT_HARIAN!$E$6:$E$9136,2) | G11: =IFERROR(AVERAGEIFS(DEBIT_HARIAN!$F$6:$F$9136,DEBIT_HARIAN!$B$6:$B$9136,$C$3,DEBIT_HARIAN!$C$6:$C$9136,3,DEBIT_HARIAN!$E$6:$E$9136,2),"") | H11: =IF(G11="","",G11*E11*86400/1000000) | I11: =WEIBULL_15HARIAN!H$7 | J11: =WEIBULL_15HARIAN!H$6 | K11: =WEIBULL_15HARIAN!H$8 | L11: =IF(OR(G11="",I11=""),"",IF(G11>=I11,"di atas Q80","di bawah Q80")) | N11: Mar II
A12: 7 | B12: April | C12: I | D12: 1-15 | E12: 15 | F12: =COUNTIFS(DEBIT_HARIAN!$B$6:$B$9136,$C$3,DEBIT_HARIAN!$C$6:$C$9136,4,DEBIT_HARIAN!$E$6:$E$9136,1) | G12: =IFERROR(AVERAGEIFS(DEBIT_HARIAN!$F$6:$F$9136,DEBIT_HARIAN!$B$6:$B$9136,$C$3,DEBIT_HARIAN!$C$6:$C$9136,4,DEBIT_HARIAN!$E$6:$E$9136,1),"") | H12: =IF(G12="","",G12*E12*86400/1000000) | I12: =WEIBULL_15HARIAN!I$7 | J12: =WEIBULL_15HARIAN!I$6 | K12: =WEIBULL_15HARIAN!I$8 | L12: =IF(OR(G12="",I12=""),"",IF(G12>=I12,"di atas Q80","di bawah Q80")) | N12: Apr I
A13: 8 | B13: April | C13: II | D13: =16&"-"&DAY(DATE($C$3,4+1,0)) | E13: =DAY(DATE($C$3,4+1,0))-15 | F13: =COUNTIFS(DEBIT_HARIAN!$B$6:$B$9136,$C$3,DEBIT_HARIAN!$C$6:$C$9136,4,DEBIT_HARIAN!$E$6:$E$9136,2) | G13: =IFERROR(AVERAGEIFS(DEBIT_HARIAN!$F$6:$F$9136,DEBIT_HARIAN!$B$6:$B$9136,$C$3,DEBIT_HARIAN!$C$6:$C$9136,4,DEBIT_HARIAN!$E$6:$E$9136,2),"") | H13: =IF(G13="","",G13*E13*86400/1000000) | I13: =WEIBULL_15HARIAN!J$7 | J13: =WEIBULL_15HARIAN!J$6 | K13: =WEIBULL_15HARIAN!J$8 | L13: =IF(OR(G13="",I13=""),"",IF(G13>=I13,"di atas Q80","di bawah Q80")) | N13: Apr II
A14: 9 | B14: Mei | C14: I | D14: 1-15 | E14: 15 | F14: =COUNTIFS(DEBIT_HARIAN!$B$6:$B$9136,$C$3,DEBIT_HARIAN!$C$6:$C$9136,5,DEBIT_HARIAN!$E$6:$E$9136,1) | G14: =IFERROR(AVERAGEIFS(DEBIT_HARIAN!$F$6:$F$9136,DEBIT_HARIAN!$B$6:$B$9136,$C$3,DEBIT_HARIAN!$C$6:$C$9136,5,DEBIT_HARIAN!$E$6:$E$9136,1),"") | H14: =IF(G14="","",G14*E14*86400/1000000) | I14: =WEIBULL_15HARIAN!K$7 | J14: =WEIBULL_15HARIAN!K$6 | K14: =WEIBULL_15HARIAN!K$8 | L14: =IF(OR(G14="",I14=""),"",IF(G14>=I14,"di atas Q80","di bawah Q80")) | N14: Mei I
A15: 10 | B15: Mei | C15: II | D15: =16&"-"&DAY(DATE($C$3,5+1,0)) | E15: =DAY(DATE($C$3,5+1,0))-15 | F15: =COUNTIFS(DEBIT_HARIAN!$B$6:$B$9136,$C$3,DEBIT_HARIAN!$C$6:$C$9136,5,DEBIT_HARIAN!$E$6:$E$9136,2) | G15: =IFERROR(AVERAGEIFS(DEBIT_HARIAN!$F$6:$F$9136,DEBIT_HARIAN!$B$6:$B$9136,$C$3,DEBIT_HARIAN!$C$6:$C$9136,5,DEBIT_HARIAN!$E$6:$E$9136,2),"") | H15: =IF(G15="","",G15*E15*86400/1000000) | I15: =WEIBULL_15HARIAN!L$7 | J15: =WEIBULL_15HARIAN!L$6 | K15: =WEIBULL_15HARIAN!L$8 | L15: =IF(OR(G15="",I15=""),"",IF(G15>=I15,"di atas Q80","di bawah Q80")) | N15: Mei II
A16: 11 | B16: Juni | C16: I | D16: 1-15 | E16: 15 | F16: =COUNTIFS(DEBIT_HARIAN!$B$6:$B$9136,$C$3,DEBIT_HARIAN!$C$6:$C$9136,6,DEBIT_HARIAN!$E$6:$E$9136,1) | G16: =IFERROR(AVERAGEIFS(DEBIT_HARIAN!$F$6:$F$9136,DEBIT_HARIAN!$B$6:$B$9136,$C$3,DEBIT_HARIAN!$C$6:$C$9136,6,DEBIT_HARIAN!$E$6:$E$9136,1),"") | H16: =IF(G16="","",G16*E16*86400/1000000) | I16: =WEIBULL_15HARIAN!M$7 | J16: =WEIBULL_15HARIAN!M$6 | K16: =WEIBULL_15HARIAN!M$8 | L16: =IF(OR(G16="",I16=""),"",IF(G16>=I16,"di atas Q80","di bawah Q80")) | N16: Jun I
A17: 12 | B17: Juni | C17: II | D17: =16&"-"&DAY(DATE($C$3,6+1,0)) | E17: =DAY(DATE($C$3,6+1,0))-15 | F17: =COUNTIFS(DEBIT_HARIAN!$B$6:$B$9136,$C$3,DEBIT_HARIAN!$C$6:$C$9136,6,DEBIT_HARIAN!$E$6:$E$9136,2) | G17: =IFERROR(AVERAGEIFS(DEBIT_HARIAN!$F$6:$F$9136,DEBIT_HARIAN!$B$6:$B$9136,$C$3,DEBIT_HARIAN!$C$6:$C$9136,6,DEBIT_HARIAN!$E$6:$E$9136,2),"") | H17: =IF(G17="","",G17*E17*86400/1000000) | I17: =WEIBULL_15HARIAN!N$7 | J17: =WEIBULL_15HARIAN!N$6 | K17: =WEIBULL_15HARIAN!N$8 | L17: =IF(OR(G17="",I17=""),"",IF(G17>=I17,"di atas Q80","di bawah Q80")) | N17: Jun II
A18: 13 | B18: Juli | C18: I | D18: 1-15 | E18: 15 | F18: =COUNTIFS(DEBIT_HARIAN!$B$6:$B$9136,$C$3,DEBIT_HARIAN!$C$6:$C$9136,7,DEBIT_HARIAN!$E$6:$E$9136,1) | G18: =IFERROR(AVERAGEIFS(DEBIT_HARIAN!$F$6:$F$9136,DEBIT_HARIAN!$B$6:$B$9136,$C$3,DEBIT_HARIAN!$C$6:$C$9136,7,DEBIT_HARIAN!$E$6:$E$9136,1),"") | H18: =IF(G18="","",G18*E18*86400/1000000) | I18: =WEIBULL_15HARIAN!O$7 | J18: =WEIBULL_15HARIAN!O$6 | K18: =WEIBULL_15HARIAN!O$8 | L18: =IF(OR(G18="",I18=""),"",IF(G18>=I18,"di atas Q80","di bawah Q80")) | N18: Jul I
A19: 14 | B19: Juli | C19: II | D19: =16&"-"&DAY(DATE($C$3,7+1,0)) | E19: =DAY(DATE($C$3,7+1,0))-15 | F19: =COUNTIFS(DEBIT_HARIAN!$B$6:$B$9136,$C$3,DEBIT_HARIAN!$C$6:$C$9136,7,DEBIT_HARIAN!$E$6:$E$9136,2) | G19: =IFERROR(AVERAGEIFS(DEBIT_HARIAN!$F$6:$F$9136,DEBIT_HARIAN!$B$6:$B$9136,$C$3,DEBIT_HARIAN!$C$6:$C$9136,7,DEBIT_HARIAN!$E$6:$E$9136,2),"") | H19: =IF(G19="","",G19*E19*86400/1000000) | I19: =WEIBULL_15HARIAN!P$7 | J19: =WEIBULL_15HARIAN!P$6 | K19: =WEIBULL_15HARIAN!P$8 | L19: =IF(OR(G19="",I19=""),"",IF(G19>=I19,"di atas Q80","di bawah Q80")) | N19: Jul II
A20: 15 | B20: Agustus | C20: I | D20: 1-15 | E20: 15 | F20: =COUNTIFS(DEBIT_HARIAN!$B$6:$B$9136,$C$3,DEBIT_HARIAN!$C$6:$C$9136,8,DEBIT_HARIAN!$E$6:$E$9136,1) | G20: =IFERROR(AVERAGEIFS(DEBIT_HARIAN!$F$6:$F$9136,DEBIT_HARIAN!$B$6:$B$9136,$C$3,DEBIT_HARIAN!$C$6:$C$9136,8,DEBIT_HARIAN!$E$6:$E$9136,1),"") | H20: =IF(G20="","",G20*E20*86400/1000000) | I20: =WEIBULL_15HARIAN!Q$7 | J20: =WEIBULL_15HARIAN!Q$6 | K20: =WEIBULL_15HARIAN!Q$8 | L20: =IF(OR(G20="",I20=""),"",IF(G20>=I20,"di atas Q80","di bawah Q80")) | N20: Agu I
A21: 16 | B21: Agustus | C21: II | D21: =16&"-"&DAY(DATE($C$3,8+1,0)) | E21: =DAY(DATE($C$3,8+1,0))-15 | F21: =COUNTIFS(DEBIT_HARIAN!$B$6:$B$9136,$C$3,DEBIT_HARIAN!$C$6:$C$9136,8,DEBIT_HARIAN!$E$6:$E$9136,2) | G21: =IFERROR(AVERAGEIFS(DEBIT_HARIAN!$F$6:$F$9136,DEBIT_HARIAN!$B$6:$B$9136,$C$3,DEBIT_HARIAN!$C$6:$C$9136,8,DEBIT_HARIAN!$E$6:$E$9136,2),"") | H21: =IF(G21="","",G21*E21*86400/1000000) | I21: =WEIBULL_15HARIAN!R$7 | J21: =WEIBULL_15HARIAN!R$6 | K21: =WEIBULL_15HARIAN!R$8 | L21: =IF(OR(G21="",I21=""),"",IF(G21>=I21,"di atas Q80","di bawah Q80")) | N21: Agu II
A22: 17 | B22: September | C22: I | D22: 1-15 | E22: 15 | F22: =COUNTIFS(DEBIT_HARIAN!$B$6:$B$9136,$C$3,DEBIT_HARIAN!$C$6:$C$9136,9,DEBIT_HARIAN!$E$6:$E$9136,1) | G22: =IFERROR(AVERAGEIFS(DEBIT_HARIAN!$F$6:$F$9136,DEBIT_HARIAN!$B$6:$B$9136,$C$3,DEBIT_HARIAN!$C$6:$C$9136,9,DEBIT_HARIAN!$E$6:$E$9136,1),"") | H22: =IF(G22="","",G22*E22*86400/1000000) | I22: =WEIBULL_15HARIAN!S$7 | J22: =WEIBULL_15HARIAN!S$6 | K22: =WEIBULL_15HARIAN!S$8 | L22: =IF(OR(G22="",I22=""),"",IF(G22>=I22,"di atas Q80","di bawah Q80")) | N22: Sep I
A23: 18 | B23: September | C23: II | D23: =16&"-"&DAY(DATE($C$3,9+1,0)) | E23: =DAY(DATE($C$3,9+1,0))-15 | F23: =COUNTIFS(DEBIT_HARIAN!$B$6:$B$9136,$C$3,DEBIT_HARIAN!$C$6:$C$9136,9,DEBIT_HARIAN!$E$6:$E$9136,2) | G23: =IFERROR(AVERAGEIFS(DEBIT_HARIAN!$F$6:$F$9136,DEBIT_HARIAN!$B$6:$B$9136,$C$3,DEBIT_HARIAN!$C$6:$C$9136,9,DEBIT_HARIAN!$E$6:$E$9136,2),"") | H23: =IF(G23="","",G23*E23*86400/1000000) | I23: =WEIBULL_15HARIAN!T$7 | J23: =WEIBULL_15HARIAN!T$6 | K23: =WEIBULL_15HARIAN!T$8 | L23: =IF(OR(G23="",I23=""),"",IF(G23>=I23,"di atas Q80","di bawah Q80")) | N23: Sep II
A24: 19 | B24: Oktober | C24: I | D24: 1-15 | E24: 15 | F24: =COUNTIFS(DEBIT_HARIAN!$B$6:$B$9136,$C$3,DEBIT_HARIAN!$C$6:$C$9136,10,DEBIT_HARIAN!$E$6:$E$9136,1) | G24: =IFERROR(AVERAGEIFS(DEBIT_HARIAN!$F$6:$F$9136,DEBIT_HARIAN!$B$6:$B$9136,$C$3,DEBIT_HARIAN!$C$6:$C$9136,10,DEBIT_HARIAN!$E$6:$E$9136,1),"") | H24: =IF(G24="","",G24*E24*86400/1000000) | I24: =WEIBULL_15HARIAN!U$7 | J24: =WEIBULL_15HARIAN!U$6 | K24: =WEIBULL_15HARIAN!U$8 | L24: =IF(OR(G24="",I24=""),"",IF(G24>=I24,"di atas Q80","di bawah Q80")) | N24: Okt I
A25: 20 | B25: Oktober | C25: II | D25: =16&"-"&DAY(DATE($C$3,10+1,0)) | E25: =DAY(DATE($C$3,10+1,0))-15 | F25: =COUNTIFS(DEBIT_HARIAN!$B$6:$B$9136,$C$3,DEBIT_HARIAN!$C$6:$C$9136,10,DEBIT_HARIAN!$E$6:$E$9136,2) | G25: =IFERROR(AVERAGEIFS(DEBIT_HARIAN!$F$6:$F$9136,DEBIT_HARIAN!$B$6:$B$9136,$C$3,DEBIT_HARIAN!$C$6:$C$9136,10,DEBIT_HARIAN!$E$6:$E$9136,2),"") | H25: =IF(G25="","",G25*E25*86400/1000000) | I25: =WEIBULL_15HARIAN!V$7 | J25: =WEIBULL_15HARIAN!V$6 | K25: =WEIBULL_15HARIAN!V$8 | L25: =IF(OR(G25="",I25=""),"",IF(G25>=I25,"di atas Q80","di bawah Q80")) | N25: Okt II
A26: 21 | B26: November | C26: I | D26: 1-15 | E26: 15 | F26: =COUNTIFS(DEBIT_HARIAN!$B$6:$B$9136,$C$3,DEBIT_HARIAN!$C$6:$C$9136,11,DEBIT_HARIAN!$E$6:$E$9136,1) | G26: =IFERROR(AVERAGEIFS(DEBIT_HARIAN!$F$6:$F$9136,DEBIT_HARIAN!$B$6:$B$9136,$C$3,DEBIT_HARIAN!$C$6:$C$9136,11,DEBIT_HARIAN!$E$6:$E$9136,1),"") | H26: =IF(G26="","",G26*E26*86400/1000000) | I26: =WEIBULL_15HARIAN!W$7 | J26: =WEIBULL_15HARIAN!W$6 | K26: =WEIBULL_15HARIAN!W$8 | L26: =IF(OR(G26="",I26=""),"",IF(G26>=I26,"di atas Q80","di bawah Q80")) | N26: Nov I
A27: 22 | B27: November | C27: II | D27: =16&"-"&DAY(DATE($C$3,11+1,0)) | E27: =DAY(DATE($C$3,11+1,0))-15 | F27: =COUNTIFS(DEBIT_HARIAN!$B$6:$B$9136,$C$3,DEBIT_HARIAN!$C$6:$C$9136,11,DEBIT_HARIAN!$E$6:$E$9136,2) | G27: =IFERROR(AVERAGEIFS(DEBIT_HARIAN!$F$6:$F$9136,DEBIT_HARIAN!$B$6:$B$9136,$C$3,DEBIT_HARIAN!$C$6:$C$9136,11,DEBIT_HARIAN!$E$6:$E$9136,2),"") | H27: =IF(G27="","",G27*E27*86400/1000000) | I27: =WEIBULL_15HARIAN!X$7 | J27: =WEIBULL_15HARIAN!X$6 | K27: =WEIBULL_15HARIAN!X$8 | L27: =IF(OR(G27="",I27=""),"",IF(G27>=I27,"di atas Q80","di bawah Q80")) | N27: Nov II
A28: 23 | B28: Desember | C28: I | D28: 1-15 | E28: 15 | F28: =COUNTIFS(DEBIT_HARIAN!$B$6:$B$9136,$C$3,DEBIT_HARIAN!$C$6:$C$9136,12,DEBIT_HARIAN!$E$6:$E$9136,1) | G28: =IFERROR(AVERAGEIFS(DEBIT_HARIAN!$F$6:$F$9136,DEBIT_HARIAN!$B$6:$B$9136,$C$3,DEBIT_HARIAN!$C$6:$C$9136,12,DEBIT_HARIAN!$E$6:$E$9136,1),"") | H28: =IF(G28="","",G28*E28*86400/1000000) | I28: =WEIBULL_15HARIAN!Y$7 | J28: =WEIBULL_15HARIAN!Y$6 | K28: =WEIBULL_15HARIAN!Y$8 | L28: =IF(OR(G28="",I28=""),"",IF(G28>=I28,"di atas Q80","di bawah Q80")) | N28: Des I
A29: 24 | B29: Desember | C29: II | D29: =16&"-"&DAY(DATE($C$3,12+1,0)) | E29: =DAY(DATE($C$3,12+1,0))-15 | F29: =COUNTIFS(DEBIT_HARIAN!$B$6:$B$9136,$C$3,DEBIT_HARIAN!$C$6:$C$9136,12,DEBIT_HARIAN!$E$6:$E$9136,2) | G29: =IFERROR(AVERAGEIFS(DEBIT_HARIAN!$F$6:$F$9136,DEBIT_HARIAN!$B$6:$B$9136,$C$3,DEBIT_HARIAN!$C$6:$C$9136,12,DEBIT_HARIAN!$E$6:$E$9136,2),"") | H29: =IF(G29="","",G29*E29*86400/1000000) | I29: =WEIBULL_15HARIAN!Z$7 | J29: =WEIBULL_15HARIAN!Z$6 | K29: =WEIBULL_15HARIAN!Z$8 | L29: =IF(OR(G29="",I29=""),"",IF(G29>=I29,"di atas Q80","di bawah Q80")) | N29: Des II
B30: Tahun 2025 | E30: =SUM(E6:E29) | F30: =SUM(F6:F29) | G30: =IFERROR(AVERAGEIFS(DEBIT_HARIAN!$F$6:$F$9136,DEBIT_HARIAN!$B$6:$B$9136,$C$3),"") | H30: =SUM(H6:H29) | L30: =IF(COUNT(G6:G29)=0,"",COUNTIF(L6:L29,"di atas Q80")&" dari "&COUNT(G6:G29)&" periode di atas Q80")
A31: Baris jumlah: debit = rata-rata debit harian setahun; volume = jumlah volume 24 periode. Ubah sel C3 untuk menampilkan tahun lain yang ada di DEBIT_HARIAN.

Sheet WEIBULL_15HARIAN
A1: DEBIT ANDALAN 15 HARIAN (WEIBULL) - Outlet
A2: Debit rata-rata 15 harian tiap tahun lengkap diurutkan dari terbesar; peluang terlampaui P = m / (n + 1) (Weibull). Q-P diinterpolasi linier antar peringkat.
A3: Jumlah tahun lengkap (n) | C3: =COUNT(DEBIT_15HARIAN!$A$7:$A$31)
A5: Debit andalan | B5: Peluang P | C5: Jan I | D5: Jan II | E5: Feb I | F5: Feb II | G5: Mar I | H5: Mar II | I5: Apr I | J5: Apr II | K5: Mei I | L5: Mei II | M5: Jun I | N5: Jun II | O5: Jul I | P5: Jul II | Q5: Agu I | R5: Agu II | S5: Sep I | T5: Sep II | U5: Okt I | V5: Okt II | W5: Nov I | X5: Nov II | Y5: Des I | Z5: Des II
A6: Q50 (m³/s) | B6: 0.5 | C6: =IF($C$3<1,"",IF(INT($B6*($C$3+1))<1,LARGE(DEBIT_15HARIAN!$B$7:$B$31,1),IF(INT($B6*($C$3+1))>=$C$3,LARGE(DEBIT_15HARIAN!$B$7:$B$31,$C$3),LARGE(DEBIT_15HARIAN!$B$7:$B$31,INT($B6*($C$3+1)))+($B6*($C$3+1)-INT($B6*($C$3+1)))*(LARGE(DEBIT_15HARIAN!$B$7:$B$31,INT($B6*($C$3+1))+1)-LARGE(DEBIT_15HARIAN!$B$7:$B$31,INT($B6*($C$3+1))))))) | D6: =IF($C$3<1,"",IF(INT($B6*($C$3+1))<1,LARGE(DEBIT_15HARIAN!$C$7:$C$31,1),IF(INT($B6*($C$3+1))>=$C$3,LARGE(DEBIT_15HARIAN!$C$7:$C$31,$C$3),LARGE(DEBIT_15HARIAN!$C$7:$C$31,INT($B6*($C$3+1)))+($B6*($C$3+1)-INT($B6*($C$3+1)))*(LARGE(DEBIT_15HARIAN!$C$7:$C$31,INT($B6*($C$3+1))+1)-LARGE(DEBIT_15HARIAN!$C$7:$C$31,INT($B6*($C$3+1))))))) | E6: =IF($C$3<1,"",IF(INT($B6*($C$3+1))<1,LARGE(DEBIT_15HARIAN!$D$7:$D$31,1),IF(INT($B6*($C$3+1))>=$C$3,LARGE(DEBIT_15HARIAN!$D$7:$D$31,$C$3),LARGE(DEBIT_15HARIAN!$D$7:$D$31,INT($B6*($C$3+1)))+($B6*($C$3+1)-INT($B6*($C$3+1)))*(LARGE(DEBIT_15HARIAN!$D$7:$D$31,INT($B6*($C$3+1))+1)-LARGE(DEBIT_15HARIAN!$D$7:$D$31,INT($B6*($C$3+1))))))) | F6: =IF($C$3<1,"",IF(INT($B6*($C$3+1))<1,LARGE(DEBIT_15HARIAN!$E$7:$E$31,1),IF(INT($B6*($C$3+1))>=$C$3,LARGE(DEBIT_15HARIAN!$E$7:$E$31,$C$3),LARGE(DEBIT_15HARIAN!$E$7:$E$31,INT($B6*($C$3+1)))+($B6*($C$3+1)-INT($B6*($C$3+1)))*(LARGE(DEBIT_15HARIAN!$E$7:$E$31,INT($B6*($C$3+1))+1)-LARGE(DEBIT_15HARIAN!$E$7:$E$31,INT($B6*($C$3+1))))))) | G6: =IF($C$3<1,"",IF(INT($B6*($C$3+1))<1,LARGE(DEBIT_15HARIAN!$F$7:$F$31,1),IF(INT($B6*($C$3+1))>=$C$3,LARGE(DEBIT_15HARIAN!$F$7:$F$31,$C$3),LARGE(DEBIT_15HARIAN!$F$7:$F$31,INT($B6*($C$3+1)))+($B6*($C$3+1)-INT($B6*($C$3+1)))*(LARGE(DEBIT_15HARIAN!$F$7:$F$31,INT($B6*($C$3+1))+1)-LARGE(DEBIT_15HARIAN!$F$7:$F$31,INT($B6*($C$3+1))))))) | H6: =IF($C$3<1,"",IF(INT($B6*($C$3+1))<1,LARGE(DEBIT_15HARIAN!$G$7:$G$31,1),IF(INT($B6*($C$3+1))>=$C$3,LARGE(DEBIT_15HARIAN!$G$7:$G$31,$C$3),LARGE(DEBIT_15HARIAN!$G$7:$G$31,INT($B6*($C$3+1)))+($B6*($C$3+1)-INT($B6*($C$3+1)))*(LARGE(DEBIT_15HARIAN!$G$7:$G$31,INT($B6*($C$3+1))+1)-LARGE(DEBIT_15HARIAN!$G$7:$G$31,INT($B6*($C$3+1))))))) | I6: =IF($C$3<1,"",IF(INT($B6*($C$3+1))<1,LARGE(DEBIT_15HARIAN!$H$7:$H$31,1),IF(INT($B6*($C$3+1))>=$C$3,LARGE(DEBIT_15HARIAN!$H$7:$H$31,$C$3),LARGE(DEBIT_15HARIAN!$H$7:$H$31,INT($B6*($C$3+1)))+($B6*($C$3+1)-INT($B6*($C$3+1)))*(LARGE(DEBIT_15HARIAN!$H$7:$H$31,INT($B6*($C$3+1))+1)-LARGE(DEBIT_15HARIAN!$H$7:$H$31,INT($B6*($C$3+1))))))) | J6: =IF($C$3<1,"",IF(INT($B6*($C$3+1))<1,LARGE(DEBIT_15HARIAN!$I$7:$I$31,1),IF(INT($B6*($C$3+1))>=$C$3,LARGE(DEBIT_15HARIAN!$I$7:$I$31,$C$3),LARGE(DEBIT_15HARIAN!$I$7:$I$31,INT($B6*($C$3+1)))+($B6*($C$3+1)-INT($B6*($C$3+1)))*(LARGE(DEBIT_15HARIAN!$I$7:$I$31,INT($B6*($C$3+1))+1)-LARGE(DEBIT_15HARIAN!$I$7:$I$31,INT($B6*($C$3+1))))))) | K6: =IF($C$3<1,"",IF(INT($B6*($C$3+1))<1,LARGE(DEBIT_15HARIAN!$J$7:$J$31,1),IF(INT($B6*($C$3+1))>=$C$3,LARGE(DEBIT_15HARIAN!$J$7:$J$31,$C$3),LARGE(DEBIT_15HARIAN!$J$7:$J$31,INT($B6*($C$3+1)))+($B6*($C$3+1)-INT($B6*($C$3+1)))*(LARGE(DEBIT_15HARIAN!$J$7:$J$31,INT($B6*($C$3+1))+1)-LARGE(DEBIT_15HARIAN!$J$7:$J$31,INT($B6*($C$3+1))))))) | L6: =IF($C$3<1,"",IF(INT($B6*($C$3+1))<1,LARGE(DEBIT_15HARIAN!$K$7:$K$31,1),IF(INT($B6*($C$3+1))>=$C$3,LARGE(DEBIT_15HARIAN!$K$7:$K$31,$C$3),LARGE(DEBIT_15HARIAN!$K$7:$K$31,INT($B6*($C$3+1)))+($B6*($C$3+1)-INT($B6*($C$3+1)))*(LARGE(DEBIT_15HARIAN!$K$7:$K$31,INT($B6*($C$3+1))+1)-LARGE(DEBIT_15HARIAN!$K$7:$K$31,INT($B6*($C$3+1))))))) | M6: =IF($C$3<1,"",IF(INT($B6*($C$3+1))<1,LARGE(DEBIT_15HARIAN!$L$7:$L$31,1),IF(INT($B6*($C$3+1))>=$C$3,LARGE(DEBIT_15HARIAN!$L$7:$L$31,$C$3),LARGE(DEBIT_15HARIAN!$L$7:$L$31,INT($B6*($C$3+1)))+($B6*($C$3+1)-INT($B6*($C$3+1)))*(LARGE(DEBIT_15HARIAN!$L$7:$L$31,INT($B6*($C$3+1))+1)-LARGE(DEBIT_15HARIAN!$L$7:$L$31,INT($B6*($C$3+1))))))) | N6: =IF($C$3<1,"",IF(INT($B6*($C$3+1))<1,LARGE(DEBIT_15HARIAN!$M$7:$M$31,1),IF(INT($B6*($C$3+1))>=$C$3,LARGE(DEBIT_15HARIAN!$M$7:$M$31,$C$3),LARGE(DEBIT_15HARIAN!$M$7:$M$31,INT($B6*($C$3+1)))+($B6*($C$3+1)-INT($B6*($C$3+1)))*(LARGE(DEBIT_15HARIAN!$M$7:$M$31,INT($B6*($C$3+1))+1)-LARGE(DEBIT_15HARIAN!$M$7:$M$31,INT($B6*($C$3+1))))))) | O6: =IF($C$3<1,"",IF(INT($B6*($C$3+1))<1,LARGE(DEBIT_15HARIAN!$N$7:$N$31,1),IF(INT($B6*($C$3+1))>=$C$3,LARGE(DEBIT_15HARIAN!$N$7:$N$31,$C$3),LARGE(DEBIT_15HARIAN!$N$7:$N$31,INT($B6*($C$3+1)))+($B6*($C$3+1)-INT($B6*($C$3+1)))*(LARGE(DEBIT_15HARIAN!$N$7:$N$31,INT($B6*($C$3+1))+1)-LARGE(DEBIT_15HARIAN!$N$7:$N$31,INT($B6*($C$3+1))))))) | P6: =IF($C$3<1,"",IF(INT($B6*($C$3+1))<1,LARGE(DEBIT_15HARIAN!$O$7:$O$31,1),IF(INT($B6*($C$3+1))>=$C$3,LARGE(DEBIT_15HARIAN!$O$7:$O$31,$C$3),LARGE(DEBIT_15HARIAN!$O$7:$O$31,INT($B6*($C$3+1)))+($B6*($C$3+1)-INT($B6*($C$3+1)))*(LARGE(DEBIT_15HARIAN!$O$7:$O$31,INT($B6*($C$3+1))+1)-LARGE(DEBIT_15HARIAN!$O$7:$O$31,INT($B6*($C$3+1))))))) | Q6: =IF($C$3<1,"",IF(INT($B6*($C$3+1))<1,LARGE(DEBIT_15HARIAN!$P$7:$P$31,1),IF(INT($B6*($C$3+1))>=$C$3,LARGE(DEBIT_15HARIAN!$P$7:$P$31,$C$3),LARGE(DEBIT_15HARIAN!$P$7:$P$31,INT($B6*($C$3+1)))+($B6*($C$3+1)-INT($B6*($C$3+1)))*(LARGE(DEBIT_15HARIAN!$P$7:$P$31,INT($B6*($C$3+1))+1)-LARGE(DEBIT_15HARIAN!$P$7:$P$31,INT($B6*($C$3+1))))))) | R6: =IF($C$3<1,"",IF(INT($B6*($C$3+1))<1,LARGE(DEBIT_15HARIAN!$Q$7:$Q$31,1),IF(INT($B6*($C$3+1))>=$C$3,LARGE(DEBIT_15HARIAN!$Q$7:$Q$31,$C$3),LARGE(DEBIT_15HARIAN!$Q$7:$Q$31,INT($B6*($C$3+1)))+($B6*($C$3+1)-INT($B6*($C$3+1)))*(LARGE(DEBIT_15HARIAN!$Q$7:$Q$31,INT($B6*($C$3+1))+1)-LARGE(DEBIT_15HARIAN!$Q$7:$Q$31,INT($B6*($C$3+1))))))) | S6: =IF($C$3<1,"",IF(INT($B6*($C$3+1))<1,LARGE(DEBIT_15HARIAN!$R$7:$R$31,1),IF(INT($B6*($C$3+1))>=$C$3,LARGE(DEBIT_15HARIAN!$R$7:$R$31,$C$3),LARGE(DEBIT_15HARIAN!$R$7:$R$31,INT($B6*($C$3+1)))+($B6*($C$3+1)-INT($B6*($C$3+1)))*(LARGE(DEBIT_15HARIAN!$R$7:$R$31,INT($B6*($C$3+1))+1)-LARGE(DEBIT_15HARIAN!$R$7:$R$31,INT($B6*($C$3+1))))))) | T6: =IF($C$3<1,"",IF(INT($B6*($C$3+1))<1,LARGE(DEBIT_15HARIAN!$S$7:$S$31,1),IF(INT($B6*($C$3+1))>=$C$3,LARGE(DEBIT_15HARIAN!$S$7:$S$31,$C$3),LARGE(DEBIT_15HARIAN!$S$7:$S$31,INT($B6*($C$3+1)))+($B6*($C$3+1)-INT($B6*($C$3+1)))*(LARGE(DEBIT_15HARIAN!$S$7:$S$31,INT($B6*($C$3+1))+1)-LARGE(DEBIT_15HARIAN!$S$7:$S$31,INT($B6*($C$3+1))))))) | U6: =IF($C$3<1,"",IF(INT($B6*($C$3+1))<1,LARGE(DEBIT_15HARIAN!$T$7:$T$31,1),IF(INT($B6*($C$3+1))>=$C$3,LARGE(DEBIT_15HARIAN!$T$7:$T$31,$C$3),LARGE(DEBIT_15HARIAN!$T$7:$T$31,INT($B6*($C$3+1)))+($B6*($C$3+1)-INT($B6*($C$3+1)))*(LARGE(DEBIT_15HARIAN!$T$7:$T$31,INT($B6*($C$3+1))+1)-LARGE(DEBIT_15HARIAN!$T$7:$T$31,INT($B6*($C$3+1))))))) | V6: =IF($C$3<1,"",IF(INT($B6*($C$3+1))<1,LARGE(DEBIT_15HARIAN!$U$7:$U$31,1),IF(INT($B6*($C$3+1))>=$C$3,LARGE(DEBIT_15HARIAN!$U$7:$U$31,$C$3),LARGE(DEBIT_15HARIAN!$U$7:$U$31,INT($B6*($C$3+1)))+($B6*($C$3+1)-INT($B6*($C$3+1)))*(LARGE(DEBIT_15HARIAN!$U$7:$U$31,INT($B6*($C$3+1))+1)-LARGE(DEBIT_15HARIAN!$U$7:$U$31,INT($B6*($C$3+1))))))) | W6: =IF($C$3<1,"",IF(INT($B6*($C$3+1))<1,LARGE(DEBIT_15HARIAN!$V$7:$V$31,1),IF(INT($B6*($C$3+1))>=$C$3,LARGE(DEBIT_15HARIAN!$V$7:$V$31,$C$3),LARGE(DEBIT_15HARIAN!$V$7:$V$31,INT($B6*($C$3+1)))+($B6*($C$3+1)-INT($B6*($C$3+1)))*(LARGE(DEBIT_15HARIAN!$V$7:$V$31,INT($B6*($C$3+1))+1)-LARGE(DEBIT_15HARIAN!$V$7:$V$31,INT($B6*($C$3+1))))))) | X6: =IF($C$3<1,"",IF(INT($B6*($C$3+1))<1,LARGE(DEBIT_15HARIAN!$W$7:$W$31,1),IF(INT($B6*($C$3+1))>=$C$3,LARGE(DEBIT_15HARIAN!$W$7:$W$31,$C$3),LARGE(DEBIT_15HARIAN!$W$7:$W$31,INT($B6*($C$3+1)))+($B6*($C$3+1)-INT($B6*($C$3+1)))*(LARGE(DEBIT_15HARIAN!$W$7:$W$31,INT($B6*($C$3+1))+1)-LARGE(DEBIT_15HARIAN!$W$7:$W$31,INT($B6*($C$3+1))))))) | Y6: =IF($C$3<1,"",IF(INT($B6*($C$3+1))<1,LARGE(DEBIT_15HARIAN!$X$7:$X$31,1),IF(INT($B6*($C$3+1))>=$C$3,LARGE(DEBIT_15HARIAN!$X$7:$X$31,$C$3),LARGE(DEBIT_15HARIAN!$X$7:$X$31,INT($B6*($C$3+1)))+($B6*($C$3+1)-INT($B6*($C$3+1)))*(LARGE(DEBIT_15HARIAN!$X$7:$X$31,INT($B6*($C$3+1))+1)-LARGE(DEBIT_15HARIAN!$X$7:$X$31,INT($B6*($C$3+1))))))) | Z6: =IF($C$3<1,"",IF(INT($B6*($C$3+1))<1,LARGE(DEBIT_15HARIAN!$Y$7:$Y$31,1),IF(INT($B6*($C$3+1))>=$C$3,LARGE(DEBIT_15HARIAN!$Y$7:$Y$31,$C$3),LARGE(DEBIT_15HARIAN!$Y$7:$Y$31,INT($B6*($C$3+1)))+($B6*($C$3+1)-INT($B6*($C$3+1)))*(LARGE(DEBIT_15HARIAN!$Y$7:$Y$31,INT($B6*($C$3+1))+1)-LARGE(DEBIT_15HARIAN!$Y$7:$Y$31,INT($B6*($C$3+1)))))))
A7: Q80 (m³/s) | B7: 0.8 | C7: =IF($C$3<1,"",IF(INT($B7*($C$3+1))<1,LARGE(DEBIT_15HARIAN!$B$7:$B$31,1),IF(INT($B7*($C$3+1))>=$C$3,LARGE(DEBIT_15HARIAN!$B$7:$B$31,$C$3),LARGE(DEBIT_15HARIAN!$B$7:$B$31,INT($B7*($C$3+1)))+($B7*($C$3+1)-INT($B7*($C$3+1)))*(LARGE(DEBIT_15HARIAN!$B$7:$B$31,INT($B7*($C$3+1))+1)-LARGE(DEBIT_15HARIAN!$B$7:$B$31,INT($B7*($C$3+1))))))) | D7: =IF($C$3<1,"",IF(INT($B7*($C$3+1))<1,LARGE(DEBIT_15HARIAN!$C$7:$C$31,1),IF(INT($B7*($C$3+1))>=$C$3,LARGE(DEBIT_15HARIAN!$C$7:$C$31,$C$3),LARGE(DEBIT_15HARIAN!$C$7:$C$31,INT($B7*($C$3+1)))+($B7*($C$3+1)-INT($B7*($C$3+1)))*(LARGE(DEBIT_15HARIAN!$C$7:$C$31,INT($B7*($C$3+1))+1)-LARGE(DEBIT_15HARIAN!$C$7:$C$31,INT($B7*($C$3+1))))))) | E7: =IF($C$3<1,"",IF(INT($B7*($C$3+1))<1,LARGE(DEBIT_15HARIAN!$D$7:$D$31,1),IF(INT($B7*($C$3+1))>=$C$3,LARGE(DEBIT_15HARIAN!$D$7:$D$31,$C$3),LARGE(DEBIT_15HARIAN!$D$7:$D$31,INT($B7*($C$3+1)))+($B7*($C$3+1)-INT($B7*($C$3+1)))*(LARGE(DEBIT_15HARIAN!$D$7:$D$31,INT($B7*($C$3+1))+1)-LARGE(DEBIT_15HARIAN!$D$7:$D$31,INT($B7*($C$3+1))))))) | F7: =IF($C$3<1,"",IF(INT($B7*($C$3+1))<1,LARGE(DEBIT_15HARIAN!$E$7:$E$31,1),IF(INT($B7*($C$3+1))>=$C$3,LARGE(DEBIT_15HARIAN!$E$7:$E$31,$C$3),LARGE(DEBIT_15HARIAN!$E$7:$E$31,INT($B7*($C$3+1)))+($B7*($C$3+1)-INT($B7*($C$3+1)))*(LARGE(DEBIT_15HARIAN!$E$7:$E$31,INT($B7*($C$3+1))+1)-LARGE(DEBIT_15HARIAN!$E$7:$E$31,INT($B7*($C$3+1))))))) | G7: =IF($C$3<1,"",IF(INT($B7*($C$3+1))<1,LARGE(DEBIT_15HARIAN!$F$7:$F$31,1),IF(INT($B7*($C$3+1))>=$C$3,LARGE(DEBIT_15HARIAN!$F$7:$F$31,$C$3),LARGE(DEBIT_15HARIAN!$F$7:$F$31,INT($B7*($C$3+1)))+($B7*($C$3+1)-INT($B7*($C$3+1)))*(LARGE(DEBIT_15HARIAN!$F$7:$F$31,INT($B7*($C$3+1))+1)-LARGE(DEBIT_15HARIAN!$F$7:$F$31,INT($B7*($C$3+1))))))) | H7: =IF($C$3<1,"",IF(INT($B7*($C$3+1))<1,LARGE(DEBIT_15HARIAN!$G$7:$G$31,1),IF(INT($B7*($C$3+1))>=$C$3,LARGE(DEBIT_15HARIAN!$G$7:$G$31,$C$3),LARGE(DEBIT_15HARIAN!$G$7:$G$31,INT($B7*($C$3+1)))+($B7*($C$3+1)-INT($B7*($C$3+1)))*(LARGE(DEBIT_15HARIAN!$G$7:$G$31,INT($B7*($C$3+1))+1)-LARGE(DEBIT_15HARIAN!$G$7:$G$31,INT($B7*($C$3+1))))))) | I7: =IF($C$3<1,"",IF(INT($B7*($C$3+1))<1,LARGE(DEBIT_15HARIAN!$H$7:$H$31,1),IF(INT($B7*($C$3+1))>=$C$3,LARGE(DEBIT_15HARIAN!$H$7:$H$31,$C$3),LARGE(DEBIT_15HARIAN!$H$7:$H$31,INT($B7*($C$3+1)))+($B7*($C$3+1)-INT($B7*($C$3+1)))*(LARGE(DEBIT_15HARIAN!$H$7:$H$31,INT($B7*($C$3+1))+1)-LARGE(DEBIT_15HARIAN!$H$7:$H$31,INT($B7*($C$3+1))))))) | J7: =IF($C$3<1,"",IF(INT($B7*($C$3+1))<1,LARGE(DEBIT_15HARIAN!$I$7:$I$31,1),IF(INT($B7*($C$3+1))>=$C$3,LARGE(DEBIT_15HARIAN!$I$7:$I$31,$C$3),LARGE(DEBIT_15HARIAN!$I$7:$I$31,INT($B7*($C$3+1)))+($B7*($C$3+1)-INT($B7*($C$3+1)))*(LARGE(DEBIT_15HARIAN!$I$7:$I$31,INT($B7*($C$3+1))+1)-LARGE(DEBIT_15HARIAN!$I$7:$I$31,INT($B7*($C$3+1))))))) | K7: =IF($C$3<1,"",IF(INT($B7*($C$3+1))<1,LARGE(DEBIT_15HARIAN!$J$7:$J$31,1),IF(INT($B7*($C$3+1))>=$C$3,LARGE(DEBIT_15HARIAN!$J$7:$J$31,$C$3),LARGE(DEBIT_15HARIAN!$J$7:$J$31,INT($B7*($C$3+1)))+($B7*($C$3+1)-INT($B7*($C$3+1)))*(LARGE(DEBIT_15HARIAN!$J$7:$J$31,INT($B7*($C$3+1))+1)-LARGE(DEBIT_15HARIAN!$J$7:$J$31,INT($B7*($C$3+1))))))) | L7: =IF($C$3<1,"",IF(INT($B7*($C$3+1))<1,LARGE(DEBIT_15HARIAN!$K$7:$K$31,1),IF(INT($B7*($C$3+1))>=$C$3,LARGE(DEBIT_15HARIAN!$K$7:$K$31,$C$3),LARGE(DEBIT_15HARIAN!$K$7:$K$31,INT($B7*($C$3+1)))+($B7*($C$3+1)-INT($B7*($C$3+1)))*(LARGE(DEBIT_15HARIAN!$K$7:$K$31,INT($B7*($C$3+1))+1)-LARGE(DEBIT_15HARIAN!$K$7:$K$31,INT($B7*($C$3+1))))))) | M7: =IF($C$3<1,"",IF(INT($B7*($C$3+1))<1,LARGE(DEBIT_15HARIAN!$L$7:$L$31,1),IF(INT($B7*($C$3+1))>=$C$3,LARGE(DEBIT_15HARIAN!$L$7:$L$31,$C$3),LARGE(DEBIT_15HARIAN!$L$7:$L$31,INT($B7*($C$3+1)))+($B7*($C$3+1)-INT($B7*($C$3+1)))*(LARGE(DEBIT_15HARIAN!$L$7:$L$31,INT($B7*($C$3+1))+1)-LARGE(DEBIT_15HARIAN!$L$7:$L$31,INT($B7*($C$3+1))))))) | N7: =IF($C$3<1,"",IF(INT($B7*($C$3+1))<1,LARGE(DEBIT_15HARIAN!$M$7:$M$31,1),IF(INT($B7*($C$3+1))>=$C$3,LARGE(DEBIT_15HARIAN!$M$7:$M$31,$C$3),LARGE(DEBIT_15HARIAN!$M$7:$M$31,INT($B7*($C$3+1)))+($B7*($C$3+1)-INT($B7*($C$3+1)))*(LARGE(DEBIT_15HARIAN!$M$7:$M$31,INT($B7*($C$3+1))+1)-LARGE(DEBIT_15HARIAN!$M$7:$M$31,INT($B7*($C$3+1))))))) | O7: =IF($C$3<1,"",IF(INT($B7*($C$3+1))<1,LARGE(DEBIT_15HARIAN!$N$7:$N$31,1),IF(INT($B7*($C$3+1))>=$C$3,LARGE(DEBIT_15HARIAN!$N$7:$N$31,$C$3),LARGE(DEBIT_15HARIAN!$N$7:$N$31,INT($B7*($C$3+1)))+($B7*($C$3+1)-INT($B7*($C$3+1)))*(LARGE(DEBIT_15HARIAN!$N$7:$N$31,INT($B7*($C$3+1))+1)-LARGE(DEBIT_15HARIAN!$N$7:$N$31,INT($B7*($C$3+1))))))) | P7: =IF($C$3<1,"",IF(INT($B7*($C$3+1))<1,LARGE(DEBIT_15HARIAN!$O$7:$O$31,1),IF(INT($B7*($C$3+1))>=$C$3,LARGE(DEBIT_15HARIAN!$O$7:$O$31,$C$3),LARGE(DEBIT_15HARIAN!$O$7:$O$31,INT($B7*($C$3+1)))+($B7*($C$3+1)-INT($B7*($C$3+1)))*(LARGE(DEBIT_15HARIAN!$O$7:$O$31,INT($B7*($C$3+1))+1)-LARGE(DEBIT_15HARIAN!$O$7:$O$31,INT($B7*($C$3+1))))))) | Q7: =IF($C$3<1,"",IF(INT($B7*($C$3+1))<1,LARGE(DEBIT_15HARIAN!$P$7:$P$31,1),IF(INT($B7*($C$3+1))>=$C$3,LARGE(DEBIT_15HARIAN!$P$7:$P$31,$C$3),LARGE(DEBIT_15HARIAN!$P$7:$P$31,INT($B7*($C$3+1)))+($B7*($C$3+1)-INT($B7*($C$3+1)))*(LARGE(DEBIT_15HARIAN!$P$7:$P$31,INT($B7*($C$3+1))+1)-LARGE(DEBIT_15HARIAN!$P$7:$P$31,INT($B7*($C$3+1))))))) | R7: =IF($C$3<1,"",IF(INT($B7*($C$3+1))<1,LARGE(DEBIT_15HARIAN!$Q$7:$Q$31,1),IF(INT($B7*($C$3+1))>=$C$3,LARGE(DEBIT_15HARIAN!$Q$7:$Q$31,$C$3),LARGE(DEBIT_15HARIAN!$Q$7:$Q$31,INT($B7*($C$3+1)))+($B7*($C$3+1)-INT($B7*($C$3+1)))*(LARGE(DEBIT_15HARIAN!$Q$7:$Q$31,INT($B7*($C$3+1))+1)-LARGE(DEBIT_15HARIAN!$Q$7:$Q$31,INT($B7*($C$3+1))))))) | S7: =IF($C$3<1,"",IF(INT($B7*($C$3+1))<1,LARGE(DEBIT_15HARIAN!$R$7:$R$31,1),IF(INT($B7*($C$3+1))>=$C$3,LARGE(DEBIT_15HARIAN!$R$7:$R$31,$C$3),LARGE(DEBIT_15HARIAN!$R$7:$R$31,INT($B7*($C$3+1)))+($B7*($C$3+1)-INT($B7*($C$3+1)))*(LARGE(DEBIT_15HARIAN!$R$7:$R$31,INT($B7*($C$3+1))+1)-LARGE(DEBIT_15HARIAN!$R$7:$R$31,INT($B7*($C$3+1))))))) | T7: =IF($C$3<1,"",IF(INT($B7*($C$3+1))<1,LARGE(DEBIT_15HARIAN!$S$7:$S$31,1),IF(INT($B7*($C$3+1))>=$C$3,LARGE(DEBIT_15HARIAN!$S$7:$S$31,$C$3),LARGE(DEBIT_15HARIAN!$S$7:$S$31,INT($B7*($C$3+1)))+($B7*($C$3+1)-INT($B7*($C$3+1)))*(LARGE(DEBIT_15HARIAN!$S$7:$S$31,INT($B7*($C$3+1))+1)-LARGE(DEBIT_15HARIAN!$S$7:$S$31,INT($B7*($C$3+1))))))) | U7: =IF($C$3<1,"",IF(INT($B7*($C$3+1))<1,LARGE(DEBIT_15HARIAN!$T$7:$T$31,1),IF(INT($B7*($C$3+1))>=$C$3,LARGE(DEBIT_15HARIAN!$T$7:$T$31,$C$3),LARGE(DEBIT_15HARIAN!$T$7:$T$31,INT($B7*($C$3+1)))+($B7*($C$3+1)-INT($B7*($C$3+1)))*(LARGE(DEBIT_15HARIAN!$T$7:$T$31,INT($B7*($C$3+1))+1)-LARGE(DEBIT_15HARIAN!$T$7:$T$31,INT($B7*($C$3+1))))))) | V7: =IF($C$3<1,"",IF(INT($B7*($C$3+1))<1,LARGE(DEBIT_15HARIAN!$U$7:$U$31,1),IF(INT($B7*($C$3+1))>=$C$3,LARGE(DEBIT_15HARIAN!$U$7:$U$31,$C$3),LARGE(DEBIT_15HARIAN!$U$7:$U$31,INT($B7*($C$3+1)))+($B7*($C$3+1)-INT($B7*($C$3+1)))*(LARGE(DEBIT_15HARIAN!$U$7:$U$31,INT($B7*($C$3+1))+1)-LARGE(DEBIT_15HARIAN!$U$7:$U$31,INT($B7*($C$3+1))))))) | W7: =IF($C$3<1,"",IF(INT($B7*($C$3+1))<1,LARGE(DEBIT_15HARIAN!$V$7:$V$31,1),IF(INT($B7*($C$3+1))>=$C$3,LARGE(DEBIT_15HARIAN!$V$7:$V$31,$C$3),LARGE(DEBIT_15HARIAN!$V$7:$V$31,INT($B7*($C$3+1)))+($B7*($C$3+1)-INT($B7*($C$3+1)))*(LARGE(DEBIT_15HARIAN!$V$7:$V$31,INT($B7*($C$3+1))+1)-LARGE(DEBIT_15HARIAN!$V$7:$V$31,INT($B7*($C$3+1))))))) | X7: =IF($C$3<1,"",IF(INT($B7*($C$3+1))<1,LARGE(DEBIT_15HARIAN!$W$7:$W$31,1),IF(INT($B7*($C$3+1))>=$C$3,LARGE(DEBIT_15HARIAN!$W$7:$W$31,$C$3),LARGE(DEBIT_15HARIAN!$W$7:$W$31,INT($B7*($C$3+1)))+($B7*($C$3+1)-INT($B7*($C$3+1)))*(LARGE(DEBIT_15HARIAN!$W$7:$W$31,INT($B7*($C$3+1))+1)-LARGE(DEBIT_15HARIAN!$W$7:$W$31,INT($B7*($C$3+1))))))) | Y7: =IF($C$3<1,"",IF(INT($B7*($C$3+1))<1,LARGE(DEBIT_15HARIAN!$X$7:$X$31,1),IF(INT($B7*($C$3+1))>=$C$3,LARGE(DEBIT_15HARIAN!$X$7:$X$31,$C$3),LARGE(DEBIT_15HARIAN!$X$7:$X$31,INT($B7*($C$3+1)))+($B7*($C$3+1)-INT($B7*($C$3+1)))*(LARGE(DEBIT_15HARIAN!$X$7:$X$31,INT($B7*($C$3+1))+1)-LARGE(DEBIT_15HARIAN!$X$7:$X$31,INT($B7*($C$3+1))))))) | Z7: =IF($C$3<1,"",IF(INT($B7*($C$3+1))<1,LARGE(DEBIT_15HARIAN!$Y$7:$Y$31,1),IF(INT($B7*($C$3+1))>=$C$3,LARGE(DEBIT_15HARIAN!$Y$7:$Y$31,$C$3),LARGE(DEBIT_15HARIAN!$Y$7:$Y$31,INT($B7*($C$3+1)))+($B7*($C$3+1)-INT($B7*($C$3+1)))*(LARGE(DEBIT_15HARIAN!$Y$7:$Y$31,INT($B7*($C$3+1))+1)-LARGE(DEBIT_15HARIAN!$Y$7:$Y$31,INT($B7*($C$3+1)))))))
A8: Q90 (m³/s) | B8: 0.9 | C8: =IF($C$3<1,"",IF(INT($B8*($C$3+1))<1,LARGE(DEBIT_15HARIAN!$B$7:$B$31,1),IF(INT($B8*($C$3+1))>=$C$3,LARGE(DEBIT_15HARIAN!$B$7:$B$31,$C$3),LARGE(DEBIT_15HARIAN!$B$7:$B$31,INT($B8*($C$3+1)))+($B8*($C$3+1)-INT($B8*($C$3+1)))*(LARGE(DEBIT_15HARIAN!$B$7:$B$31,INT($B8*($C$3+1))+1)-LARGE(DEBIT_15HARIAN!$B$7:$B$31,INT($B8*($C$3+1))))))) | D8: =IF($C$3<1,"",IF(INT($B8*($C$3+1))<1,LARGE(DEBIT_15HARIAN!$C$7:$C$31,1),IF(INT($B8*($C$3+1))>=$C$3,LARGE(DEBIT_15HARIAN!$C$7:$C$31,$C$3),LARGE(DEBIT_15HARIAN!$C$7:$C$31,INT($B8*($C$3+1)))+($B8*($C$3+1)-INT($B8*($C$3+1)))*(LARGE(DEBIT_15HARIAN!$C$7:$C$31,INT($B8*($C$3+1))+1)-LARGE(DEBIT_15HARIAN!$C$7:$C$31,INT($B8*($C$3+1))))))) | E8: =IF($C$3<1,"",IF(INT($B8*($C$3+1))<1,LARGE(DEBIT_15HARIAN!$D$7:$D$31,1),IF(INT($B8*($C$3+1))>=$C$3,LARGE(DEBIT_15HARIAN!$D$7:$D$31,$C$3),LARGE(DEBIT_15HARIAN!$D$7:$D$31,INT($B8*($C$3+1)))+($B8*($C$3+1)-INT($B8*($C$3+1)))*(LARGE(DEBIT_15HARIAN!$D$7:$D$31,INT($B8*($C$3+1))+1)-LARGE(DEBIT_15HARIAN!$D$7:$D$31,INT($B8*($C$3+1))))))) | F8: =IF($C$3<1,"",IF(INT($B8*($C$3+1))<1,LARGE(DEBIT_15HARIAN!$E$7:$E$31,1),IF(INT($B8*($C$3+1))>=$C$3,LARGE(DEBIT_15HARIAN!$E$7:$E$31,$C$3),LARGE(DEBIT_15HARIAN!$E$7:$E$31,INT($B8*($C$3+1)))+($B8*($C$3+1)-INT($B8*($C$3+1)))*(LARGE(DEBIT_15HARIAN!$E$7:$E$31,INT($B8*($C$3+1))+1)-LARGE(DEBIT_15HARIAN!$E$7:$E$31,INT($B8*($C$3+1))))))) | G8: =IF($C$3<1,"",IF(INT($B8*($C$3+1))<1,LARGE(DEBIT_15HARIAN!$F$7:$F$31,1),IF(INT($B8*($C$3+1))>=$C$3,LARGE(DEBIT_15HARIAN!$F$7:$F$31,$C$3),LARGE(DEBIT_15HARIAN!$F$7:$F$31,INT($B8*($C$3+1)))+($B8*($C$3+1)-INT($B8*($C$3+1)))*(LARGE(DEBIT_15HARIAN!$F$7:$F$31,INT($B8*($C$3+1))+1)-LARGE(DEBIT_15HARIAN!$F$7:$F$31,INT($B8*($C$3+1))))))) | H8: =IF($C$3<1,"",IF(INT($B8*($C$3+1))<1,LARGE(DEBIT_15HARIAN!$G$7:$G$31,1),IF(INT($B8*($C$3+1))>=$C$3,LARGE(DEBIT_15HARIAN!$G$7:$G$31,$C$3),LARGE(DEBIT_15HARIAN!$G$7:$G$31,INT($B8*($C$3+1)))+($B8*($C$3+1)-INT($B8*($C$3+1)))*(LARGE(DEBIT_15HARIAN!$G$7:$G$31,INT($B8*($C$3+1))+1)-LARGE(DEBIT_15HARIAN!$G$7:$G$31,INT($B8*($C$3+1))))))) | I8: =IF($C$3<1,"",IF(INT($B8*($C$3+1))<1,LARGE(DEBIT_15HARIAN!$H$7:$H$31,1),IF(INT($B8*($C$3+1))>=$C$3,LARGE(DEBIT_15HARIAN!$H$7:$H$31,$C$3),LARGE(DEBIT_15HARIAN!$H$7:$H$31,INT($B8*($C$3+1)))+($B8*($C$3+1)-INT($B8*($C$3+1)))*(LARGE(DEBIT_15HARIAN!$H$7:$H$31,INT($B8*($C$3+1))+1)-LARGE(DEBIT_15HARIAN!$H$7:$H$31,INT($B8*($C$3+1))))))) | J8: =IF($C$3<1,"",IF(INT($B8*($C$3+1))<1,LARGE(DEBIT_15HARIAN!$I$7:$I$31,1),IF(INT($B8*($C$3+1))>=$C$3,LARGE(DEBIT_15HARIAN!$I$7:$I$31,$C$3),LARGE(DEBIT_15HARIAN!$I$7:$I$31,INT($B8*($C$3+1)))+($B8*($C$3+1)-INT($B8*($C$3+1)))*(LARGE(DEBIT_15HARIAN!$I$7:$I$31,INT($B8*($C$3+1))+1)-LARGE(DEBIT_15HARIAN!$I$7:$I$31,INT($B8*($C$3+1))))))) | K8: =IF($C$3<1,"",IF(INT($B8*($C$3+1))<1,LARGE(DEBIT_15HARIAN!$J$7:$J$31,1),IF(INT($B8*($C$3+1))>=$C$3,LARGE(DEBIT_15HARIAN!$J$7:$J$31,$C$3),LARGE(DEBIT_15HARIAN!$J$7:$J$31,INT($B8*($C$3+1)))+($B8*($C$3+1)-INT($B8*($C$3+1)))*(LARGE(DEBIT_15HARIAN!$J$7:$J$31,INT($B8*($C$3+1))+1)-LARGE(DEBIT_15HARIAN!$J$7:$J$31,INT($B8*($C$3+1))))))) | L8: =IF($C$3<1,"",IF(INT($B8*($C$3+1))<1,LARGE(DEBIT_15HARIAN!$K$7:$K$31,1),IF(INT($B8*($C$3+1))>=$C$3,LARGE(DEBIT_15HARIAN!$K$7:$K$31,$C$3),LARGE(DEBIT_15HARIAN!$K$7:$K$31,INT($B8*($C$3+1)))+($B8*($C$3+1)-INT($B8*($C$3+1)))*(LARGE(DEBIT_15HARIAN!$K$7:$K$31,INT($B8*($C$3+1))+1)-LARGE(DEBIT_15HARIAN!$K$7:$K$31,INT($B8*($C$3+1))))))) | M8: =IF($C$3<1,"",IF(INT($B8*($C$3+1))<1,LARGE(DEBIT_15HARIAN!$L$7:$L$31,1),IF(INT($B8*($C$3+1))>=$C$3,LARGE(DEBIT_15HARIAN!$L$7:$L$31,$C$3),LARGE(DEBIT_15HARIAN!$L$7:$L$31,INT($B8*($C$3+1)))+($B8*($C$3+1)-INT($B8*($C$3+1)))*(LARGE(DEBIT_15HARIAN!$L$7:$L$31,INT($B8*($C$3+1))+1)-LARGE(DEBIT_15HARIAN!$L$7:$L$31,INT($B8*($C$3+1))))))) | N8: =IF($C$3<1,"",IF(INT($B8*($C$3+1))<1,LARGE(DEBIT_15HARIAN!$M$7:$M$31,1),IF(INT($B8*($C$3+1))>=$C$3,LARGE(DEBIT_15HARIAN!$M$7:$M$31,$C$3),LARGE(DEBIT_15HARIAN!$M$7:$M$31,INT($B8*($C$3+1)))+($B8*($C$3+1)-INT($B8*($C$3+1)))*(LARGE(DEBIT_15HARIAN!$M$7:$M$31,INT($B8*($C$3+1))+1)-LARGE(DEBIT_15HARIAN!$M$7:$M$31,INT($B8*($C$3+1))))))) | O8: =IF($C$3<1,"",IF(INT($B8*($C$3+1))<1,LARGE(DEBIT_15HARIAN!$N$7:$N$31,1),IF(INT($B8*($C$3+1))>=$C$3,LARGE(DEBIT_15HARIAN!$N$7:$N$31,$C$3),LARGE(DEBIT_15HARIAN!$N$7:$N$31,INT($B8*($C$3+1)))+($B8*($C$3+1)-INT($B8*($C$3+1)))*(LARGE(DEBIT_15HARIAN!$N$7:$N$31,INT($B8*($C$3+1))+1)-LARGE(DEBIT_15HARIAN!$N$7:$N$31,INT($B8*($C$3+1))))))) | P8: =IF($C$3<1,"",IF(INT($B8*($C$3+1))<1,LARGE(DEBIT_15HARIAN!$O$7:$O$31,1),IF(INT($B8*($C$3+1))>=$C$3,LARGE(DEBIT_15HARIAN!$O$7:$O$31,$C$3),LARGE(DEBIT_15HARIAN!$O$7:$O$31,INT($B8*($C$3+1)))+($B8*($C$3+1)-INT($B8*($C$3+1)))*(LARGE(DEBIT_15HARIAN!$O$7:$O$31,INT($B8*($C$3+1))+1)-LARGE(DEBIT_15HARIAN!$O$7:$O$31,INT($B8*($C$3+1))))))) | Q8: =IF($C$3<1,"",IF(INT($B8*($C$3+1))<1,LARGE(DEBIT_15HARIAN!$P$7:$P$31,1),IF(INT($B8*($C$3+1))>=$C$3,LARGE(DEBIT_15HARIAN!$P$7:$P$31,$C$3),LARGE(DEBIT_15HARIAN!$P$7:$P$31,INT($B8*($C$3+1)))+($B8*($C$3+1)-INT($B8*($C$3+1)))*(LARGE(DEBIT_15HARIAN!$P$7:$P$31,INT($B8*($C$3+1))+1)-LARGE(DEBIT_15HARIAN!$P$7:$P$31,INT($B8*($C$3+1))))))) | R8: =IF($C$3<1,"",IF(INT($B8*($C$3+1))<1,LARGE(DEBIT_15HARIAN!$Q$7:$Q$31,1),IF(INT($B8*($C$3+1))>=$C$3,LARGE(DEBIT_15HARIAN!$Q$7:$Q$31,$C$3),LARGE(DEBIT_15HARIAN!$Q$7:$Q$31,INT($B8*($C$3+1)))+($B8*($C$3+1)-INT($B8*($C$3+1)))*(LARGE(DEBIT_15HARIAN!$Q$7:$Q$31,INT($B8*($C$3+1))+1)-LARGE(DEBIT_15HARIAN!$Q$7:$Q$31,INT($B8*($C$3+1))))))) | S8: =IF($C$3<1,"",IF(INT($B8*($C$3+1))<1,LARGE(DEBIT_15HARIAN!$R$7:$R$31,1),IF(INT($B8*($C$3+1))>=$C$3,LARGE(DEBIT_15HARIAN!$R$7:$R$31,$C$3),LARGE(DEBIT_15HARIAN!$R$7:$R$31,INT($B8*($C$3+1)))+($B8*($C$3+1)-INT($B8*($C$3+1)))*(LARGE(DEBIT_15HARIAN!$R$7:$R$31,INT($B8*($C$3+1))+1)-LARGE(DEBIT_15HARIAN!$R$7:$R$31,INT($B8*($C$3+1))))))) | T8: =IF($C$3<1,"",IF(INT($B8*($C$3+1))<1,LARGE(DEBIT_15HARIAN!$S$7:$S$31,1),IF(INT($B8*($C$3+1))>=$C$3,LARGE(DEBIT_15HARIAN!$S$7:$S$31,$C$3),LARGE(DEBIT_15HARIAN!$S$7:$S$31,INT($B8*($C$3+1)))+($B8*($C$3+1)-INT($B8*($C$3+1)))*(LARGE(DEBIT_15HARIAN!$S$7:$S$31,INT($B8*($C$3+1))+1)-LARGE(DEBIT_15HARIAN!$S$7:$S$31,INT($B8*($C$3+1))))))) | U8: =IF($C$3<1,"",IF(INT($B8*($C$3+1))<1,LARGE(DEBIT_15HARIAN!$T$7:$T$31,1),IF(INT($B8*($C$3+1))>=$C$3,LARGE(DEBIT_15HARIAN!$T$7:$T$31,$C$3),LARGE(DEBIT_15HARIAN!$T$7:$T$31,INT($B8*($C$3+1)))+($B8*($C$3+1)-INT($B8*($C$3+1)))*(LARGE(DEBIT_15HARIAN!$T$7:$T$31,INT($B8*($C$3+1))+1)-LARGE(DEBIT_15HARIAN!$T$7:$T$31,INT($B8*($C$3+1))))))) | V8: =IF($C$3<1,"",IF(INT($B8*($C$3+1))<1,LARGE(DEBIT_15HARIAN!$U$7:$U$31,1),IF(INT($B8*($C$3+1))>=$C$3,LARGE(DEBIT_15HARIAN!$U$7:$U$31,$C$3),LARGE(DEBIT_15HARIAN!$U$7:$U$31,INT($B8*($C$3+1)))+($B8*($C$3+1)-INT($B8*($C$3+1)))*(LARGE(DEBIT_15HARIAN!$U$7:$U$31,INT($B8*($C$3+1))+1)-LARGE(DEBIT_15HARIAN!$U$7:$U$31,INT($B8*($C$3+1))))))) | W8: =IF($C$3<1,"",IF(INT($B8*($C$3+1))<1,LARGE(DEBIT_15HARIAN!$V$7:$V$31,1),IF(INT($B8*($C$3+1))>=$C$3,LARGE(DEBIT_15HARIAN!$V$7:$V$31,$C$3),LARGE(DEBIT_15HARIAN!$V$7:$V$31,INT($B8*($C$3+1)))+($B8*($C$3+1)-INT($B8*($C$3+1)))*(LARGE(DEBIT_15HARIAN!$V$7:$V$31,INT($B8*($C$3+1))+1)-LARGE(DEBIT_15HARIAN!$V$7:$V$31,INT($B8*($C$3+1))))))) | X8: =IF($C$3<1,"",IF(INT($B8*($C$3+1))<1,LARGE(DEBIT_15HARIAN!$W$7:$W$31,1),IF(INT($B8*($C$3+1))>=$C$3,LARGE(DEBIT_15HARIAN!$W$7:$W$31,$C$3),LARGE(DEBIT_15HARIAN!$W$7:$W$31,INT($B8*($C$3+1)))+($B8*($C$3+1)-INT($B8*($C$3+1)))*(LARGE(DEBIT_15HARIAN!$W$7:$W$31,INT($B8*($C$3+1))+1)-LARGE(DEBIT_15HARIAN!$W$7:$W$31,INT($B8*($C$3+1))))))) | Y8: =IF($C$3<1,"",IF(INT($B8*($C$3+1))<1,LARGE(DEBIT_15HARIAN!$X$7:$X$31,1),IF(INT($B8*($C$3+1))>=$C$3,LARGE(DEBIT_15HARIAN!$X$7:$X$31,$C$3),LARGE(DEBIT_15HARIAN!$X$7:$X$31,INT($B8*($C$3+1)))+($B8*($C$3+1)-INT($B8*($C$3+1)))*(LARGE(DEBIT_15HARIAN!$X$7:$X$31,INT($B8*($C$3+1))+1)-LARGE(DEBIT_15HARIAN!$X$7:$X$31,INT($B8*($C$3+1))))))) | Z8: =IF($C$3<1,"",IF(INT($B8*($C$3+1))<1,LARGE(DEBIT_15HARIAN!$Y$7:$Y$31,1),IF(INT($B8*($C$3+1))>=$C$3,LARGE(DEBIT_15HARIAN!$Y$7:$Y$31,$C$3),LARGE(DEBIT_15HARIAN!$Y$7:$Y$31,INT($B8*($C$3+1)))+($B8*($C$3+1)-INT($B8*($C$3+1)))*(LARGE(DEBIT_15HARIAN!$Y$7:$Y$31,INT($B8*($C$3+1))+1)-LARGE(DEBIT_15HARIAN!$Y$7:$Y$31,INT($B8*($C$3+1)))))))
A9: Q95 (m³/s) | B9: 0.95 | C9: =IF($C$3<1,"",IF(INT($B9*($C$3+1))<1,LARGE(DEBIT_15HARIAN!$B$7:$B$31,1),IF(INT($B9*($C$3+1))>=$C$3,LARGE(DEBIT_15HARIAN!$B$7:$B$31,$C$3),LARGE(DEBIT_15HARIAN!$B$7:$B$31,INT($B9*($C$3+1)))+($B9*($C$3+1)-INT($B9*($C$3+1)))*(LARGE(DEBIT_15HARIAN!$B$7:$B$31,INT($B9*($C$3+1))+1)-LARGE(DEBIT_15HARIAN!$B$7:$B$31,INT($B9*($C$3+1))))))) | D9: =IF($C$3<1,"",IF(INT($B9*($C$3+1))<1,LARGE(DEBIT_15HARIAN!$C$7:$C$31,1),IF(INT($B9*($C$3+1))>=$C$3,LARGE(DEBIT_15HARIAN!$C$7:$C$31,$C$3),LARGE(DEBIT_15HARIAN!$C$7:$C$31,INT($B9*($C$3+1)))+($B9*($C$3+1)-INT($B9*($C$3+1)))*(LARGE(DEBIT_15HARIAN!$C$7:$C$31,INT($B9*($C$3+1))+1)-LARGE(DEBIT_15HARIAN!$C$7:$C$31,INT($B9*($C$3+1))))))) | E9: =IF($C$3<1,"",IF(INT($B9*($C$3+1))<1,LARGE(DEBIT_15HARIAN!$D$7:$D$31,1),IF(INT($B9*($C$3+1))>=$C$3,LARGE(DEBIT_15HARIAN!$D$7:$D$31,$C$3),LARGE(DEBIT_15HARIAN!$D$7:$D$31,INT($B9*($C$3+1)))+($B9*($C$3+1)-INT($B9*($C$3+1)))*(LARGE(DEBIT_15HARIAN!$D$7:$D$31,INT($B9*($C$3+1))+1)-LARGE(DEBIT_15HARIAN!$D$7:$D$31,INT($B9*($C$3+1))))))) | F9: =IF($C$3<1,"",IF(INT($B9*($C$3+1))<1,LARGE(DEBIT_15HARIAN!$E$7:$E$31,1),IF(INT($B9*($C$3+1))>=$C$3,LARGE(DEBIT_15HARIAN!$E$7:$E$31,$C$3),LARGE(DEBIT_15HARIAN!$E$7:$E$31,INT($B9*($C$3+1)))+($B9*($C$3+1)-INT($B9*($C$3+1)))*(LARGE(DEBIT_15HARIAN!$E$7:$E$31,INT($B9*($C$3+1))+1)-LARGE(DEBIT_15HARIAN!$E$7:$E$31,INT($B9*($C$3+1))))))) | G9: =IF($C$3<1,"",IF(INT($B9*($C$3+1))<1,LARGE(DEBIT_15HARIAN!$F$7:$F$31,1),IF(INT($B9*($C$3+1))>=$C$3,LARGE(DEBIT_15HARIAN!$F$7:$F$31,$C$3),LARGE(DEBIT_15HARIAN!$F$7:$F$31,INT($B9*($C$3+1)))+($B9*($C$3+1)-INT($B9*($C$3+1)))*(LARGE(DEBIT_15HARIAN!$F$7:$F$31,INT($B9*($C$3+1))+1)-LARGE(DEBIT_15HARIAN!$F$7:$F$31,INT($B9*($C$3+1))))))) | H9: =IF($C$3<1,"",IF(INT($B9*($C$3+1))<1,LARGE(DEBIT_15HARIAN!$G$7:$G$31,1),IF(INT($B9*($C$3+1))>=$C$3,LARGE(DEBIT_15HARIAN!$G$7:$G$31,$C$3),LARGE(DEBIT_15HARIAN!$G$7:$G$31,INT($B9*($C$3+1)))+($B9*($C$3+1)-INT($B9*($C$3+1)))*(LARGE(DEBIT_15HARIAN!$G$7:$G$31,INT($B9*($C$3+1))+1)-LARGE(DEBIT_15HARIAN!$G$7:$G$31,INT($B9*($C$3+1))))))) | I9: =IF($C$3<1,"",IF(INT($B9*($C$3+1))<1,LARGE(DEBIT_15HARIAN!$H$7:$H$31,1),IF(INT($B9*($C$3+1))>=$C$3,LARGE(DEBIT_15HARIAN!$H$7:$H$31,$C$3),LARGE(DEBIT_15HARIAN!$H$7:$H$31,INT($B9*($C$3+1)))+($B9*($C$3+1)-INT($B9*($C$3+1)))*(LARGE(DEBIT_15HARIAN!$H$7:$H$31,INT($B9*($C$3+1))+1)-LARGE(DEBIT_15HARIAN!$H$7:$H$31,INT($B9*($C$3+1))))))) | J9: =IF($C$3<1,"",IF(INT($B9*($C$3+1))<1,LARGE(DEBIT_15HARIAN!$I$7:$I$31,1),IF(INT($B9*($C$3+1))>=$C$3,LARGE(DEBIT_15HARIAN!$I$7:$I$31,$C$3),LARGE(DEBIT_15HARIAN!$I$7:$I$31,INT($B9*($C$3+1)))+($B9*($C$3+1)-INT($B9*($C$3+1)))*(LARGE(DEBIT_15HARIAN!$I$7:$I$31,INT($B9*($C$3+1))+1)-LARGE(DEBIT_15HARIAN!$I$7:$I$31,INT($B9*($C$3+1))))))) | K9: =IF($C$3<1,"",IF(INT($B9*($C$3+1))<1,LARGE(DEBIT_15HARIAN!$J$7:$J$31,1),IF(INT($B9*($C$3+1))>=$C$3,LARGE(DEBIT_15HARIAN!$J$7:$J$31,$C$3),LARGE(DEBIT_15HARIAN!$J$7:$J$31,INT($B9*($C$3+1)))+($B9*($C$3+1)-INT($B9*($C$3+1)))*(LARGE(DEBIT_15HARIAN!$J$7:$J$31,INT($B9*($C$3+1))+1)-LARGE(DEBIT_15HARIAN!$J$7:$J$31,INT($B9*($C$3+1))))))) | L9: =IF($C$3<1,"",IF(INT($B9*($C$3+1))<1,LARGE(DEBIT_15HARIAN!$K$7:$K$31,1),IF(INT($B9*($C$3+1))>=$C$3,LARGE(DEBIT_15HARIAN!$K$7:$K$31,$C$3),LARGE(DEBIT_15HARIAN!$K$7:$K$31,INT($B9*($C$3+1)))+($B9*($C$3+1)-INT($B9*($C$3+1)))*(LARGE(DEBIT_15HARIAN!$K$7:$K$31,INT($B9*($C$3+1))+1)-LARGE(DEBIT_15HARIAN!$K$7:$K$31,INT($B9*($C$3+1))))))) | M9: =IF($C$3<1,"",IF(INT($B9*($C$3+1))<1,LARGE(DEBIT_15HARIAN!$L$7:$L$31,1),IF(INT($B9*($C$3+1))>=$C$3,LARGE(DEBIT_15HARIAN!$L$7:$L$31,$C$3),LARGE(DEBIT_15HARIAN!$L$7:$L$31,INT($B9*($C$3+1)))+($B9*($C$3+1)-INT($B9*($C$3+1)))*(LARGE(DEBIT_15HARIAN!$L$7:$L$31,INT($B9*($C$3+1))+1)-LARGE(DEBIT_15HARIAN!$L$7:$L$31,INT($B9*($C$3+1))))))) | N9: =IF($C$3<1,"",IF(INT($B9*($C$3+1))<1,LARGE(DEBIT_15HARIAN!$M$7:$M$31,1),IF(INT($B9*($C$3+1))>=$C$3,LARGE(DEBIT_15HARIAN!$M$7:$M$31,$C$3),LARGE(DEBIT_15HARIAN!$M$7:$M$31,INT($B9*($C$3+1)))+($B9*($C$3+1)-INT($B9*($C$3+1)))*(LARGE(DEBIT_15HARIAN!$M$7:$M$31,INT($B9*($C$3+1))+1)-LARGE(DEBIT_15HARIAN!$M$7:$M$31,INT($B9*($C$3+1))))))) | O9: =IF($C$3<1,"",IF(INT($B9*($C$3+1))<1,LARGE(DEBIT_15HARIAN!$N$7:$N$31,1),IF(INT($B9*($C$3+1))>=$C$3,LARGE(DEBIT_15HARIAN!$N$7:$N$31,$C$3),LARGE(DEBIT_15HARIAN!$N$7:$N$31,INT($B9*($C$3+1)))+($B9*($C$3+1)-INT($B9*($C$3+1)))*(LARGE(DEBIT_15HARIAN!$N$7:$N$31,INT($B9*($C$3+1))+1)-LARGE(DEBIT_15HARIAN!$N$7:$N$31,INT($B9*($C$3+1))))))) | P9: =IF($C$3<1,"",IF(INT($B9*($C$3+1))<1,LARGE(DEBIT_15HARIAN!$O$7:$O$31,1),IF(INT($B9*($C$3+1))>=$C$3,LARGE(DEBIT_15HARIAN!$O$7:$O$31,$C$3),LARGE(DEBIT_15HARIAN!$O$7:$O$31,INT($B9*($C$3+1)))+($B9*($C$3+1)-INT($B9*($C$3+1)))*(LARGE(DEBIT_15HARIAN!$O$7:$O$31,INT($B9*($C$3+1))+1)-LARGE(DEBIT_15HARIAN!$O$7:$O$31,INT($B9*($C$3+1))))))) | Q9: =IF($C$3<1,"",IF(INT($B9*($C$3+1))<1,LARGE(DEBIT_15HARIAN!$P$7:$P$31,1),IF(INT($B9*($C$3+1))>=$C$3,LARGE(DEBIT_15HARIAN!$P$7:$P$31,$C$3),LARGE(DEBIT_15HARIAN!$P$7:$P$31,INT($B9*($C$3+1)))+($B9*($C$3+1)-INT($B9*($C$3+1)))*(LARGE(DEBIT_15HARIAN!$P$7:$P$31,INT($B9*($C$3+1))+1)-LARGE(DEBIT_15HARIAN!$P$7:$P$31,INT($B9*($C$3+1))))))) | R9: =IF($C$3<1,"",IF(INT($B9*($C$3+1))<1,LARGE(DEBIT_15HARIAN!$Q$7:$Q$31,1),IF(INT($B9*($C$3+1))>=$C$3,LARGE(DEBIT_15HARIAN!$Q$7:$Q$31,$C$3),LARGE(DEBIT_15HARIAN!$Q$7:$Q$31,INT($B9*($C$3+1)))+($B9*($C$3+1)-INT($B9*($C$3+1)))*(LARGE(DEBIT_15HARIAN!$Q$7:$Q$31,INT($B9*($C$3+1))+1)-LARGE(DEBIT_15HARIAN!$Q$7:$Q$31,INT($B9*($C$3+1))))))) | S9: =IF($C$3<1,"",IF(INT($B9*($C$3+1))<1,LARGE(DEBIT_15HARIAN!$R$7:$R$31,1),IF(INT($B9*($C$3+1))>=$C$3,LARGE(DEBIT_15HARIAN!$R$7:$R$31,$C$3),LARGE(DEBIT_15HARIAN!$R$7:$R$31,INT($B9*($C$3+1)))+($B9*($C$3+1)-INT($B9*($C$3+1)))*(LARGE(DEBIT_15HARIAN!$R$7:$R$31,INT($B9*($C$3+1))+1)-LARGE(DEBIT_15HARIAN!$R$7:$R$31,INT($B9*($C$3+1))))))) | T9: =IF($C$3<1,"",IF(INT($B9*($C$3+1))<1,LARGE(DEBIT_15HARIAN!$S$7:$S$31,1),IF(INT($B9*($C$3+1))>=$C$3,LARGE(DEBIT_15HARIAN!$S$7:$S$31,$C$3),LARGE(DEBIT_15HARIAN!$S$7:$S$31,INT($B9*($C$3+1)))+($B9*($C$3+1)-INT($B9*($C$3+1)))*(LARGE(DEBIT_15HARIAN!$S$7:$S$31,INT($B9*($C$3+1))+1)-LARGE(DEBIT_15HARIAN!$S$7:$S$31,INT($B9*($C$3+1))))))) | U9: =IF($C$3<1,"",IF(INT($B9*($C$3+1))<1,LARGE(DEBIT_15HARIAN!$T$7:$T$31,1),IF(INT($B9*($C$3+1))>=$C$3,LARGE(DEBIT_15HARIAN!$T$7:$T$31,$C$3),LARGE(DEBIT_15HARIAN!$T$7:$T$31,INT($B9*($C$3+1)))+($B9*($C$3+1)-INT($B9*($C$3+1)))*(LARGE(DEBIT_15HARIAN!$T$7:$T$31,INT($B9*($C$3+1))+1)-LARGE(DEBIT_15HARIAN!$T$7:$T$31,INT($B9*($C$3+1))))))) | V9: =IF($C$3<1,"",IF(INT($B9*($C$3+1))<1,LARGE(DEBIT_15HARIAN!$U$7:$U$31,1),IF(INT($B9*($C$3+1))>=$C$3,LARGE(DEBIT_15HARIAN!$U$7:$U$31,$C$3),LARGE(DEBIT_15HARIAN!$U$7:$U$31,INT($B9*($C$3+1)))+($B9*($C$3+1)-INT($B9*($C$3+1)))*(LARGE(DEBIT_15HARIAN!$U$7:$U$31,INT($B9*($C$3+1))+1)-LARGE(DEBIT_15HARIAN!$U$7:$U$31,INT($B9*($C$3+1))))))) | W9: =IF($C$3<1,"",IF(INT($B9*($C$3+1))<1,LARGE(DEBIT_15HARIAN!$V$7:$V$31,1),IF(INT($B9*($C$3+1))>=$C$3,LARGE(DEBIT_15HARIAN!$V$7:$V$31,$C$3),LARGE(DEBIT_15HARIAN!$V$7:$V$31,INT($B9*($C$3+1)))+($B9*($C$3+1)-INT($B9*($C$3+1)))*(LARGE(DEBIT_15HARIAN!$V$7:$V$31,INT($B9*($C$3+1))+1)-LARGE(DEBIT_15HARIAN!$V$7:$V$31,INT($B9*($C$3+1))))))) | X9: =IF($C$3<1,"",IF(INT($B9*($C$3+1))<1,LARGE(DEBIT_15HARIAN!$W$7:$W$31,1),IF(INT($B9*($C$3+1))>=$C$3,LARGE(DEBIT_15HARIAN!$W$7:$W$31,$C$3),LARGE(DEBIT_15HARIAN!$W$7:$W$31,INT($B9*($C$3+1)))+($B9*($C$3+1)-INT($B9*($C$3+1)))*(LARGE(DEBIT_15HARIAN!$W$7:$W$31,INT($B9*($C$3+1))+1)-LARGE(DEBIT_15HARIAN!$W$7:$W$31,INT($B9*($C$3+1))))))) | Y9: =IF($C$3<1,"",IF(INT($B9*($C$3+1))<1,LARGE(DEBIT_15HARIAN!$X$7:$X$31,1),IF(INT($B9*($C$3+1))>=$C$3,LARGE(DEBIT_15HARIAN!$X$7:$X$31,$C$3),LARGE(DEBIT_15HARIAN!$X$7:$X$31,INT($B9*($C$3+1)))+($B9*($C$3+1)-INT($B9*($C$3+1)))*(LARGE(DEBIT_15HARIAN!$X$7:$X$31,INT($B9*($C$3+1))+1)-LARGE(DEBIT_15HARIAN!$X$7:$X$31,INT($B9*($C$3+1))))))) | Z9: =IF($C$3<1,"",IF(INT($B9*($C$3+1))<1,LARGE(DEBIT_15HARIAN!$Y$7:$Y$31,1),IF(INT($B9*($C$3+1))>=$C$3,LARGE(DEBIT_15HARIAN!$Y$7:$Y$31,$C$3),LARGE(DEBIT_15HARIAN!$Y$7:$Y$31,INT($B9*($C$3+1)))+($B9*($C$3+1)-INT($B9*($C$3+1)))*(LARGE(DEBIT_15HARIAN!$Y$7:$Y$31,INT($B9*($C$3+1))+1)-LARGE(DEBIT_15HARIAN!$Y$7:$Y$31,INT($B9*($C$3+1)))))))
A10: Rata-rata (m³/s) | C10: =IFERROR(AVERAGE(DEBIT_15HARIAN!$B$7:$B$31),"") | D10: =IFERROR(AVERAGE(DEBIT_15HARIAN!$C$7:$C$31),"") | E10: =IFERROR(AVERAGE(DEBIT_15HARIAN!$D$7:$D$31),"") | F10: =IFERROR(AVERAGE(DEBIT_15HARIAN!$E$7:$E$31),"") | G10: =IFERROR(AVERAGE(DEBIT_15HARIAN!$F$7:$F$31),"") | H10: =IFERROR(AVERAGE(DEBIT_15HARIAN!$G$7:$G$31),"") | I10: =IFERROR(AVERAGE(DEBIT_15HARIAN!$H$7:$H$31),"") | J10: =IFERROR(AVERAGE(DEBIT_15HARIAN!$I$7:$I$31),"") | K10: =IFERROR(AVERAGE(DEBIT_15HARIAN!$J$7:$J$31),"") | L10: =IFERROR(AVERAGE(DEBIT_15HARIAN!$K$7:$K$31),"") | M10: =IFERROR(AVERAGE(DEBIT_15HARIAN!$L$7:$L$31),"") | N10: =IFERROR(AVERAGE(DEBIT_15HARIAN!$M$7:$M$31),"") | O10: =IFERROR(AVERAGE(DEBIT_15HARIAN!$N$7:$N$31),"") | P10: =IFERROR(AVERAGE(DEBIT_15HARIAN!$O$7:$O$31),"") | Q10: =IFERROR(AVERAGE(DEBIT_15HARIAN!$P$7:$P$31),"") | R10: =IFERROR(AVERAGE(DEBIT_15HARIAN!$Q$7:$Q$31),"") | S10: =IFERROR(AVERAGE(DEBIT_15HARIAN!$R$7:$R$31),"") | T10: =IFERROR(AVERAGE(DEBIT_15HARIAN!$S$7:$S$31),"") | U10: =IFERROR(AVERAGE(DEBIT_15HARIAN!$T$7:$T$31),"") | V10: =IFERROR(AVERAGE(DEBIT_15HARIAN!$U$7:$U$31),"") | W10: =IFERROR(AVERAGE(DEBIT_15HARIAN!$V$7:$V$31),"") | X10: =IFERROR(AVERAGE(DEBIT_15HARIAN!$W$7:$W$31),"") | Y10: =IFERROR(AVERAGE(DEBIT_15HARIAN!$X$7:$X$31),"") | Z10: =IFERROR(AVERAGE(DEBIT_15HARIAN!$Y$7:$Y$31),"")
A11: Q50 = debit normal; Q80 = debit andalan irigasi; Q90 = air baku / domestik; Q95 = aliran pemeliharaan sungai (acuan umum, sesuaikan dengan pedoman yang Anda pakai).
A33: Peringkat Weibull (debit 15 harian diurutkan dari terbesar)
A34: Peringkat m | B34: P = m/(n+1) | C34: Jan I | D34: Jan II | E34: Feb I | F34: Feb II | G34: Mar I | H34: Mar II | I34: Apr I | J34: Apr II | K34: Mei I | L34: Mei II | M34: Jun I | N34: Jun II | O34: Jul I | P34: Jul II | Q34: Agu I | R34: Agu II | S34: Sep I | T34: Sep II | U34: Okt I | V34: Okt II | W34: Nov I | X34: Nov II | Y34: Des I | Z34: Des II
A35: 1 | B35: =IF(A35>$C$3,"",A35/($C$3+1)) | C35: =IF($A35>$C$3,"",LARGE(DEBIT_15HARIAN!$B$7:$B$31,$A35)) | D35: =IF($A35>$C$3,"",LARGE(DEBIT_15HARIAN!$C$7:$C$31,$A35)) | E35: =IF($A35>$C$3,"",LARGE(DEBIT_15HARIAN!$D$7:$D$31,$A35)) | F35: =IF($A35>$C$3,"",LARGE(DEBIT_15HARIAN!$E$7:$E$31,$A35)) | G35: =IF($A35>$C$3,"",LARGE(DEBIT_15HARIAN!$F$7:$F$31,$A35)) | H35: =IF($A35>$C$3,"",LARGE(DEBIT_15HARIAN!$G$7:$G$31,$A35)) | I35: =IF($A35>$C$3,"",LARGE(DEBIT_15HARIAN!$H$7:$H$31,$A35)) | J35: =IF($A35>$C$3,"",LARGE(DEBIT_15HARIAN!$I$7:$I$31,$A35)) | K35: =IF($A35>$C$3,"",LARGE(DEBIT_15HARIAN!$J$7:$J$31,$A35)) | L35: =IF($A35>$C$3,"",LARGE(DEBIT_15HARIAN!$K$7:$K$31,$A35)) | M35: =IF($A35>$C$3,"",LARGE(DEBIT_15HARIAN!$L$7:$L$31,$A35)) | N35: =IF($A35>$C$3,"",LARGE(DEBIT_15HARIAN!$M$7:$M$31,$A35)) | O35: =IF($A35>$C$3,"",LARGE(DEBIT_15HARIAN!$N$7:$N$31,$A35)) | P35: =IF($A35>$C$3,"",LARGE(DEBIT_15HARIAN!$O$7:$O$31,$A35)) | Q35: =IF($A35>$C$3,"",LARGE(DEBIT_15HARIAN!$P$7:$P$31,$A35)) | R35: =IF($A35>$C$3,"",LARGE(DEBIT_15HARIAN!$Q$7:$Q$31,$A35)) | S35: =IF($A35>$C$3,"",LARGE(DEBIT_15HARIAN!$R$7:$R$31,$A35)) | T35: =IF($A35>$C$3,"",LARGE(DEBIT_15HARIAN!$S$7:$S$31,$A35)) | U35: =IF($A35>$C$3,"",LARGE(DEBIT_15HARIAN!$T$7:$T$31,$A35)) | V35: =IF($A35>$C$3,"",LARGE(DEBIT_15HARIAN!$U$7:$U$31,$A35)) | W35: =IF($A35>$C$3,"",LARGE(DEBIT_15HARIAN!$V$7:$V$31,$A35)) | X35: =IF($A35>$C$3,"",LARGE(DEBIT_15HARIAN!$W$7:$W$31,$A35)) | Y35: =IF($A35>$C$3,"",LARGE(DEBIT_15HARIAN!$X$7:$X$31,$A35)) | Z35: =IF($A35>$C$3,"",LARGE(DEBIT_15HARIAN!$Y$7:$Y$31,$A35))
A36: 2 | B36: =IF(A36>$C$3,"",A36/($C$3+1)) | C36: =IF($A36>$C$3,"",LARGE(DEBIT_15HARIAN!$B$7:$B$31,$A36)) | D36: =IF($A36>$C$3,"",LARGE(DEBIT_15HARIAN!$C$7:$C$31,$A36)) | E36: =IF($A36>$C$3,"",LARGE(DEBIT_15HARIAN!$D$7:$D$31,$A36)) | F36: =IF($A36>$C$3,"",LARGE(DEBIT_15HARIAN!$E$7:$E$31,$A36)) | G36: =IF($A36>$C$3,"",LARGE(DEBIT_15HARIAN!$F$7:$F$31,$A36)) | H36: =IF($A36>$C$3,"",LARGE(DEBIT_15HARIAN!$G$7:$G$31,$A36)) | I36: =IF($A36>$C$3,"",LARGE(DEBIT_15HARIAN!$H$7:$H$31,$A36)) | J36: =IF($A36>$C$3,"",LARGE(DEBIT_15HARIAN!$I$7:$I$31,$A36)) | K36: =IF($A36>$C$3,"",LARGE(DEBIT_15HARIAN!$J$7:$J$31,$A36)) | L36: =IF($A36>$C$3,"",LARGE(DEBIT_15HARIAN!$K$7:$K$31,$A36)) | M36: =IF($A36>$C$3,"",LARGE(DEBIT_15HARIAN!$L$7:$L$31,$A36)) | N36: =IF($A36>$C$3,"",LARGE(DEBIT_15HARIAN!$M$7:$M$31,$A36)) | O36: =IF($A36>$C$3,"",LARGE(DEBIT_15HARIAN!$N$7:$N$31,$A36)) | P36: =IF($A36>$C$3,"",LARGE(DEBIT_15HARIAN!$O$7:$O$31,$A36)) | Q36: =IF($A36>$C$3,"",LARGE(DEBIT_15HARIAN!$P$7:$P$31,$A36)) | R36: =IF($A36>$C$3,"",LARGE(DEBIT_15HARIAN!$Q$7:$Q$31,$A36)) | S36: =IF($A36>$C$3,"",LARGE(DEBIT_15HARIAN!$R$7:$R$31,$A36)) | T36: =IF($A36>$C$3,"",LARGE(DEBIT_15HARIAN!$S$7:$S$31,$A36)) | U36: =IF($A36>$C$3,"",LARGE(DEBIT_15HARIAN!$T$7:$T$31,$A36)) | V36: =IF($A36>$C$3,"",LARGE(DEBIT_15HARIAN!$U$7:$U$31,$A36)) | W36: =IF($A36>$C$3,"",LARGE(DEBIT_15HARIAN!$V$7:$V$31,$A36)) | X36: =IF($A36>$C$3,"",LARGE(DEBIT_15HARIAN!$W$7:$W$31,$A36)) | Y36: =IF($A36>$C$3,"",LARGE(DEBIT_15HARIAN!$X$7:$X$31,$A36)) | Z36: =IF($A36>$C$3,"",LARGE(DEBIT_15HARIAN!$Y$7:$Y$31,$A36))
A37: 3 | B37: =IF(A37>$C$3,"",A37/($C$3+1)) | C37: =IF($A37>$C$3,"",LARGE(DEBIT_15HARIAN!$B$7:$B$31,$A37)) | D37: =IF($A37>$C$3,"",LARGE(DEBIT_15HARIAN!$C$7:$C$31,$A37)) | E37: =IF($A37>$C$3,"",LARGE(DEBIT_15HARIAN!$D$7:$D$31,$A37)) | F37: =IF($A37>$C$3,"",LARGE(DEBIT_15HARIAN!$E$7:$E$31,$A37)) | G37: =IF($A37>$C$3,"",LARGE(DEBIT_15HARIAN!$F$7:$F$31,$A37)) | H37: =IF($A37>$C$3,"",LARGE(DEBIT_15HARIAN!$G$7:$G$31,$A37)) | I37: =IF($A37>$C$3,"",LARGE(DEBIT_15HARIAN!$H$7:$H$31,$A37)) | J37: =IF($A37>$C$3,"",LARGE(DEBIT_15HARIAN!$I$7:$I$31,$A37)) | K37: =IF($A37>$C$3,"",LARGE(DEBIT_15HARIAN!$J$7:$J$31,$A37)) | L37: =IF($A37>$C$3,"",LARGE(DEBIT_15HARIAN!$K$7:$K$31,$A37)) | M37: =IF($A37>$C$3,"",LARGE(DEBIT_15HARIAN!$L$7:$L$31,$A37)) | N37: =IF($A37>$C$3,"",LARGE(DEBIT_15HARIAN!$M$7:$M$31,$A37)) | O37: =IF($A37>$C$3,"",LARGE(DEBIT_15HARIAN!$N$7:$N$31,$A37)) | P37: =IF($A37>$C$3,"",LARGE(DEBIT_15HARIAN!$O$7:$O$31,$A37)) | Q37: =IF($A37>$C$3,"",LARGE(DEBIT_15HARIAN!$P$7:$P$31,$A37)) | R37: =IF($A37>$C$3,"",LARGE(DEBIT_15HARIAN!$Q$7:$Q$31,$A37)) | S37: =IF($A37>$C$3,"",LARGE(DEBIT_15HARIAN!$R$7:$R$31,$A37)) | T37: =IF($A37>$C$3,"",LARGE(DEBIT_15HARIAN!$S$7:$S$31,$A37)) | U37: =IF($A37>$C$3,"",LARGE(DEBIT_15HARIAN!$T$7:$T$31,$A37)) | V37: =IF($A37>$C$3,"",LARGE(DEBIT_15HARIAN!$U$7:$U$31,$A37)) | W37: =IF($A37>$C$3,"",LARGE(DEBIT_15HARIAN!$V$7:$V$31,$A37)) | X37: =IF($A37>$C$3,"",LARGE(DEBIT_15HARIAN!$W$7:$W$31,$A37)) | Y37: =IF($A37>$C$3,"",LARGE(DEBIT_15HARIAN!$X$7:$X$31,$A37)) | Z37: =IF($A37>$C$3,"",LARGE(DEBIT_15HARIAN!$Y$7:$Y$31,$A37))
A38: 4 | B38: =IF(A38>$C$3,"",A38/($C$3+1)) | C38: =IF($A38>$C$3,"",LARGE(DEBIT_15HARIAN!$B$7:$B$31,$A38)) | D38: =IF($A38>$C$3,"",LARGE(DEBIT_15HARIAN!$C$7:$C$31,$A38)) | E38: =IF($A38>$C$3,"",LARGE(DEBIT_15HARIAN!$D$7:$D$31,$A38)) | F38: =IF($A38>$C$3,"",LARGE(DEBIT_15HARIAN!$E$7:$E$31,$A38)) | G38: =IF($A38>$C$3,"",LARGE(DEBIT_15HARIAN!$F$7:$F$31,$A38)) | H38: =IF($A38>$C$3,"",LARGE(DEBIT_15HARIAN!$G$7:$G$31,$A38)) | I38: =IF($A38>$C$3,"",LARGE(DEBIT_15HARIAN!$H$7:$H$31,$A38)) | J38: =IF($A38>$C$3,"",LARGE(DEBIT_15HARIAN!$I$7:$I$31,$A38)) | K38: =IF($A38>$C$3,"",LARGE(DEBIT_15HARIAN!$J$7:$J$31,$A38)) | L38: =IF($A38>$C$3,"",LARGE(DEBIT_15HARIAN!$K$7:$K$31,$A38)) | M38: =IF($A38>$C$3,"",LARGE(DEBIT_15HARIAN!$L$7:$L$31,$A38)) | N38: =IF($A38>$C$3,"",LARGE(DEBIT_15HARIAN!$M$7:$M$31,$A38)) | O38: =IF($A38>$C$3,"",LARGE(DEBIT_15HARIAN!$N$7:$N$31,$A38)) | P38: =IF($A38>$C$3,"",LARGE(DEBIT_15HARIAN!$O$7:$O$31,$A38)) | Q38: =IF($A38>$C$3,"",LARGE(DEBIT_15HARIAN!$P$7:$P$31,$A38)) | R38: =IF($A38>$C$3,"",LARGE(DEBIT_15HARIAN!$Q$7:$Q$31,$A38)) | S38: =IF($A38>$C$3,"",LARGE(DEBIT_15HARIAN!$R$7:$R$31,$A38)) | T38: =IF($A38>$C$3,"",LARGE(DEBIT_15HARIAN!$S$7:$S$31,$A38)) | U38: =IF($A38>$C$3,"",LARGE(DEBIT_15HARIAN!$T$7:$T$31,$A38)) | V38: =IF($A38>$C$3,"",LARGE(DEBIT_15HARIAN!$U$7:$U$31,$A38)) | W38: =IF($A38>$C$3,"",LARGE(DEBIT_15HARIAN!$V$7:$V$31,$A38)) | X38: =IF($A38>$C$3,"",LARGE(DEBIT_15HARIAN!$W$7:$W$31,$A38)) | Y38: =IF($A38>$C$3,"",LARGE(DEBIT_15HARIAN!$X$7:$X$31,$A38)) | Z38: =IF($A38>$C$3,"",LARGE(DEBIT_15HARIAN!$Y$7:$Y$31,$A38))
A39: 5 | B39: =IF(A39>$C$3,"",A39/($C$3+1)) | C39: =IF($A39>$C$3,"",LARGE(DEBIT_15HARIAN!$B$7:$B$31,$A39)) | D39: =IF($A39>$C$3,"",LARGE(DEBIT_15HARIAN!$C$7:$C$31,$A39)) | E39: =IF($A39>$C$3,"",LARGE(DEBIT_15HARIAN!$D$7:$D$31,$A39)) | F39: =IF($A39>$C$3,"",LARGE(DEBIT_15HARIAN!$E$7:$E$31,$A39)) | G39: =IF($A39>$C$3,"",LARGE(DEBIT_15HARIAN!$F$7:$F$31,$A39)) | H39: =IF($A39>$C$3,"",LARGE(DEBIT_15HARIAN!$G$7:$G$31,$A39)) | I39: =IF($A39>$C$3,"",LARGE(DEBIT_15HARIAN!$H$7:$H$31,$A39)) | J39: =IF($A39>$C$3,"",LARGE(DEBIT_15HARIAN!$I$7:$I$31,$A39)) | K39: =IF($A39>$C$3,"",LARGE(DEBIT_15HARIAN!$J$7:$J$31,$A39)) | L39: =IF($A39>$C$3,"",LARGE(DEBIT_15HARIAN!$K$7:$K$31,$A39)) | M39: =IF($A39>$C$3,"",LARGE(DEBIT_15HARIAN!$L$7:$L$31,$A39)) | N39: =IF($A39>$C$3,"",LARGE(DEBIT_15HARIAN!$M$7:$M$31,$A39)) | O39: =IF($A39>$C$3,"",LARGE(DEBIT_15HARIAN!$N$7:$N$31,$A39)) | P39: =IF($A39>$C$3,"",LARGE(DEBIT_15HARIAN!$O$7:$O$31,$A39)) | Q39: =IF($A39>$C$3,"",LARGE(DEBIT_15HARIAN!$P$7:$P$31,$A39)) | R39: =IF($A39>$C$3,"",LARGE(DEBIT_15HARIAN!$Q$7:$Q$31,$A39)) | S39: =IF($A39>$C$3,"",LARGE(DEBIT_15HARIAN!$R$7:$R$31,$A39)) | T39: =IF($A39>$C$3,"",LARGE(DEBIT_15HARIAN!$S$7:$S$31,$A39)) | U39: =IF($A39>$C$3,"",LARGE(DEBIT_15HARIAN!$T$7:$T$31,$A39)) | V39: =IF($A39>$C$3,"",LARGE(DEBIT_15HARIAN!$U$7:$U$31,$A39)) | W39: =IF($A39>$C$3,"",LARGE(DEBIT_15HARIAN!$V$7:$V$31,$A39)) | X39: =IF($A39>$C$3,"",LARGE(DEBIT_15HARIAN!$W$7:$W$31,$A39)) | Y39: =IF($A39>$C$3,"",LARGE(DEBIT_15HARIAN!$X$7:$X$31,$A39)) | Z39: =IF($A39>$C$3,"",LARGE(DEBIT_15HARIAN!$Y$7:$Y$31,$A39))
A40: 6 | B40: =IF(A40>$C$3,"",A40/($C$3+1)) | C40: =IF($A40>$C$3,"",LARGE(DEBIT_15HARIAN!$B$7:$B$31,$A40)) | D40: =IF($A40>$C$3,"",LARGE(DEBIT_15HARIAN!$C$7:$C$31,$A40)) | E40: =IF($A40>$C$3,"",LARGE(DEBIT_15HARIAN!$D$7:$D$31,$A40)) | F40: =IF($A40>$C$3,"",LARGE(DEBIT_15HARIAN!$E$7:$E$31,$A40)) | G40: =IF($A40>$C$3,"",LARGE(DEBIT_15HARIAN!$F$7:$F$31,$A40)) | H40: =IF($A40>$C$3,"",LARGE(DEBIT_15HARIAN!$G$7:$G$31,$A40)) | I40: =IF($A40>$C$3,"",LARGE(DEBIT_15HARIAN!$H$7:$H$31,$A40)) | J40: =IF($A40>$C$3,"",LARGE(DEBIT_15HARIAN!$I$7:$I$31,$A40)) | K40: =IF($A40>$C$3,"",LARGE(DEBIT_15HARIAN!$J$7:$J$31,$A40)) | L40: =IF($A40>$C$3,"",LARGE(DEBIT_15HARIAN!$K$7:$K$31,$A40)) | M40: =IF($A40>$C$3,"",LARGE(DEBIT_15HARIAN!$L$7:$L$31,$A40)) | N40: =IF($A40>$C$3,"",LARGE(DEBIT_15HARIAN!$M$7:$M$31,$A40)) | O40: =IF($A40>$C$3,"",LARGE(DEBIT_15HARIAN!$N$7:$N$31,$A40)) | P40: =IF($A40>$C$3,"",LARGE(DEBIT_15HARIAN!$O$7:$O$31,$A40)) | Q40: =IF($A40>$C$3,"",LARGE(DEBIT_15HARIAN!$P$7:$P$31,$A40)) | R40: =IF($A40>$C$3,"",LARGE(DEBIT_15HARIAN!$Q$7:$Q$31,$A40)) | S40: =IF($A40>$C$3,"",LARGE(DEBIT_15HARIAN!$R$7:$R$31,$A40)) | T40: =IF($A40>$C$3,"",LARGE(DEBIT_15HARIAN!$S$7:$S$31,$A40)) | U40: =IF($A40>$C$3,"",LARGE(DEBIT_15HARIAN!$T$7:$T$31,$A40)) | V40: =IF($A40>$C$3,"",LARGE(DEBIT_15HARIAN!$U$7:$U$31,$A40)) | W40: =IF($A40>$C$3,"",LARGE(DEBIT_15HARIAN!$V$7:$V$31,$A40)) | X40: =IF($A40>$C$3,"",LARGE(DEBIT_15HARIAN!$W$7:$W$31,$A40)) | Y40: =IF($A40>$C$3,"",LARGE(DEBIT_15HARIAN!$X$7:$X$31,$A40)) | Z40: =IF($A40>$C$3,"",LARGE(DEBIT_15HARIAN!$Y$7:$Y$31,$A40))
