Workbook

Sheet INFO
A1: KETERSEDIAAN AIR METODE WEIBULL - Lola_Besar (Outlet)
A3: DAS / proyek | B3: Lola_Besar
A4: Elemen | B4: Outlet
A5: Luas tangkapan (km²) | B5: 73.2339
A6: Periode simulasi | B6: 2001-01-01 00:00 s/d 2026-01-01 00:00 (interval 1440 menit)
A7: Data debit harian | B7: 01-01-2001 s/d 31-12-2025 (9131 hari)
A8: Tahun lengkap (dipakai Weibull) | B8: 2001, 2002, 2003, 2004, 2005, 2006, 2007, 2008, 2009, 2010, 2011, 2012, 2013, 2014, 2015, 2016, 2017, 2018, 2019, 2020, 2021, 2022, 2023, 2024, 2025
A9: Syarat tahun lengkap | B9: setiap periode 15 harian punya minimal 10 hari data
A10: Tahun tidak lengkap | B10: -
A11: Hujan | B11: Hujan satelit terkalibrasi - Kalibrasi, pos Bula, Quantile mapping, mutu Baik
A12: Dibuat | B12: 21-10-2026 13:31 - HEC-HMS DAS Analyzer, menu Simulasi
A14: Catatan
A15: - WEIBULL_BULANAN / WEIBULL_15HARIAN: debit rata-rata bulanan / 15 harian tiap tahun lengkap diurutkan dari terbesar ke terkecil; peluang terlampaui P = m/(n+1); Q50, Q80, Q90, Q95 diinterpolasi linier antar peringkat.
A16: - ANDALAN_HARIAN: kurva durasi aliran dari DEBIT HARIAN (semua hari, dan per bulan - debit harian bulan itu dari semua tahun dikumpulkan) dengan peluang Weibull yang sama.
A17: - Semua angka turunan adalah rumus Excel yang merujuk lembar DEBIT_HARIAN (angka biru = hasil simulasi).
A18: - 15 harian: periode I = tanggal 1-15, periode II = tanggal 16 s/d akhir bulan.

Sheet WEIBULL_BULANAN
A1: DEBIT ANDALAN BULANAN (WEIBULL) - Outlet
A2: Debit rata-rata bulanan tiap tahun lengkap diurutkan dari terbesar; peluang terlampaui P = m / (n + 1) (Weibull). Q-P diinterpolasi linier antar peringkat.
A3: Jumlah tahun lengkap (n) | C3: =COUNT(DEBIT_BULANAN!$A$7:$A$31)
A5: Debit andalan | B5: Peluang P | C5: Jan | D5: Feb | E5: Mar | F5: Apr | G5: Mei | H5: Jun | I5: Jul | J5: Agu | K5: Sep | L5: Okt | M5: Nov | N5: Des
A6: Q50 (m³/s) | B6: 0.5 | C6: =IF($C$3<1,"",IF(INT($B6*($C$3+1))<1,LARGE(DEBIT_BULANAN!$B$7:$B$31,1),IF(INT($B6*($C$3+1))>=$C$3,LARGE(DEBIT_BULANAN!$B$7:$B$31,$C$3),LARGE(DEBIT_BULANAN!$B$7:$B$31,INT($B6*($C$3+1)))+($B6*($C$3+1)-INT($B6*($C$3+1)))*(LARGE(DEBIT_BULANAN!$B$7:$B$31,INT($B6*($C$3+1))+1)-LARGE(DEBIT_BULANAN!$B$7:$B$31,INT($B6*($C$3+1))))))) | D6: =IF($C$3<1,"",IF(INT($B6*($C$3+1))<1,LARGE(DEBIT_BULANAN!$C$7:$C$31,1),IF(INT($B6*($C$3+1))>=$C$3,LARGE(DEBIT_BULANAN!$C$7:$C$31,$C$3),LARGE(DEBIT_BULANAN!$C$7:$C$31,INT($B6*($C$3+1)))+($B6*($C$3+1)-INT($B6*($C$3+1)))*(LARGE(DEBIT_BULANAN!$C$7:$C$31,INT($B6*($C$3+1))+1)-LARGE(DEBIT_BULANAN!$C$7:$C$31,INT($B6*($C$3+1))))))) | E6: =IF($C$3<1,"",IF(INT($B6*($C$3+1))<1,LARGE(DEBIT_BULANAN!$D$7:$D$31,1),IF(INT($B6*($C$3+1))>=$C$3,LARGE(DEBIT_BULANAN!$D$7:$D$31,$C$3),LARGE(DEBIT_BULANAN!$D$7:$D$31,INT($B6*($C$3+1)))+($B6*($C$3+1)-INT($B6*($C$3+1)))*(LARGE(DEBIT_BULANAN!$D$7:$D$31,INT($B6*($C$3+1))+1)-LARGE(DEBIT_BULANAN!$D$7:$D$31,INT($B6*($C$3+1))))))) | F6: =IF($C$3<1,"",IF(INT($B6*($C$3+1))<1,LARGE(DEBIT_BULANAN!$E$7:$E$31,1),IF(INT($B6*($C$3+1))>=$C$3,LARGE(DEBIT_BULANAN!$E$7:$E$31,$C$3),LARGE(DEBIT_BULANAN!$E$7:$E$31,INT($B6*($C$3+1)))+($B6*($C$3+1)-INT($B6*($C$3+1)))*(LARGE(DEBIT_BULANAN!$E$7:$E$31,INT($B6*($C$3+1))+1)-LARGE(DEBIT_BULANAN!$E$7:$E$31,INT($B6*($C$3+1))))))) | G6: =IF($C$3<1,"",IF(INT($B6*($C$3+1))<1,LARGE(DEBIT_BULANAN!$F$7:$F$31,1),IF(INT($B6*($C$3+1))>=$C$3,LARGE(DEBIT_BULANAN!$F$7:$F$31,$C$3),LARGE(DEBIT_BULANAN!$F$7:$F$31,INT($B6*($C$3+1)))+($B6*($C$3+1)-INT($B6*($C$3+1)))*(LARGE(DEBIT_BULANAN!$F$7:$F$31,INT($B6*($C$3+1))+1)-LARGE(DEBIT_BULANAN!$F$7:$F$31,INT($B6*($C$3+1))))))) | H6: =IF($C$3<1,"",IF(INT($B6*($C$3+1))<1,LARGE(DEBIT_BULANAN!$G$7:$G$31,1),IF(INT($B6*($C$3+1))>=$C$3,LARGE(DEBIT_BULANAN!$G$7:$G$31,$C$3),LARGE(DEBIT_BULANAN!$G$7:$G$31,INT($B6*($C$3+1)))+($B6*($C$3+1)-INT($B6*($C$3+1)))*(LARGE(DEBIT_BULANAN!$G$7:$G$31,INT($B6*($C$3+1))+1)-LARGE(DEBIT_BULANAN!$G$7:$G$31,INT($B6*($C$3+1))))))) | I6: =IF($C$3<1,"",IF(INT($B6*($C$3+1))<1,LARGE(DEBIT_BULANAN!$H$7:$H$31,1),IF(INT($B6*($C$3+1))>=$C$3,LARGE(DEBIT_BULANAN!$H$7:$H$31,$C$3),LARGE(DEBIT_BULANAN!$H$7:$H$31,INT($B6*($C$3+1)))+($B6*($C$3+1)-INT($B6*($C$3+1)))*(LARGE(DEBIT_BULANAN!$H$7:$H$31,INT($B6*($C$3+1))+1)-LARGE(DEBIT_BULANAN!$H$7:$H$31,INT($B6*($C$3+1))))))) | J6: =IF($C$3<1,"",IF(INT($B6*($C$3+1))<1,LARGE(DEBIT_BULANAN!$I$7:$I$31,1),IF(INT($B6*($C$3+1))>=$C$3,LARGE(DEBIT_BULANAN!$I$7:$I$31,$C$3),LARGE(DEBIT_BULANAN!$I$7:$I$31,INT($B6*($C$3+1)))+($B6*($C$3+1)-INT($B6*($C$3+1)))*(LARGE(DEBIT_BULANAN!$I$7:$I$31,INT($B6*($C$3+1))+1)-LARGE(DEBIT_BULANAN!$I$7:$I$31,INT($B6*($C$3+1))))))) | K6: =IF($C$3<1,"",IF(INT($B6*($C$3+1))<1,LARGE(DEBIT_BULANAN!$J$7:$J$31,1),IF(INT($B6*($C$3+1))>=$C$3,LARGE(DEBIT_BULANAN!$J$7:$J$31,$C$3),LARGE(DEBIT_BULANAN!$J$7:$J$31,INT($B6*($C$3+1)))+($B6*($C$3+1)-INT($B6*($C$3+1)))*(LARGE(DEBIT_BULANAN!$J$7:$J$31,INT($B6*($C$3+1))+1)-LARGE(DEBIT_BULANAN!$J$7:$J$31,INT($B6*($C$3+1))))))) | L6: =IF($C$3<1,"",IF(INT($B6*($C$3+1))<1,LARGE(DEBIT_BULANAN!$K$7:$K$31,1),IF(INT($B6*($C$3+1))>=$C$3,LARGE(DEBIT_BULANAN!$K$7:$K$31,$C$3),LARGE(DEBIT_BULANAN!$K$7:$K$31,INT($B6*($C$3+1)))+($B6*($C$3+1)-INT($B6*($C$3+1)))*(LARGE(DEBIT_BULANAN!$K$7:$K$31,INT($B6*($C$3+1))+1)-LARGE(DEBIT_BULANAN!$K$7:$K$31,INT($B6*($C$3+1))))))) | M6: =IF($C$3<1,"",IF(INT($B6*($C$3+1))<1,LARGE(DEBIT_BULANAN!$L$7:$L$31,1),IF(INT($B6*($C$3+1))>=$C$3,LARGE(DEBIT_BULANAN!$L$7:$L$31,$C$3),LARGE(DEBIT_BULANAN!$L$7:$L$31,INT($B6*($C$3+1)))+($B6*($C$3+1)-INT($B6*($C$3+1)))*(LARGE(DEBIT_BULANAN!$L$7:$L$31,INT($B6*($C$3+1))+1)-LARGE(DEBIT_BULANAN!$L$7:$L$31,INT($B6*($C$3+1))))))) | N6: =IF($C$3<1,"",IF(INT($B6*($C$3+1))<1,LARGE(DEBIT_BULANAN!$M$7:$M$31,1),IF(INT($B6*($C$3+1))>=$C$3,LARGE(DEBIT_BULANAN!$M$7:$M$31,$C$3),LARGE(DEBIT_BULANAN!$M$7:$M$31,INT($B6*($C$3+1)))+($B6*($C$3+1)-INT($B6*($C$3+1)))*(LARGE(DEBIT_BULANAN!$M$7:$M$31,INT($B6*($C$3+1))+1)-LARGE(DEBIT_BULANAN!$M$7:$M$31,INT($B6*($C$3+1)))))))
A7: Q80 (m³/s) | B7: 0.8 | C7: =IF($C$3<1,"",IF(INT($B7*($C$3+1))<1,LARGE(DEBIT_BULANAN!$B$7:$B$31,1),IF(INT($B7*($C$3+1))>=$C$3,LARGE(DEBIT_BULANAN!$B$7:$B$31,$C$3),LARGE(DEBIT_BULANAN!$B$7:$B$31,INT($B7*($C$3+1)))+($B7*($C$3+1)-INT($B7*($C$3+1)))*(LARGE(DEBIT_BULANAN!$B$7:$B$31,INT($B7*($C$3+1))+1)-LARGE(DEBIT_BULANAN!$B$7:$B$31,INT($B7*($C$3+1))))))) | D7: =IF($C$3<1,"",IF(INT($B7*($C$3+1))<1,LARGE(DEBIT_BULANAN!$C$7:$C$31,1),IF(INT($B7*($C$3+1))>=$C$3,LARGE(DEBIT_BULANAN!$C$7:$C$31,$C$3),LARGE(DEBIT_BULANAN!$C$7:$C$31,INT($B7*($C$3+1)))+($B7*($C$3+1)-INT($B7*($C$3+1)))*(LARGE(DEBIT_BULANAN!$C$7:$C$31,INT($B7*($C$3+1))+1)-LARGE(DEBIT_BULANAN!$C$7:$C$31,INT($B7*($C$3+1))))))) | E7: =IF($C$3<1,"",IF(INT($B7*($C$3+1))<1,LARGE(DEBIT_BULANAN!$D$7:$D$31,1),IF(INT($B7*($C$3+1))>=$C$3,LARGE(DEBIT_BULANAN!$D$7:$D$31,$C$3),LARGE(DEBIT_BULANAN!$D$7:$D$31,INT($B7*($C$3+1)))+($B7*($C$3+1)-INT($B7*($C$3+1)))*(LARGE(DEBIT_BULANAN!$D$7:$D$31,INT($B7*($C$3+1))+1)-LARGE(DEBIT_BULANAN!$D$7:$D$31,INT($B7*($C$3+1))))))) | F7: =IF($C$3<1,"",IF(INT($B7*($C$3+1))<1,LARGE(DEBIT_BULANAN!$E$7:$E$31,1),IF(INT($B7*($C$3+1))>=$C$3,LARGE(DEBIT_BULANAN!$E$7:$E$31,$C$3),LARGE(DEBIT_BULANAN!$E$7:$E$31,INT($B7*($C$3+1)))+($B7*($C$3+1)-INT($B7*($C$3+1)))*(LARGE(DEBIT_BULANAN!$E$7:$E$31,INT($B7*($C$3+1))+1)-LARGE(DEBIT_BULANAN!$E$7:$E$31,INT($B7*($C$3+1))))))) | G7: =IF($C$3<1,"",IF(INT($B7*($C$3+1))<1,LARGE(DEBIT_BULANAN!$F$7:$F$31,1),IF(INT($B7*($C$3+1))>=$C$3,LARGE(DEBIT_BULANAN!$F$7:$F$31,$C$3),LARGE(DEBIT_BULANAN!$F$7:$F$31,INT($B7*($C$3+1)))+($B7*($C$3+1)-INT($B7*($C$3+1)))*(LARGE(DEBIT_BULANAN!$F$7:$F$31,INT($B7*($C$3+1))+1)-LARGE(DEBIT_BULANAN!$F$7:$F$31,INT($B7*($C$3+1))))))) | H7: =IF($C$3<1,"",IF(INT($B7*($C$3+1))<1,LARGE(DEBIT_BULANAN!$G$7:$G$31,1),IF(INT($B7*($C$3+1))>=$C$3,LARGE(DEBIT_BULANAN!$G$7:$G$31,$C$3),LARGE(DEBIT_BULANAN!$G$7:$G$31,INT($B7*($C$3+1)))+($B7*($C$3+1)-INT($B7*($C$3+1)))*(LARGE(DEBIT_BULANAN!$G$7:$G$31,INT($B7*($C$3+1))+1)-LARGE(DEBIT_BULANAN!$G$7:$G$31,INT($B7*($C$3+1))))))) | I7: =IF($C$3<1,"",IF(INT($B7*($C$3+1))<1,LARGE(DEBIT_BULANAN!$H$7:$H$31,1),IF(INT($B7*($C$3+1))>=$C$3,LARGE(DEBIT_BULANAN!$H$7:$H$31,$C$3),LARGE(DEBIT_BULANAN!$H$7:$H$31,INT($B7*($C$3+1)))+($B7*($C$3+1)-INT($B7*($C$3+1)))*(LARGE(DEBIT_BULANAN!$H$7:$H$31,INT($B7*($C$3+1))+1)-LARGE(DEBIT_BULANAN!$H$7:$H$31,INT($B7*($C$3+1))))))) | J7: =IF($C$3<1,"",IF(INT($B7*($C$3+1))<1,LARGE(DEBIT_BULANAN!$I$7:$I$31,1),IF(INT($B7*($C$3+1))>=$C$3,LARGE(DEBIT_BULANAN!$I$7:$I$31,$C$3),LARGE(DEBIT_BULANAN!$I$7:$I$31,INT($B7*($C$3+1)))+($B7*($C$3+1)-INT($B7*($C$3+1)))*(LARGE(DEBIT_BULANAN!$I$7:$I$31,INT($B7*($C$3+1))+1)-LARGE(DEBIT_BULANAN!$I$7:$I$31,INT($B7*($C$3+1))))))) | K7: =IF($C$3<1,"",IF(INT($B7*($C$3+1))<1,LARGE(DEBIT_BULANAN!$J$7:$J$31,1),IF(INT($B7*($C$3+1))>=$C$3,LARGE(DEBIT_BULANAN!$J$7:$J$31,$C$3),LARGE(DEBIT_BULANAN!$J$7:$J$31,INT($B7*($C$3+1)))+($B7*($C$3+1)-INT($B7*($C$3+1)))*(LARGE(DEBIT_BULANAN!$J$7:$J$31,INT($B7*($C$3+1))+1)-LARGE(DEBIT_BULANAN!$J$7:$J$31,INT($B7*($C$3+1))))))) | L7: =IF($C$3<1,"",IF(INT($B7*($C$3+1))<1,LARGE(DEBIT_BULANAN!$K$7:$K$31,1),IF(INT($B7*($C$3+1))>=$C$3,LARGE(DEBIT_BULANAN!$K$7:$K$31,$C$3),LARGE(DEBIT_BULANAN!$K$7:$K$31,INT($B7*($C$3+1)))+($B7*($C$3+1)-INT($B7*($C$3+1)))*(LARGE(DEBIT_BULANAN!$K$7:$K$31,INT($B7*($C$3+1))+1)-LARGE(DEBIT_BULANAN!$K$7:$K$31,INT($B7*($C$3+1))))))) | M7: =IF($C$3<1,"",IF(INT($B7*($C$3+1))<1,LARGE(DEBIT_BULANAN!$L$7:$L$31,1),IF(INT($B7*($C$3+1))>=$C$3,LARGE(DEBIT_BULANAN!$L$7:$L$31,$C$3),LARGE(DEBIT_BULANAN!$L$7:$L$31,INT($B7*($C$3+1)))+($B7*($C$3+1)-INT($B7*($C$3+1)))*(LARGE(DEBIT_BULANAN!$L$7:$L$31,INT($B7*($C$3+1))+1)-LARGE(DEBIT_BULANAN!$L$7:$L$31,INT($B7*($C$3+1))))))) | N7: =IF($C$3<1,"",IF(INT($B7*($C$3+1))<1,LARGE(DEBIT_BULANAN!$M$7:$M$31,1),IF(INT($B7*($C$3+1))>=$C$3,LARGE(DEBIT_BULANAN!$M$7:$M$31,$C$3),LARGE(DEBIT_BULANAN!$M$7:$M$31,INT($B7*($C$3+1)))+($B7*($C$3+1)-INT($B7*($C$3+1)))*(LARGE(DEBIT_BULANAN!$M$7:$M$31,INT($B7*($C$3+1))+1)-LARGE(DEBIT_BULANAN!$M$7:$M$31,INT($B7*($C$3+1)))))))
A8: Q90 (m³/s) | B8: 0.9 | C8: =IF($C$3<1,"",IF(INT($B8*($C$3+1))<1,LARGE(DEBIT_BULANAN!$B$7:$B$31,1),IF(INT($B8*($C$3+1))>=$C$3,LARGE(DEBIT_BULANAN!$B$7:$B$31,$C$3),LARGE(DEBIT_BULANAN!$B$7:$B$31,INT($B8*($C$3+1)))+($B8*($C$3+1)-INT($B8*($C$3+1)))*(LARGE(DEBIT_BULANAN!$B$7:$B$31,INT($B8*($C$3+1))+1)-LARGE(DEBIT_BULANAN!$B$7:$B$31,INT($B8*($C$3+1))))))) | D8: =IF($C$3<1,"",IF(INT($B8*($C$3+1))<1,LARGE(DEBIT_BULANAN!$C$7:$C$31,1),IF(INT($B8*($C$3+1))>=$C$3,LARGE(DEBIT_BULANAN!$C$7:$C$31,$C$3),LARGE(DEBIT_BULANAN!$C$7:$C$31,INT($B8*($C$3+1)))+($B8*($C$3+1)-INT($B8*($C$3+1)))*(LARGE(DEBIT_BULANAN!$C$7:$C$31,INT($B8*($C$3+1))+1)-LARGE(DEBIT_BULANAN!$C$7:$C$31,INT($B8*($C$3+1))))))) | E8: =IF($C$3<1,"",IF(INT($B8*($C$3+1))<1,LARGE(DEBIT_BULANAN!$D$7:$D$31,1),IF(INT($B8*($C$3+1))>=$C$3,LARGE(DEBIT_BULANAN!$D$7:$D$31,$C$3),LARGE(DEBIT_BULANAN!$D$7:$D$31,INT($B8*($C$3+1)))+($B8*($C$3+1)-INT($B8*($C$3+1)))*(LARGE(DEBIT_BULANAN!$D$7:$D$31,INT($B8*($C$3+1))+1)-LARGE(DEBIT_BULANAN!$D$7:$D$31,INT($B8*($C$3+1))))))) | F8: =IF($C$3<1,"",IF(INT($B8*($C$3+1))<1,LARGE(DEBIT_BULANAN!$E$7:$E$31,1),IF(INT($B8*($C$3+1))>=$C$3,LARGE(DEBIT_BULANAN!$E$7:$E$31,$C$3),LARGE(DEBIT_BULANAN!$E$7:$E$31,INT($B8*($C$3+1)))+($B8*($C$3+1)-INT($B8*($C$3+1)))*(LARGE(DEBIT_BULANAN!$E$7:$E$31,INT($B8*($C$3+1))+1)-LARGE(DEBIT_BULANAN!$E$7:$E$31,INT($B8*($C$3+1))))))) | G8: =IF($C$3<1,"",IF(INT($B8*($C$3+1))<1,LARGE(DEBIT_BULANAN!$F$7:$F$31,1),IF(INT($B8*($C$3+1))>=$C$3,LARGE(DEBIT_BULANAN!$F$7:$F$31,$C$3),LARGE(DEBIT_BULANAN!$F$7:$F$31,INT($B8*($C$3+1)))+($B8*($C$3+1)-INT($B8*($C$3+1)))*(LARGE(DEBIT_BULANAN!$F$7:$F$31,INT($B8*($C$3+1))+1)-LARGE(DEBIT_BULANAN!$F$7:$F$31,INT($B8*($C$3+1))))))) | H8: =IF($C$3<1,"",IF(INT($B8*($C$3+1))<1,LARGE(DEBIT_BULANAN!$G$7:$G$31,1),IF(INT($B8*($C$3+1))>=$C$3,LARGE(DEBIT_BULANAN!$G$7:$G$31,$C$3),LARGE(DEBIT_BULANAN!$G$7:$G$31,INT($B8*($C$3+1)))+($B8*($C$3+1)-INT($B8*($C$3+1)))*(LARGE(DEBIT_BULANAN!$G$7:$G$31,INT($B8*($C$3+1))+1)-LARGE(DEBIT_BULANAN!$G$7:$G$31,INT($B8*($C$3+1))))))) | I8: =IF($C$3<1,"",IF(INT($B8*($C$3+1))<1,LARGE(DEBIT_BULANAN!$H$7:$H$31,1),IF(INT($B8*($C$3+1))>=$C$3,LARGE(DEBIT_BULANAN!$H$7:$H$31,$C$3),LARGE(DEBIT_BULANAN!$H$7:$H$31,INT($B8*($C$3+1)))+($B8*($C$3+1)-INT($B8*($C$3+1)))*(LARGE(DEBIT_BULANAN!$H$7:$H$31,INT($B8*($C$3+1))+1)-LARGE(DEBIT_BULANAN!$H$7:$H$31,INT($B8*($C$3+1))))))) | J8: =IF($C$3<1,"",IF(INT($B8*($C$3+1))<1,LARGE(DEBIT_BULANAN!$I$7:$I$31,1),IF(INT($B8*($C$3+1))>=$C$3,LARGE(DEBIT_BULANAN!$I$7:$I$31,$C$3),LARGE(DEBIT_BULANAN!$I$7:$I$31,INT($B8*($C$3+1)))+($B8*($C$3+1)-INT($B8*($C$3+1)))*(LARGE(DEBIT_BULANAN!$I$7:$I$31,INT($B8*($C$3+1))+1)-LARGE(DEBIT_BULANAN!$I$7:$I$31,INT($B8*($C$3+1))))))) | K8: =IF($C$3<1,"",IF(INT($B8*($C$3+1))<1,LARGE(DEBIT_BULANAN!$J$7:$J$31,1),IF(INT($B8*($C$3+1))>=$C$3,LARGE(DEBIT_BULANAN!$J$7:$J$31,$C$3),LARGE(DEBIT_BULANAN!$J$7:$J$31,INT($B8*($C$3+1)))+($B8*($C$3+1)-INT($B8*($C$3+1)))*(LARGE(DEBIT_BULANAN!$J$7:$J$31,INT($B8*($C$3+1))+1)-LARGE(DEBIT_BULANAN!$J$7:$J$31,INT($B8*($C$3+1))))))) | L8: =IF($C$3<1,"",IF(INT($B8*($C$3+1))<1,LARGE(DEBIT_BULANAN!$K$7:$K$31,1),IF(INT($B8*($C$3+1))>=$C$3,LARGE(DEBIT_BULANAN!$K$7:$K$31,$C$3),LARGE(DEBIT_BULANAN!$K$7:$K$31,INT($B8*($C$3+1)))+($B8*($C$3+1)-INT($B8*($C$3+1)))*(LARGE(DEBIT_BULANAN!$K$7:$K$31,INT($B8*($C$3+1))+1)-LARGE(DEBIT_BULANAN!$K$7:$K$31,INT($B8*($C$3+1))))))) | M8: =IF($C$3<1,"",IF(INT($B8*($C$3+1))<1,LARGE(DEBIT_BULANAN!$L$7:$L$31,1),IF(INT($B8*($C$3+1))>=$C$3,LARGE(DEBIT_BULANAN!$L$7:$L$31,$C$3),LARGE(DEBIT_BULANAN!$L$7:$L$31,INT($B8*($C$3+1)))+($B8*($C$3+1)-INT($B8*($C$3+1)))*(LARGE(DEBIT_BULANAN!$L$7:$L$31,INT($B8*($C$3+1))+1)-LARGE(DEBIT_BULANAN!$L$7:$L$31,INT($B8*($C$3+1))))))) | N8: =IF($C$3<1,"",IF(INT($B8*($C$3+1))<1,LARGE(DEBIT_BULANAN!$M$7:$M$31,1),IF(INT($B8*($C$3+1))>=$C$3,LARGE(DEBIT_BULANAN!$M$7:$M$31,$C$3),LARGE(DEBIT_BULANAN!$M$7:$M$31,INT($B8*($C$3+1)))+($B8*($C$3+1)-INT($B8*($C$3+1)))*(LARGE(DEBIT_BULANAN!$M$7:$M$31,INT($B8*($C$3+1))+1)-LARGE(DEBIT_BULANAN!$M$7:$M$31,INT($B8*($C$3+1)))))))
A9: Q95 (m³/s) | B9: 0.95 | C9: =IF($C$3<1,"",IF(INT($B9*($C$3+1))<1,LARGE(DEBIT_BULANAN!$B$7:$B$31,1),IF(INT($B9*($C$3+1))>=$C$3,LARGE(DEBIT_BULANAN!$B$7:$B$31,$C$3),LARGE(DEBIT_BULANAN!$B$7:$B$31,INT($B9*($C$3+1)))+($B9*($C$3+1)-INT($B9*($C$3+1)))*(LARGE(DEBIT_BULANAN!$B$7:$B$31,INT($B9*($C$3+1))+1)-LARGE(DEBIT_BULANAN!$B$7:$B$31,INT($B9*($C$3+1))))))) | D9: =IF($C$3<1,"",IF(INT($B9*($C$3+1))<1,LARGE(DEBIT_BULANAN!$C$7:$C$31,1),IF(INT($B9*($C$3+1))>=$C$3,LARGE(DEBIT_BULANAN!$C$7:$C$31,$C$3),LARGE(DEBIT_BULANAN!$C$7:$C$31,INT($B9*($C$3+1)))+($B9*($C$3+1)-INT($B9*($C$3+1)))*(LARGE(DEBIT_BULANAN!$C$7:$C$31,INT($B9*($C$3+1))+1)-LARGE(DEBIT_BULANAN!$C$7:$C$31,INT($B9*($C$3+1))))))) | E9: =IF($C$3<1,"",IF(INT($B9*($C$3+1))<1,LARGE(DEBIT_BULANAN!$D$7:$D$31,1),IF(INT($B9*($C$3+1))>=$C$3,LARGE(DEBIT_BULANAN!$D$7:$D$31,$C$3),LARGE(DEBIT_BULANAN!$D$7:$D$31,INT($B9*($C$3+1)))+($B9*($C$3+1)-INT($B9*($C$3+1)))*(LARGE(DEBIT_BULANAN!$D$7:$D$31,INT($B9*($C$3+1))+1)-LARGE(DEBIT_BULANAN!$D$7:$D$31,INT($B9*($C$3+1))))))) | F9: =IF($C$3<1,"",IF(INT($B9*($C$3+1))<1,LARGE(DEBIT_BULANAN!$E$7:$E$31,1),IF(INT($B9*($C$3+1))>=$C$3,LARGE(DEBIT_BULANAN!$E$7:$E$31,$C$3),LARGE(DEBIT_BULANAN!$E$7:$E$31,INT($B9*($C$3+1)))+($B9*($C$3+1)-INT($B9*($C$3+1)))*(LARGE(DEBIT_BULANAN!$E$7:$E$31,INT($B9*($C$3+1))+1)-LARGE(DEBIT_BULANAN!$E$7:$E$31,INT($B9*($C$3+1))))))) | G9: =IF($C$3<1,"",IF(INT($B9*($C$3+1))<1,LARGE(DEBIT_BULANAN!$F$7:$F$31,1),IF(INT($B9*($C$3+1))>=$C$3,LARGE(DEBIT_BULANAN!$F$7:$F$31,$C$3),LARGE(DEBIT_BULANAN!$F$7:$F$31,INT($B9*($C$3+1)))+($B9*($C$3+1)-INT($B9*($C$3+1)))*(LARGE(DEBIT_BULANAN!$F$7:$F$31,INT($B9*($C$3+1))+1)-LARGE(DEBIT_BULANAN!$F$7:$F$31,INT($B9*($C$3+1))))))) | H9: =IF($C$3<1,"",IF(INT($B9*($C$3+1))<1,LARGE(DEBIT_BULANAN!$G$7:$G$31,1),IF(INT($B9*($C$3+1))>=$C$3,LARGE(DEBIT_BULANAN!$G$7:$G$31,$C$3),LARGE(DEBIT_BULANAN!$G$7:$G$31,INT($B9*($C$3+1)))+($B9*($C$3+1)-INT($B9*($C$3+1)))*(LARGE(DEBIT_BULANAN!$G$7:$G$31,INT($B9*($C$3+1))+1)-LARGE(DEBIT_BULANAN!$G$7:$G$31,INT($B9*($C$3+1))))))) | I9: =IF($C$3<1,"",IF(INT($B9*($C$3+1))<1,LARGE(DEBIT_BULANAN!$H$7:$H$31,1),IF(INT($B9*($C$3+1))>=$C$3,LARGE(DEBIT_BULANAN!$H$7:$H$31,$C$3),LARGE(DEBIT_BULANAN!$H$7:$H$31,INT($B9*($C$3+1)))+($B9*($C$3+1)-INT($B9*($C$3+1)))*(LARGE(DEBIT_BULANAN!$H$7:$H$31,INT($B9*($C$3+1))+1)-LARGE(DEBIT_BULANAN!$H$7:$H$31,INT($B9*($C$3+1))))))) | J9: =IF($C$3<1,"",IF(INT($B9*($C$3+1))<1,LARGE(DEBIT_BULANAN!$I$7:$I$31,1),IF(INT($B9*($C$3+1))>=$C$3,LARGE(DEBIT_BULANAN!$I$7:$I$31,$C$3),LARGE(DEBIT_BULANAN!$I$7:$I$31,INT($B9*($C$3+1)))+($B9*($C$3+1)-INT($B9*($C$3+1)))*(LARGE(DEBIT_BULANAN!$I$7:$I$31,INT($B9*($C$3+1))+1)-LARGE(DEBIT_BULANAN!$I$7:$I$31,INT($B9*($C$3+1))))))) | K9: =IF($C$3<1,"",IF(INT($B9*($C$3+1))<1,LARGE(DEBIT_BULANAN!$J$7:$J$31,1),IF(INT($B9*($C$3+1))>=$C$3,LARGE(DEBIT_BULANAN!$J$7:$J$31,$C$3),LARGE(DEBIT_BULANAN!$J$7:$J$31,INT($B9*($C$3+1)))+($B9*($C$3+1)-INT($B9*($C$3+1)))*(LARGE(DEBIT_BULANAN!$J$7:$J$31,INT($B9*($C$3+1))+1)-LARGE(DEBIT_BULANAN!$J$7:$J$31,INT($B9*($C$3+1))))))) | L9: =IF($C$3<1,"",IF(INT($B9*($C$3+1))<1,LARGE(DEBIT_BULANAN!$K$7:$K$31,1),IF(INT($B9*($C$3+1))>=$C$3,LARGE(DEBIT_BULANAN!$K$7:$K$31,$C$3),LARGE(DEBIT_BULANAN!$K$7:$K$31,INT($B9*($C$3+1)))+($B9*($C$3+1)-INT($B9*($C$3+1)))*(LARGE(DEBIT_BULANAN!$K$7:$K$31,INT($B9*($C$3+1))+1)-LARGE(DEBIT_BULANAN!$K$7:$K$31,INT($B9*($C$3+1))))))) | M9: =IF($C$3<1,"",IF(INT($B9*($C$3+1))<1,LARGE(DEBIT_BULANAN!$L$7:$L$31,1),IF(INT($B9*($C$3+1))>=$C$3,LARGE(DEBIT_BULANAN!$L$7:$L$31,$C$3),LARGE(DEBIT_BULANAN!$L$7:$L$31,INT($B9*($C$3+1)))+($B9*($C$3+1)-INT($B9*($C$3+1)))*(LARGE(DEBIT_BULANAN!$L$7:$L$31,INT($B9*($C$3+1))+1)-LARGE(DEBIT_BULANAN!$L$7:$L$31,INT($B9*($C$3+1))))))) | N9: =IF($C$3<1,"",IF(INT($B9*($C$3+1))<1,LARGE(DEBIT_BULANAN!$M$7:$M$31,1),IF(INT($B9*($C$3+1))>=$C$3,LARGE(DEBIT_BULANAN!$M$7:$M$31,$C$3),LARGE(DEBIT_BULANAN!$M$7:$M$31,INT($B9*($C$3+1)))+($B9*($C$3+1)-INT($B9*($C$3+1)))*(LARGE(DEBIT_BULANAN!$M$7:$M$31,INT($B9*($C$3+1))+1)-LARGE(DEBIT_BULANAN!$M$7:$M$31,INT($B9*($C$3+1)))))))
A10: Rata-rata (m³/s) | C10: =IFERROR(AVERAGE(DEBIT_BULANAN!$B$7:$B$31),"") | D10: =IFERROR(AVERAGE(DEBIT_BULANAN!$C$7:$C$31),"") | E10: =IFERROR(AVERAGE(DEBIT_BULANAN!$D$7:$D$31),"") | F10: =IFERROR(AVERAGE(DEBIT_BULANAN!$E$7:$E$31),"") | G10: =IFERROR(AVERAGE(DEBIT_BULANAN!$F$7:$F$31),"") | H10: =IFERROR(AVERAGE(DEBIT_BULANAN!$G$7:$G$31),"") | I10: =IFERROR(AVERAGE(DEBIT_BULANAN!$H$7:$H$31),"") | J10: =IFERROR(AVERAGE(DEBIT_BULANAN!$I$7:$I$31),"") | K10: =IFERROR(AVERAGE(DEBIT_BULANAN!$J$7:$J$31),"") | L10: =IFERROR(AVERAGE(DEBIT_BULANAN!$K$7:$K$31),"") | M10: =IFERROR(AVERAGE(DEBIT_BULANAN!$L$7:$L$31),"") | N10: =IFERROR(AVERAGE(DEBIT_BULANAN!$M$7:$M$31),"")
A11: Q50 = debit normal; Q80 = debit andalan irigasi; Q90 = air baku / domestik; Q95 = aliran pemeliharaan sungai (acuan umum, sesuaikan dengan pedoman yang Anda pakai).
A33: Peringkat Weibull (debit bulanan diurutkan dari terbesar)
A34: Peringkat m | B34: P = m/(n+1) | C34: Jan | D34: Feb | E34: Mar | F34: Apr | G34: Mei | H34: Jun | I34: Jul | J34: Agu | K34: Sep | L34: Okt | M34: Nov | N34: Des
A35: 1 | B35: =IF(A35>$C$3,"",A35/($C$3+1)) | C35: =IF($A35>$C$3,"",LARGE(DEBIT_BULANAN!$B$7:$B$31,$A35)) | D35: =IF($A35>$C$3,"",LARGE(DEBIT_BULANAN!$C$7:$C$31,$A35)) | E35: =IF($A35>$C$3,"",LARGE(DEBIT_BULANAN!$D$7:$D$31,$A35)) | F35: =IF($A35>$C$3,"",LARGE(DEBIT_BULANAN!$E$7:$E$31,$A35)) | G35: =IF($A35>$C$3,"",LARGE(DEBIT_BULANAN!$F$7:$F$31,$A35)) | H35: =IF($A35>$C$3,"",LARGE(DEBIT_BULANAN!$G$7:$G$31,$A35)) | I35: =IF($A35>$C$3,"",LARGE(DEBIT_BULANAN!$H$7:$H$31,$A35)) | J35: =IF($A35>$C$3,"",LARGE(DEBIT_BULANAN!$I$7:$I$31,$A35)) | K35: =IF($A35>$C$3,"",LARGE(DEBIT_BULANAN!$J$7:$J$31,$A35)) | L35: =IF($A35>$C$3,"",LARGE(DEBIT_BULANAN!$K$7:$K$31,$A35)) | M35: =IF($A35>$C$3,"",LARGE(DEBIT_BULANAN!$L$7:$L$31,$A35)) | N35: =IF($A35>$C$3,"",LARGE(DEBIT_BULANAN!$M$7:$M$31,$A35))
A36: 2 | B36: =IF(A36>$C$3,"",A36/($C$3+1)) | C36: =IF($A36>$C$3,"",LARGE(DEBIT_BULANAN!$B$7:$B$31,$A36)) | D36: =IF($A36>$C$3,"",LARGE(DEBIT_BULANAN!$C$7:$C$31,$A36)) | E36: =IF($A36>$C$3,"",LARGE(DEBIT_BULANAN!$D$7:$D$31,$A36)) | F36: =IF($A36>$C$3,"",LARGE(DEBIT_BULANAN!$E$7:$E$31,$A36)) | G36: =IF($A36>$C$3,"",LARGE(DEBIT_BULANAN!$F$7:$F$31,$A36)) | H36: =IF($A36>$C$3,"",LARGE(DEBIT_BULANAN!$G$7:$G$31,$A36)) | I36: =IF($A36>$C$3,"",LARGE(DEBIT_BULANAN!$H$7:$H$31,$A36)) | J36: =IF($A36>$C$3,"",LARGE(DEBIT_BULANAN!$I$7:$I$31,$A36)) | K36: =IF($A36>$C$3,"",LARGE(DEBIT_BULANAN!$J$7:$J$31,$A36)) | L36: =IF($A36>$C$3,"",LARGE(DEBIT_BULANAN!$K$7:$K$31,$A36)) | M36: =IF($A36>$C$3,"",LARGE(DEBIT_BULANAN!$L$7:$L$31,$A36)) | N36: =IF($A36>$C$3,"",LARGE(DEBIT_BULANAN!$M$7:$M$31,$A36))
A37: 3 | B37: =IF(A37>$C$3,"",A37/($C$3+1)) | C37: =IF($A37>$C$3,"",LARGE(DEBIT_BULANAN!$B$7:$B$31,$A37)) | D37: =IF($A37>$C$3,"",LARGE(DEBIT_BULANAN!$C$7:$C$31,$A37)) | E37: =IF($A37>$C$3,"",LARGE(DEBIT_BULANAN!$D$7:$D$31,$A37)) | F37: =IF($A37>$C$3,"",LARGE(DEBIT_BULANAN!$E$7:$E$31,$A37)) | G37: =IF($A37>$C$3,"",LARGE(DEBIT_BULANAN!$F$7:$F$31,$A37)) | H37: =IF($A37>$C$3,"",LARGE(DEBIT_BULANAN!$G$7:$G$31,$A37)) | I37: =IF($A37>$C$3,"",LARGE(DEBIT_BULANAN!$H$7:$H$31,$A37)) | J37: =IF($A37>$C$3,"",LARGE(DEBIT_BULANAN!$I$7:$I$31,$A37)) | K37: =IF($A37>$C$3,"",LARGE(DEBIT_BULANAN!$J$7:$J$31,$A37)) | L37: =IF($A37>$C$3,"",LARGE(DEBIT_BULANAN!$K$7:$K$31,$A37)) | M37: =IF($A37>$C$3,"",LARGE(DEBIT_BULANAN!$L$7:$L$31,$A37)) | N37: =IF($A37>$C$3,"",LARGE(DEBIT_BULANAN!$M$7:$M$31,$A37))
A38: 4 | B38: =IF(A38>$C$3,"",A38/($C$3+1)) | C38: =IF($A38>$C$3,"",LARGE(DEBIT_BULANAN!$B$7:$B$31,$A38)) | D38: =IF($A38>$C$3,"",LARGE(DEBIT_BULANAN!$C$7:$C$31,$A38)) | E38: =IF($A38>$C$3,"",LARGE(DEBIT_BULANAN!$D$7:$D$31,$A38)) | F38: =IF($A38>$C$3,"",LARGE(DEBIT_BULANAN!$E$7:$E$31,$A38)) | G38: =IF($A38>$C$3,"",LARGE(DEBIT_BULANAN!$F$7:$F$31,$A38)) | H38: =IF($A38>$C$3,"",LARGE(DEBIT_BULANAN!$G$7:$G$31,$A38)) | I38: =IF($A38>$C$3,"",LARGE(DEBIT_BULANAN!$H$7:$H$31,$A38)) | J38: =IF($A38>$C$3,"",LARGE(DEBIT_BULANAN!$I$7:$I$31,$A38)) | K38: =IF($A38>$C$3,"",LARGE(DEBIT_BULANAN!$J$7:$J$31,$A38)) | L38: =IF($A38>$C$3,"",LARGE(DEBIT_BULANAN!$K$7:$K$31,$A38)) | M38: =IF($A38>$C$3,"",LARGE(DEBIT_BULANAN!$L$7:$L$31,$A38)) | N38: =IF($A38>$C$3,"",LARGE(DEBIT_BULANAN!$M$7:$M$31,$A38))
A39: 5 | B39: =IF(A39>$C$3,"",A39/($C$3+1)) | C39: =IF($A39>$C$3,"",LARGE(DEBIT_BULANAN!$B$7:$B$31,$A39)) | D39: =IF($A39>$C$3,"",LARGE(DEBIT_BULANAN!$C$7:$C$31,$A39)) | E39: =IF($A39>$C$3,"",LARGE(DEBIT_BULANAN!$D$7:$D$31,$A39)) | F39: =IF($A39>$C$3,"",LARGE(DEBIT_BULANAN!$E$7:$E$31,$A39)) | G39: =IF($A39>$C$3,"",LARGE(DEBIT_BULANAN!$F$7:$F$31,$A39)) | H39: =IF($A39>$C$3,"",LARGE(DEBIT_BULANAN!$G$7:$G$31,$A39)) | I39: =IF($A39>$C$3,"",LARGE(DEBIT_BULANAN!$H$7:$H$31,$A39)) | J39: =IF($A39>$C$3,"",LARGE(DEBIT_BULANAN!$I$7:$I$31,$A39)) | K39: =IF($A39>$C$3,"",LARGE(DEBIT_BULANAN!$J$7:$J$31,$A39)) | L39: =IF($A39>$C$3,"",LARGE(DEBIT_BULANAN!$K$7:$K$31,$A39)) | M39: =IF($A39>$C$3,"",LARGE(DEBIT_BULANAN!$L$7:$L$31,$A39)) | N39: =IF($A39>$C$3,"",LARGE(DEBIT_BULANAN!$M$7:$M$31,$A39))
A40: 6 | B40: =IF(A40>$C$3,"",A40/($C$3+1)) | C40: =IF($A40>$C$3,"",LARGE(DEBIT_BULANAN!$B$7:$B$31,$A40)) | D40: =IF($A40>$C$3,"",LARGE(DEBIT_BULANAN!$C$7:$C$31,$A40)) | E40: =IF($A40>$C$3,"",LARGE(DEBIT_BULANAN!$D$7:$D$31,$A40)) | F40: =IF($A40>$C$3,"",LARGE(DEBIT_BULANAN!$E$7:$E$31,$A40)) | G40: =IF($A40>$C$3,"",LARGE(DEBIT_BULANAN!$F$7:$F$31,$A40)) | H40: =IF($A40>$C$3,"",LARGE(DEBIT_BULANAN!$G$7:$G$31,$A40)) | I40: =IF($A40>$C$3,"",LARGE(DEBIT_BULANAN!$H$7:$H$31,$A40)) | J40: =IF($A40>$C$3,"",LARGE(DEBIT_BULANAN!$I$7:$I$31,$A40)) | K40: =IF($A40>$C$3,"",LARGE(DEBIT_BULANAN!$J$7:$J$31,$A40)) | L40: =IF($A40>$C$3,"",LARGE(DEBIT_BULANAN!$K$7:$K$31,$A40)) | M40: =IF($A40>$C$3,"",LARGE(DEBIT_BULANAN!$L$7:$L$31,$A40)) | N40: =IF($A40>$C$3,"",LARGE(DEBIT_BULANAN!$M$7:$M$31,$A40))
A41: 7 | B41: =IF(A41>$C$3,"",A41/($C$3+1)) | C41: =IF($A41>$C$3,"",LARGE(DEBIT_BULANAN!$B$7:$B$31,$A41)) | D41: =IF($A41>$C$3,"",LARGE(DEBIT_BULANAN!$C$7:$C$31,$A41)) | E41: =IF($A41>$C$3,"",LARGE(DEBIT_BULANAN!$D$7:$D$31,$A41)) | F41: =IF($A41>$C$3,"",LARGE(DEBIT_BULANAN!$E$7:$E$31,$A41)) | G41: =IF($A41>$C$3,"",LARGE(DEBIT_BULANAN!$F$7:$F$31,$A41)) | H41: =IF($A41>$C$3,"",LARGE(DEBIT_BULANAN!$G$7:$G$31,$A41)) | I41: =IF($A41>$C$3,"",LARGE(DEBIT_BULANAN!$H$7:$H$31,$A41)) | J41: =IF($A41>$C$3,"",LARGE(DEBIT_BULANAN!$I$7:$I$31,$A41)) | K41: =IF($A41>$C$3,"",LARGE(DEBIT_BULANAN!$J$7:$J$31,$A41)) | L41: =IF($A41>$C$3,"",LARGE(DEBIT_BULANAN!$K$7:$K$31,$A41)) | M41: =IF($A41>$C$3,"",LARGE(DEBIT_BULANAN!$L$7:$L$31,$A41)) | N41: =IF($A41>$C$3,"",LARGE(DEBIT_BULANAN!$M$7:$M$31,$A41))
A42: 8 | B42: =IF(A42>$C$3,"",A42/($C$3+1)) | C42: =IF($A42>$C$3,"",LARGE(DEBIT_BULANAN!$B$7:$B$31,$A42)) | D42: =IF($A42>$C$3,"",LARGE(DEBIT_BULANAN!$C$7:$C$31,$A42)) | E42: =IF($A42>$C$3,"",LARGE(DEBIT_BULANAN!$D$7:$D$31,$A42)) | F42: =IF($A42>$C$3,"",LARGE(DEBIT_BULANAN!$E$7:$E$31,$A42)) | G42: =IF($A42>$C$3,"",LARGE(DEBIT_BULANAN!$F$7:$F$31,$A42)) | H42: =IF($A42>$C$3,"",LARGE(DEBIT_BULANAN!$G$7:$G$31,$A42)) | I42: =IF($A42>$C$3,"",LARGE(DEBIT_BULANAN!$H$7:$H$31,$A42)) | J42: =IF($A42>$C$3,"",LARGE(DEBIT_BULANAN!$I$7:$I$31,$A42)) | K42: =IF($A42>$C$3,"",LARGE(DEBIT_BULANAN!$J$7:$J$31,$A42)) | L42: =IF($A42>$C$3,"",LARGE(DEBIT_BULANAN!$K$7:$K$31,$A42)) | M42: =IF($A42>$C$3,"",LARGE(DEBIT_BULANAN!$L$7:$L$31,$A42)) | N42: =IF($A42>$C$3,"",LARGE(DEBIT_BULANAN!$M$7:$M$31,$A42))
A43: 9 | B43: =IF(A43>$C$3,"",A43/($C$3+1)) | C43: =IF($A43>$C$3,"",LARGE(DEBIT_BULANAN!$B$7:$B$31,$A43)) | D43: =IF($A43>$C$3,"",LARGE(DEBIT_BULANAN!$C$7:$C$31,$A43)) | E43: =IF($A43>$C$3,"",LARGE(DEBIT_BULANAN!$D$7:$D$31,$A43)) | F43: =IF($A43>$C$3,"",LARGE(DEBIT_BULANAN!$E$7:$E$31,$A43)) | G43: =IF($A43>$C$3,"",LARGE(DEBIT_BULANAN!$F$7:$F$31,$A43)) | H43: =IF($A43>$C$3,"",LARGE(DEBIT_BULANAN!$G$7:$G$31,$A43)) | I43: =IF($A43>$C$3,"",LARGE(DEBIT_BULANAN!$H$7:$H$31,$A43)) | J43: =IF($A43>$C$3,"",LARGE(DEBIT_BULANAN!$I$7:$I$31,$A43)) | K43: =IF($A43>$C$3,"",LARGE(DEBIT_BULANAN!$J$7:$J$31,$A43)) | L43: =IF($A43>$C$3,"",LARGE(DEBIT_BULANAN!$K$7:$K$31,$A43)) | M43: =IF($A43>$C$3,"",LARGE(DEBIT_BULANAN!$L$7:$L$31,$A43)) | N43: =IF($A43>$C$3,"",LARGE(DEBIT_BULANAN!$M$7:$M$31,$A43))
A44: 10 | B44: =IF(A44>$C$3,"",A44/($C$3+1)) | C44: =IF($A44>$C$3,"",LARGE(DEBIT_BULANAN!$B$7:$B$31,$A44)) | D44: =IF($A44>$C$3,"",LARGE(DEBIT_BULANAN!$C$7:$C$31,$A44)) | E44: =IF($A44>$C$3,"",LARGE(DEBIT_BULANAN!$D$7:$D$31,$A44)) | F44: =IF($A44>$C$3,"",LARGE(DEBIT_BULANAN!$E$7:$E$31,$A44)) | G44: =IF($A44>$C$3,"",LARGE(DEBIT_BULANAN!$F$7:$F$31,$A44)) | H44: =IF($A44>$C$3,"",LARGE(DEBIT_BULANAN!$G$7:$G$31,$A44)) | I44: =IF($A44>$C$3,"",LARGE(DEBIT_BULANAN!$H$7:$H$31,$A44)) | J44: =IF($A44>$C$3,"",LARGE(DEBIT_BULANAN!$I$7:$I$31,$A44)) | K44: =IF($A44>$C$3,"",LARGE(DEBIT_BULANAN!$J$7:$J$31,$A44)) | L44: =IF($A44>$C$3,"",LARGE(DEBIT_BULANAN!$K$7:$K$31,$A44)) | M44: =IF($A44>$C$3,"",LARGE(DEBIT_BULANAN!$L$7:$L$31,$A44)) | N44: =IF($A44>$C$3,"",LARGE(DEBIT_BULANAN!$M$7:$M$31,$A44))
A45: 11 | B45: =IF(A45>$C$3,"",A45/($C$3+1)) | C45: =IF($A45>$C$3,"",LARGE(DEBIT_BULANAN!$B$7:$B$31,$A45)) | D45: =IF($A45>$C$3,"",LARGE(DEBIT_BULANAN!$C$7:$C$31,$A45)) | E45: =IF($A45>$C$3,"",LARGE(DEBIT_BULANAN!$D$7:$D$31,$A45)) | F45: =IF($A45>$C$3,"",LARGE(DEBIT_BULANAN!$E$7:$E$31,$A45)) | G45: =IF($A45>$C$3,"",LARGE(DEBIT_BULANAN!$F$7:$F$31,$A45)) | H45: =IF($A45>$C$3,"",LARGE(DEBIT_BULANAN!$G$7:$G$31,$A45)) | I45: =IF($A45>$C$3,"",LARGE(DEBIT_BULANAN!$H$7:$H$31,$A45)) | J45: =IF($A45>$C$3,"",LARGE(DEBIT_BULANAN!$I$7:$I$31,$A45)) | K45: =IF($A45>$C$3,"",LARGE(DEBIT_BULANAN!$J$7:$J$31,$A45)) | L45: =IF($A45>$C$3,"",LARGE(DEBIT_BULANAN!$K$7:$K$31,$A45)) | M45: =IF($A45>$C$3,"",LARGE(DEBIT_BULANAN!$L$7:$L$31,$A45)) | N45: =IF($A45>$C$3,"",LARGE(DEBIT_BULANAN!$M$7:$M$31,$A45))
A46: 12 | B46: =IF(A46>$C$3,"",A46/($C$3+1)) | C46: =IF($A46>$C$3,"",LARGE(DEBIT_BULANAN!$B$7:$B$31,$A46)) | D46: =IF($A46>$C$3,"",LARGE(DEBIT_BULANAN!$C$7:$C$31,$A46)) | E46: =IF($A46>$C$3,"",LARGE(DEBIT_BULANAN!$D$7:$D$31,$A46)) | F46: =IF($A46>$C$3,"",LARGE(DEBIT_BULANAN!$E$7:$E$31,$A46)) | G46: =IF($A46>$C$3,"",LARGE(DEBIT_BULANAN!$F$7:$F$31,$A46)) | H46: =IF($A46>$C$3,"",LARGE(DEBIT_BULANAN!$G$7:$G$31,$A46)) | I46: =IF($A46>$C$3,"",LARGE(DEBIT_BULANAN!$H$7:$H$31,$A46)) | J46: =IF($A46>$C$3,"",LARGE(DEBIT_BULANAN!$I$7:$I$31,$A46)) | K46: =IF($A46>$C$3,"",LARGE(DEBIT_BULANAN!$J$7:$J$31,$A46)) | L46: =IF($A46>$C$3,"",LARGE(DEBIT_BULANAN!$K$7:$K$31,$A46)) | M46: =IF($A46>$C$3,"",LARGE(DEBIT_BULANAN!$L$7:$L$31,$A46)) | N46: =IF($A46>$C$3,"",LARGE(DEBIT_BULANAN!$M$7:$M$31,$A46))
... A59: 25 | B59: =IF(A59>$C$3,"",A59/($C$3+1)) | C59: =IF($A59>$C$3,"",LARGE(DEBIT_BULANAN!$B$7:$B$31,$A59)) | D59: =IF($A59>$C$3,"",LARGE(DEBIT_BULANAN!$C$7:$C$31,$A59)) | E59: =IF($A59>$C$3,"",LARGE(DEBIT_BULANAN!$D$7:$D$31,$A59)) | F59: =IF($A59>$C$3,"",LARGE(DEBIT_BULANAN!$E$7:$E$31,$A59)) | G59: =IF($A59>$C$3,"",LARGE(DEBIT_BULANAN!$F$7:$F$31,$A59)) | H59: =IF($A59>$C$3,"",LARGE(DEBIT_BULANAN!$G$7:$G$31,$A59)) | I59: =IF($A59>$C$3,"",LARGE(DEBIT_BULANAN!$H$7:$H$31,$A59)) | J59: =IF($A59>$C$3,"",LARGE(DEBIT_BULANAN!$I$7:$I$31,$A59)) | K59: =IF($A59>$C$3,"",LARGE(DEBIT_BULANAN!$J$7:$J$31,$A59)) | L59: =IF($A59>$C$3,"",LARGE(DEBIT_BULANAN!$K$7:$K$31,$A59)) | M59: =IF($A59>$C$3,"",LARGE(DEBIT_BULANAN!$L$7:$L$31,$A59)) | N59: =IF($A59>$C$3,"",LARGE(DEBIT_BULANAN!$M$7:$M$31,$A59))

Sheet WEIBULL_15HARIAN
A1: DEBIT ANDALAN 15 HARIAN (WEIBULL) - Outlet
A2: Debit rata-rata 15 harian tiap tahun lengkap diurutkan dari terbesar; peluang terlampaui P = m / (n + 1) (Weibull). Q-P diinterpolasi linier antar peringkat.
A3: Jumlah tahun lengkap (n) | C3: =COUNT(DEBIT_15HARIAN!$A$7:$A$31)
A5: Debit andalan | B5: Peluang P | C5: Jan I | D5: Jan II | E5: Feb I | F5: Feb II | G5: Mar I | H5: Mar II | I5: Apr I | J5: Apr II | K5: Mei I | L5: Mei II | M5: Jun I | N5: Jun II | O5: Jul I | P5: Jul II | Q5: Agu I | R5: Agu II | S5: Sep I | T5: Sep II | U5: Okt I | V5: Okt II | W5: Nov I | X5: Nov II | Y5: Des I | Z5: Des II
A6: Q50 (m³/s) | B6: 0.5 | C6: =IF($C$3<1,"",IF(INT($B6*($C$3+1))<1,LARGE(DEBIT_15HARIAN!$B$7:$B$31,1),IF(INT($B6*($C$3+1))>=$C$3,LARGE(DEBIT_15HARIAN!$B$7:$B$31,$C$3),LARGE(DEBIT_15HARIAN!$B$7:$B$31,INT($B6*($C$3+1)))+($B6*($C$3+1)-INT($B6*($C$3+1)))*(LARGE(DEBIT_15HARIAN!$B$7:$B$31,INT($B6*($C$3+1))+1)-LARGE(DEBIT_15HARIAN!$B$7:$B$31,INT($B6*($C$3+1))))))) | D6: =IF($C$3<1,"",IF(INT($B6*($C$3+1))<1,LARGE(DEBIT_15HARIAN!$C$7:$C$31,1),IF(INT($B6*($C$3+1))>=$C$3,LARGE(DEBIT_15HARIAN!$C$7:$C$31,$C$3),LARGE(DEBIT_15HARIAN!$C$7:$C$31,INT($B6*($C$3+1)))+($B6*($C$3+1)-INT($B6*($C$3+1)))*(LARGE(DEBIT_15HARIAN!$C$7:$C$31,INT($B6*($C$3+1))+1)-LARGE(DEBIT_15HARIAN!$C$7:$C$31,INT($B6*($C$3+1))))))) | E6: =IF($C$3<1,"",IF(INT($B6*($C$3+1))<1,LARGE(DEBIT_15HARIAN!$D$7:$D$31,1),IF(INT($B6*($C$3+1))>=$C$3,LARGE(DEBIT_15HARIAN!$D$7:$D$31,$C$3),LARGE(DEBIT_15HARIAN!$D$7:$D$31,INT($B6*($C$3+1)))+($B6*($C$3+1)-INT($B6*($C$3+1)))*(LARGE(DEBIT_15HARIAN!$D$7:$D$31,INT($B6*($C$3+1))+1)-LARGE(DEBIT_15HARIAN!$D$7:$D$31,INT($B6*($C$3+1))))))) | F6: =IF($C$3<1,"",IF(INT($B6*($C$3+1))<1,LARGE(DEBIT_15HARIAN!$E$7:$E$31,1),IF(INT($B6*($C$3+1))>=$C$3,LARGE(DEBIT_15HARIAN!$E$7:$E$31,$C$3),LARGE(DEBIT_15HARIAN!$E$7:$E$31,INT($B6*($C$3+1)))+($B6*($C$3+1)-INT($B6*($C$3+1)))*(LARGE(DEBIT_15HARIAN!$E$7:$E$31,INT($B6*($C$3+1))+1)-LARGE(DEBIT_15HARIAN!$E$7:$E$31,INT($B6*($C$3+1))))))) | G6: =IF($C$3<1,"",IF(INT($B6*($C$3+1))<1,LARGE(DEBIT_15HARIAN!$F$7:$F$31,1),IF(INT($B6*($C$3+1))>=$C$3,LARGE(DEBIT_15HARIAN!$F$7:$F$31,$C$3),LARGE(DEBIT_15HARIAN!$F$7:$F$31,INT($B6*($C$3+1)))+($B6*($C$3+1)-INT($B6*($C$3+1)))*(LARGE(DEBIT_15HARIAN!$F$7:$F$31,INT($B6*($C$3+1))+1)-LARGE(DEBIT_15HARIAN!$F$7:$F$31,INT($B6*($C$3+1))))))) | H6: =IF($C$3<1,"",IF(INT($B6*($C$3+1))<1,LARGE(DEBIT_15HARIAN!$G$7:$G$31,1),IF(INT($B6*($C$3+1))>=$C$3,LARGE(DEBIT_15HARIAN!$G$7:$G$31,$C$3),LARGE(DEBIT_15HARIAN!$G$7:$G$31,INT($B6*($C$3+1)))+($B6*($C$3+1)-INT($B6*($C$3+1)))*(LARGE(DEBIT_15HARIAN!$G$7:$G$31,INT($B6*($C$3+1))+1)-LARGE(DEBIT_15HARIAN!$G$7:$G$31,INT($B6*($C$3+1))))))) | I6: =IF($C$3<1,"",IF(INT($B6*($C$3+1))<1,LARGE(DEBIT_15HARIAN!$H$7:$H$31,1),IF(INT($B6*($C$3+1))>=$C$3,LARGE(DEBIT_15HARIAN!$H$7:$H$31,$C$3),LARGE(DEBIT_15HARIAN!$H$7:$H$31,INT($B6*($C$3+1)))+($B6*($C$3+1)-INT($B6*($C$3+1)))*(LARGE(DEBIT_15HARIAN!$H$7:$H$31,INT($B6*($C$3+1))+1)-LARGE(DEBIT_15HARIAN!$H$7:$H$31,INT($B6*($C$3+1))))))) | J6: =IF($C$3<1,"",IF(INT($B6*($C$3+1))<1,LARGE(DEBIT_15HARIAN!$I$7:$I$31,1),IF(INT($B6*($C$3+1))>=$C$3,LARGE(DEBIT_15HARIAN!$I$7:$I$31,$C$3),LARGE(DEBIT_15HARIAN!$I$7:$I$31,INT($B6*($C$3+1)))+($B6*($C$3+1)-INT($B6*($C$3+1)))*(LARGE(DEBIT_15HARIAN!$I$7:$I$31,INT($B6*($C$3+1))+1)-LARGE(DEBIT_15HARIAN!$I$7:$I$31,INT($B6*($C$3+1))))))) | K6: =IF($C$3<1,"",IF(INT($B6*($C$3+1))<1,LARGE(DEBIT_15HARIAN!$J$7:$J$31,1),IF(INT($B6*($C$3+1))>=$C$3,LARGE(DEBIT_15HARIAN!$J$7:$J$31,$C$3),LARGE(DEBIT_15HARIAN!$J$7:$J$31,INT($B6*($C$3+1)))+($B6*($C$3+1)-INT($B6*($C$3+1)))*(LARGE(DEBIT_15HARIAN!$J$7:$J$31,INT($B6*($C$3+1))+1)-LARGE(DEBIT_15HARIAN!$J$7:$J$31,INT($B6*($C$3+1))))))) | L6: =IF($C$3<1,"",IF(INT($B6*($C$3+1))<1,LARGE(DEBIT_15HARIAN!$K$7:$K$31,1),IF(INT($B6*($C$3+1))>=$C$3,LARGE(DEBIT_15HARIAN!$K$7:$K$31,$C$3),LARGE(DEBIT_15HARIAN!$K$7:$K$31,INT($B6*($C$3+1)))+($B6*($C$3+1)-INT($B6*($C$3+1)))*(LARGE(DEBIT_15HARIAN!$K$7:$K$31,INT($B6*($C$3+1))+1)-LARGE(DEBIT_15HARIAN!$K$7:$K$31,INT($B6*($C$3+1))))))) | M6: =IF($C$3<1,"",IF(INT($B6*($C$3+1))<1,LARGE(DEBIT_15HARIAN!$L$7:$L$31,1),IF(INT($B6*($C$3+1))>=$C$3,LARGE(DEBIT_15HARIAN!$L$7:$L$31,$C$3),LARGE(DEBIT_15HARIAN!$L$7:$L$31,INT($B6*($C$3+1)))+($B6*($C$3+1)-INT($B6*($C$3+1)))*(LARGE(DEBIT_15HARIAN!$L$7:$L$31,INT($B6*($C$3+1))+1)-LARGE(DEBIT_15HARIAN!$L$7:$L$31,INT($B6*($C$3+1))))))) | N6: =IF($C$3<1,"",IF(INT($B6*($C$3+1))<1,LARGE(DEBIT_15HARIAN!$M$7:$M$31,1),IF(INT($B6*($C$3+1))>=$C$3,LARGE(DEBIT_15HARIAN!$M$7:$M$31,$C$3),LARGE(DEBIT_15HARIAN!$M$7:$M$31,INT($B6*($C$3+1)))+($B6*($C$3+1)-INT($B6*($C$3+1)))*(LARGE(DEBIT_15HARIAN!$M$7:$M$31,INT($B6*($C$3+1))+1)-LARGE(DEBIT_15HARIAN!$M$7:$M$31,INT($B6*($C$3+1))))))) | O6: =IF($C$3<1,"",IF(INT($B6*($C$3+1))<1,LARGE(DEBIT_15HARIAN!$N$7:$N$31,1),IF(INT($B6*($C$3+1))>=$C$3,LARGE(DEBIT_15HARIAN!$N$7:$N$31,$C$3),LARGE(DEBIT_15HARIAN!$N$7:$N$31,INT($B6*($C$3+1)))+($B6*($C$3+1)-INT($B6*($C$3+1)))*(LARGE(DEBIT_15HARIAN!$N$7:$N$31,INT($B6*($C$3+1))+1)-LARGE(DEBIT_15HARIAN!$N$7:$N$31,INT($B6*($C$3+1))))))) | P6: =IF($C$3<1,"",IF(INT($B6*($C$3+1))<1,LARGE(DEBIT_15HARIAN!$O$7:$O$31,1),IF(INT($B6*($C$3+1))>=$C$3,LARGE(DEBIT_15HARIAN!$O$7:$O$31,$C$3),LARGE(DEBIT_15HARIAN!$O$7:$O$31,INT($B6*($C$3+1)))+($B6*($C$3+1)-INT($B6*($C$3+1)))*(LARGE(DEBIT_15HARIAN!$O$7:$O$31,INT($B6*($C$3+1))+1)-LARGE(DEBIT_15HARIAN!$O$7:$O$31,INT($B6*($C$3+1))))))) | Q6: =IF($C$3<1,"",IF(INT($B6*($C$3+1))<1,LARGE(DEBIT_15HARIAN!$P$7:$P$31,1),IF(INT($B6*($C$3+1))>=$C$3,LARGE(DEBIT_15HARIAN!$P$7:$P$31,$C$3),LARGE(DEBIT_15HARIAN!$P$7:$P$31,INT($B6*($C$3+1)))+($B6*($C$3+1)-INT($B6*($C$3+1)))*(LARGE(DEBIT_15HARIAN!$P$7:$P$31,INT($B6*($C$3+1))+1)-LARGE(DEBIT_15HARIAN!$P$7:$P$31,INT($B6*($C$3+1))))))) | R6: =IF($C$3<1,"",IF(INT($B6*($C$3+1))<1,LARGE(DEBIT_15HARIAN!$Q$7:$Q$31,1),IF(INT($B6*($C$3+1))>=$C$3,LARGE(DEBIT_15HARIAN!$Q$7:$Q$31,$C$3),LARGE(DEBIT_15HARIAN!$Q$7:$Q$31,INT($B6*($C$3+1)))+($B6*($C$3+1)-INT($B6*($C$3+1)))*(LARGE(DEBIT_15HARIAN!$Q$7:$Q$31,INT($B6*($C$3+1))+1)-LARGE(DEBIT_15HARIAN!$Q$7:$Q$31,INT($B6*($C$3+1))))))) | S6: =IF($C$3<1,"",IF(INT($B6*($C$3+1))<1,LARGE(DEBIT_15HARIAN!$R$7:$R$31,1),IF(INT($B6*($C$3+1))>=$C$3,LARGE(DEBIT_15HARIAN!$R$7:$R$31,$C$3),LARGE(DEBIT_15HARIAN!$R$7:$R$31,INT($B6*($C$3+1)))+($B6*($C$3+1)-INT($B6*($C$3+1)))*(LARGE(DEBIT_15HARIAN!$R$7:$R$31,INT($B6*($C$3+1))+1)-LARGE(DEBIT_15HARIAN!$R$7:$R$31,INT($B6*($C$3+1))))))) | T6: =IF($C$3<1,"",IF(INT($B6*($C$3+1))<1,LARGE(DEBIT_15HARIAN!$S$7:$S$31,1),IF(INT($B6*($C$3+1))>=$C$3,LARGE(DEBIT_15HARIAN!$S$7:$S$31,$C$3),LARGE(DEBIT_15HARIAN!$S$7:$S$31,INT($B6*($C$3+1)))+($B6*($C$3+1)-INT($B6*($C$3+1)))*(LARGE(DEBIT_15HARIAN!$S$7:$S$31,INT($B6*($C$3+1))+1)-LARGE(DEBIT_15HARIAN!$S$7:$S$31,INT($B6*($C$3+1))))))) | U6: =IF($C$3<1,"",IF(INT($B6*($C$3+1))<1,LARGE(DEBIT_15HARIAN!$T$7:$T$31,1),IF(INT($B6*($C$3+1))>=$C$3,LARGE(DEBIT_15HARIAN!$T$7:$T$31,$C$3),LARGE(DEBIT_15HARIAN!$T$7:$T$31,INT($B6*($C$3+1)))+($B6*($C$3+1)-INT($B6*($C$3+1)))*(LARGE(DEBIT_15HARIAN!$T$7:$T$31,INT($B6*($C$3+1))+1)-LARGE(DEBIT_15HARIAN!$T$7:$T$31,INT($B6*($C$3+1))))))) | V6: =IF($C$3<1,"",IF(INT($B6*($C$3+1))<1,LARGE(DEBIT_15HARIAN!$U$7:$U$31,1),IF(INT($B6*($C$3+1))>=$C$3,LARGE(DEBIT_15HARIAN!$U$7:$U$31,$C$3),LARGE(DEBIT_15HARIAN!$U$7:$U$31,INT($B6*($C$3+1)))+($B6*($C$3+1)-INT($B6*($C$3+1)))*(LARGE(DEBIT_15HARIAN!$U$7:$U$31,INT($B6*($C$3+1))+1)-LARGE(DEBIT_15HARIAN!$U$7:$U$31,INT($B6*($C$3+1))))))) | W6: =IF($C$3<1,"",IF(INT($B6*($C$3+1))<1,LARGE(DEBIT_15HARIAN!$V$7:$V$31,1),IF(INT($B6*($C$3+1))>=$C$3,LARGE(DEBIT_15HARIAN!$V$7:$V$31,$C$3),LARGE(DEBIT_15HARIAN!$V$7:$V$31,INT($B6*($C$3+1)))+($B6*($C$3+1)-INT($B6*($C$3+1)))*(LARGE(DEBIT_15HARIAN!$V$7:$V$31,INT($B6*($C$3+1))+1)-LARGE(DEBIT_15HARIAN!$V$7:$V$31,INT($B6*($C$3+1))))))) | X6: =IF($C$3<1,"",IF(INT($B6*($C$3+1))<1,LARGE(DEBIT_15HARIAN!$W$7:$W$31,1),IF(INT($B6*($C$3+1))>=$C$3,LARGE(DEBIT_15HARIAN!$W$7:$W$31,$C$3),LARGE(DEBIT_15HARIAN!$W$7:$W$31,INT($B6*($C$3+1)))+($B6*($C$3+1)-INT($B6*($C$3+1)))*(LARGE(DEBIT_15HARIAN!$W$7:$W$31,INT($B6*($C$3+1))+1)-LARGE(DEBIT_15HARIAN!$W$7:$W$31,INT($B6*($C$3+1))))))) | Y6: =IF($C$3<1,"",IF(INT($B6*($C$3+1))<1,LARGE(DEBIT_15HARIAN!$X$7:$X$31,1),IF(INT($B6*($C$3+1))>=$C$3,LARGE(DEBIT_15HARIAN!$X$7:$X$31,$C$3),LARGE(DEBIT_15HARIAN!$X$7:$X$31,INT($B6*($C$3+1)))+($B6*($C$3+1)-INT($B6*($C$3+1)))*(LARGE(DEBIT_15HARIAN!$X$7:$X$31,INT($B6*($C$3+1))+1)-LARGE(DEBIT_15HARIAN!$X$7:$X$31,INT($B6*($C$3+1))))))) | Z6: =IF($C$3<1,"",IF(INT($B6*($C$3+1))<1,LARGE(DEBIT_15HARIAN!$Y$7:$Y$31,1),IF(INT($B6*($C$3+1))>=$C$3,LARGE(DEBIT_15HARIAN!$Y$7:$Y$31,$C$3),LARGE(DEBIT_15HARIAN!$Y$7:$Y$31,INT($B6*($C$3+1)))+($B6*($C$3+1)-INT($B6*($C$3+1)))*(LARGE(DEBIT_15HARIAN!$Y$7:$Y$31,INT($B6*($C$3+1))+1)-LARGE(DEBIT_15HARIAN!$Y$7:$Y$31,INT($B6*($C$3+1)))))))
A7: Q80 (m³/s) | B7: 0.8 | C7: =IF($C$3<1,"",IF(INT($B7*($C$3+1))<1,LARGE(DEBIT_15HARIAN!$B$7:$B$31,1),IF(INT($B7*($C$3+1))>=$C$3,LARGE(DEBIT_15HARIAN!$B$7:$B$31,$C$3),LARGE(DEBIT_15HARIAN!$B$7:$B$31,INT($B7*($C$3+1)))+($B7*($C$3+1)-INT($B7*($C$3+1)))*(LARGE(DEBIT_15HARIAN!$B$7:$B$31,INT($B7*($C$3+1))+1)-LARGE(DEBIT_15HARIAN!$B$7:$B$31,INT($B7*($C$3+1))))))) | D7: =IF($C$3<1,"",IF(INT($B7*($C$3+1))<1,LARGE(DEBIT_15HARIAN!$C$7:$C$31,1),IF(INT($B7*($C$3+1))>=$C$3,LARGE(DEBIT_15HARIAN!$C$7:$C$31,$C$3),LARGE(DEBIT_15HARIAN!$C$7:$C$31,INT($B7*($C$3+1)))+($B7*($C$3+1)-INT($B7*($C$3+1)))*(LARGE(DEBIT_15HARIAN!$C$7:$C$31,INT($B7*($C$3+1))+1)-LARGE(DEBIT_15HARIAN!$C$7:$C$31,INT($B7*($C$3+1))))))) | E7: =IF($C$3<1,"",IF(INT($B7*($C$3+1))<1,LARGE(DEBIT_15HARIAN!$D$7:$D$31,1),IF(INT($B7*($C$3+1))>=$C$3,LARGE(DEBIT_15HARIAN!$D$7:$D$31,$C$3),LARGE(DEBIT_15HARIAN!$D$7:$D$31,INT($B7*($C$3+1)))+($B7*($C$3+1)-INT($B7*($C$3+1)))*(LARGE(DEBIT_15HARIAN!$D$7:$D$31,INT($B7*($C$3+1))+1)-LARGE(DEBIT_15HARIAN!$D$7:$D$31,INT($B7*($C$3+1))))))) | F7: =IF($C$3<1,"",IF(INT($B7*($C$3+1))<1,LARGE(DEBIT_15HARIAN!$E$7:$E$31,1),IF(INT($B7*($C$3+1))>=$C$3,LARGE(DEBIT_15HARIAN!$E$7:$E$31,$C$3),LARGE(DEBIT_15HARIAN!$E$7:$E$31,INT($B7*($C$3+1)))+($B7*($C$3+1)-INT($B7*($C$3+1)))*(LARGE(DEBIT_15HARIAN!$E$7:$E$31,INT($B7*($C$3+1))+1)-LARGE(DEBIT_15HARIAN!$E$7:$E$31,INT($B7*($C$3+1))))))) | G7: =IF($C$3<1,"",IF(INT($B7*($C$3+1))<1,LARGE(DEBIT_15HARIAN!$F$7:$F$31,1),IF(INT($B7*($C$3+1))>=$C$3,LARGE(DEBIT_15HARIAN!$F$7:$F$31,$C$3),LARGE(DEBIT_15HARIAN!$F$7:$F$31,INT($B7*($C$3+1)))+($B7*($C$3+1)-INT($B7*($C$3+1)))*(LARGE(DEBIT_15HARIAN!$F$7:$F$31,INT($B7*($C$3+1))+1)-LARGE(DEBIT_15HARIAN!$F$7:$F$31,INT($B7*($C$3+1))))))) | H7: =IF($C$3<1,"",IF(INT($B7*($C$3+1))<1,LARGE(DEBIT_15HARIAN!$G$7:$G$31,1),IF(INT($B7*($C$3+1))>=$C$3,LARGE(DEBIT_15HARIAN!$G$7:$G$31,$C$3),LARGE(DEBIT_15HARIAN!$G$7:$G$31,INT($B7*($C$3+1)))+($B7*($C$3+1)-INT($B7*($C$3+1)))*(LARGE(DEBIT_15HARIAN!$G$7:$G$31,INT($B7*($C$3+1))+1)-LARGE(DEBIT_15HARIAN!$G$7:$G$31,INT($B7*($C$3+1))))))) | I7: =IF($C$3<1,"",IF(INT($B7*($C$3+1))<1,LARGE(DEBIT_15HARIAN!$H$7:$H$31,1),IF(INT($B7*($C$3+1))>=$C$3,LARGE(DEBIT_15HARIAN!$H$7:$H$31,$C$3),LARGE(DEBIT_15HARIAN!$H$7:$H$31,INT($B7*($C$3+1)))+($B7*($C$3+1)-INT($B7*($C$3+1)))*(LARGE(DEBIT_15HARIAN!$H$7:$H$31,INT($B7*($C$3+1))+1)-LARGE(DEBIT_15HARIAN!$H$7:$H$31,INT($B7*($C$3+1))))))) | J7: =IF($C$3<1,"",IF(INT($B7*($C$3+1))<1,LARGE(DEBIT_15HARIAN!$I$7:$I$31,1),IF(INT($B7*($C$3+1))>=$C$3,LARGE(DEBIT_15HARIAN!$I$7:$I$31,$C$3),LARGE(DEBIT_15HARIAN!$I$7:$I$31,INT($B7*($C$3+1)))+($B7*($C$3+1)-INT($B7*($C$3+1)))*(LARGE(DEBIT_15HARIAN!$I$7:$I$31,INT($B7*($C$3+1))+1)-LARGE(DEBIT_15HARIAN!$I$7:$I$31,INT($B7*($C$3+1))))))) | K7: =IF($C$3<1,"",IF(INT($B7*($C$3+1))<1,LARGE(DEBIT_15HARIAN!$J$7:$J$31,1),IF(INT($B7*($C$3+1))>=$C$3,LARGE(DEBIT_15HARIAN!$J$7:$J$31,$C$3),LARGE(DEBIT_15HARIAN!$J$7:$J$31,INT($B7*($C$3+1)))+($B7*($C$3+1)-INT($B7*($C$3+1)))*(LARGE(DEBIT_15HARIAN!$J$7:$J$31,INT($B7*($C$3+1))+1)-LARGE(DEBIT_15HARIAN!$J$7:$J$31,INT($B7*($C$3+1))))))) | L7: =IF($C$3<1,"",IF(INT($B7*($C$3+1))<1,LARGE(DEBIT_15HARIAN!$K$7:$K$31,1),IF(INT($B7*($C$3+1))>=$C$3,LARGE(DEBIT_15HARIAN!$K$7:$K$31,$C$3),LARGE(DEBIT_15HARIAN!$K$7:$K$31,INT($B7*($C$3+1)))+($B7*($C$3+1)-INT($B7*($C$3+1)))*(LARGE(DEBIT_15HARIAN!$K$7:$K$31,INT($B7*($C$3+1))+1)-LARGE(DEBIT_15HARIAN!$K$7:$K$31,INT($B7*($C$3+1))))))) | M7: =IF($C$3<1,"",IF(INT($B7*($C$3+1))<1,LARGE(DEBIT_15HARIAN!$L$7:$L$31,1),IF(INT($B7*($C$3+1))>=$C$3,LARGE(DEBIT_15HARIAN!$L$7:$L$31,$C$3),LARGE(DEBIT_15HARIAN!$L$7:$L$31,INT($B7*($C$3+1)))+($B7*($C$3+1)-INT($B7*($C$3+1)))*(LARGE(DEBIT_15HARIAN!$L$7:$L$31,INT($B7*($C$3+1))+1)-LARGE(DEBIT_15HARIAN!$L$7:$L$31,INT($B7*($C$3+1))))))) | N7: =IF($C$3<1,"",IF(INT($B7*($C$3+1))<1,LARGE(DEBIT_15HARIAN!$M$7:$M$31,1),IF(INT($B7*($C$3+1))>=$C$3,LARGE(DEBIT_15HARIAN!$M$7:$M$31,$C$3),LARGE(DEBIT_15HARIAN!$M$7:$M$31,INT($B7*($C$3+1)))+($B7*($C$3+1)-INT($B7*($C$3+1)))*(LARGE(DEBIT_15HARIAN!$M$7:$M$31,INT($B7*($C$3+1))+1)-LARGE(DEBIT_15HARIAN!$M$7:$M$31,INT($B7*($C$3+1))))))) | O7: =IF($C$3<1,"",IF(INT($B7*($C$3+1))<1,LARGE(DEBIT_15HARIAN!$N$7:$N$31,1),IF(INT($B7*($C$3+1))>=$C$3,LARGE(DEBIT_15HARIAN!$N$7:$N$31,$C$3),LARGE(DEBIT_15HARIAN!$N$7:$N$31,INT($B7*($C$3+1)))+($B7*($C$3+1)-INT($B7*($C$3+1)))*(LARGE(DEBIT_15HARIAN!$N$7:$N$31,INT($B7*($C$3+1))+1)-LARGE(DEBIT_15HARIAN!$N$7:$N$31,INT($B7*($C$3+1))))))) | P7: =IF($C$3<1,"",IF(INT($B7*($C$3+1))<1,LARGE(DEBIT_15HARIAN!$O$7:$O$31,1),IF(INT($B7*($C$3+1))>=$C$3,LARGE(DEBIT_15HARIAN!$O$7:$O$31,$C$3),LARGE(DEBIT_15HARIAN!$O$7:$O$31,INT($B7*($C$3+1)))+($B7*($C$3+1)-INT($B7*($C$3+1)))*(LARGE(DEBIT_15HARIAN!$O$7:$O$31,INT($B7*($C$3+1))+1)-LARGE(DEBIT_15HARIAN!$O$7:$O$31,INT($B7*($C$3+1))))))) | Q7: =IF($C$3<1,"",IF(INT($B7*($C$3+1))<1,LARGE(DEBIT_15HARIAN!$P$7:$P$31,1),IF(INT($B7*($C$3+1))>=$C$3,LARGE(DEBIT_15HARIAN!$P$7:$P$31,$C$3),LARGE(DEBIT_15HARIAN!$P$7:$P$31,INT($B7*($C$3+1)))+($B7*($C$3+1)-INT($B7*($C$3+1)))*(LARGE(DEBIT_15HARIAN!$P$7:$P$31,INT($B7*($C$3+1))+1)-LARGE(DEBIT_15HARIAN!$P$7:$P$31,INT($B7*($C$3+1))))))) | R7: =IF($C$3<1,"",IF(INT($B7*($C$3+1))<1,LARGE(DEBIT_15HARIAN!$Q$7:$Q$31,1),IF(INT($B7*($C$3+1))>=$C$3,LARGE(DEBIT_15HARIAN!$Q$7:$Q$31,$C$3),LARGE(DEBIT_15HARIAN!$Q$7:$Q$31,INT($B7*($C$3+1)))+($B7*($C$3+1)-INT($B7*($C$3+1)))*(LARGE(DEBIT_15HARIAN!$Q$7:$Q$31,INT($B7*($C$3+1))+1)-LARGE(DEBIT_15HARIAN!$Q$7:$Q$31,INT($B7*($C$3+1))))))) | S7: =IF($C$3<1,"",IF(INT($B7*($C$3+1))<1,LARGE(DEBIT_15HARIAN!$R$7:$R$31,1),IF(INT($B7*($C$3+1))>=$C$3,LARGE(DEBIT_15HARIAN!$R$7:$R$31,$C$3),LARGE(DEBIT_15HARIAN!$R$7:$R$31,INT($B7*($C$3+1)))+($B7*($C$3+1)-INT($B7*($C$3+1)))*(LARGE(DEBIT_15HARIAN!$R$7:$R$31,INT($B7*($C$3+1))+1)-LARGE(DEBIT_15HARIAN!$R$7:$R$31,INT($B7*($C$3+1))))))) | T7: =IF($C$3<1,"",IF(INT($B7*($C$3+1))<1,LARGE(DEBIT_15HARIAN!$S$7:$S$31,1),IF(INT($B7*($C$3+1))>=$C$3,LARGE(DEBIT_15HARIAN!$S$7:$S$31,$C$3),LARGE(DEBIT_15HARIAN!$S$7:$S$31,INT($B7*($C$3+1)))+($B7*($C$3+1)-INT($B7*($C$3+1)))*(LARGE(DEBIT_15HARIAN!$S$7:$S$31,INT($B7*($C$3+1))+1)-LARGE(DEBIT_15HARIAN!$S$7:$S$31,INT($B7*($C$3+1))))))) | U7: =IF($C$3<1,"",IF(INT($B7*($C$3+1))<1,LARGE(DEBIT_15HARIAN!$T$7:$T$31,1),IF(INT($B7*($C$3+1))>=$C$3,LARGE(DEBIT_15HARIAN!$T$7:$T$31,$C$3),LARGE(DEBIT_15HARIAN!$T$7:$T$31,INT($B7*($C$3+1)))+($B7*($C$3+1)-INT($B7*($C$3+1)))*(LARGE(DEBIT_15HARIAN!$T$7:$T$31,INT($B7*($C$3+1))+1)-LARGE(DEBIT_15HARIAN!$T$7:$T$31,INT($B7*($C$3+1))))))) | V7: =IF($C$3<1,"",IF(INT($B7*($C$3+1))<1,LARGE(DEBIT_15HARIAN!$U$7:$U$31,1),IF(INT($B7*($C$3+1))>=$C$3,LARGE(DEBIT_15HARIAN!$U$7:$U$31,$C$3),LARGE(DEBIT_15HARIAN!$U$7:$U$31,INT($B7*($C$3+1)))+($B7*($C$3+1)-INT($B7*($C$3+1)))*(LARGE(DEBIT_15HARIAN!$U$7:$U$31,INT($B7*($C$3+1))+1)-LARGE(DEBIT_15HARIAN!$U$7:$U$31,INT($B7*($C$3+1))))))) | W7: =IF($C$3<1,"",IF(INT($B7*($C$3+1))<1,LARGE(DEBIT_15HARIAN!$V$7:$V$31,1),IF(INT($B7*($C$3+1))>=$C$3,LARGE(DEBIT_15HARIAN!$V$7:$V$31,$C$3),LARGE(DEBIT_15HARIAN!$V$7:$V$31,INT($B7*($C$3+1)))+($B7*($C$3+1)-INT($B7*($C$3+1)))*(LARGE(DEBIT_15HARIAN!$V$7:$V$31,INT($B7*($C$3+1))+1)-LARGE(DEBIT_15HARIAN!$V$7:$V$31,INT($B7*($C$3+1))))))) | X7: =IF($C$3<1,"",IF(INT($B7*($C$3+1))<1,LARGE(DEBIT_15HARIAN!$W$7:$W$31,1),IF(INT($B7*($C$3+1))>=$C$3,LARGE(DEBIT_15HARIAN!$W$7:$W$31,$C$3),LARGE(DEBIT_15HARIAN!$W$7:$W$31,INT($B7*($C$3+1)))+($B7*($C$3+1)-INT($B7*($C$3+1)))*(LARGE(DEBIT_15HARIAN!$W$7:$W$31,INT($B7*($C$3+1))+1)-LARGE(DEBIT_15HARIAN!$W$7:$W$31,INT($B7*($C$3+1))))))) | Y7: =IF($C$3<1,"",IF(INT($B7*($C$3+1))<1,LARGE(DEBIT_15HARIAN!$X$7:$X$31,1),IF(INT($B7*($C$3+1))>=$C$3,LARGE(DEBIT_15HARIAN!$X$7:$X$31,$C$3),LARGE(DEBIT_15HARIAN!$X$7:$X$31,INT($B7*($C$3+1)))+($B7*($C$3+1)-INT($B7*($C$3+1)))*(LARGE(DEBIT_15HARIAN!$X$7:$X$31,INT($B7*($C$3+1))+1)-LARGE(DEBIT_15HARIAN!$X$7:$X$31,INT($B7*($C$3+1))))))) | Z7: =IF($C$3<1,"",IF(INT($B7*($C$3+1))<1,LARGE(DEBIT_15HARIAN!$Y$7:$Y$31,1),IF(INT($B7*($C$3+1))>=$C$3,LARGE(DEBIT_15HARIAN!$Y$7:$Y$31,$C$3),LARGE(DEBIT_15HARIAN!$Y$7:$Y$31,INT($B7*($C$3+1)))+($B7*($C$3+1)-INT($B7*($C$3+1)))*(LARGE(DEBIT_15HARIAN!$Y$7:$Y$31,INT($B7*($C$3+1))+1)-LARGE(DEBIT_15HARIAN!$Y$7:$Y$31,INT($B7*($C$3+1)))))))
A8: Q90 (m³/s) | B8: 0.9 | C8: =IF($C$3<1,"",IF(INT($B8*($C$3+1))<1,LARGE(DEBIT_15HARIAN!$B$7:$B$31,1),IF(INT($B8*($C$3+1))>=$C$3,LARGE(DEBIT_15HARIAN!$B$7:$B$31,$C$3),LARGE(DEBIT_15HARIAN!$B$7:$B$31,INT($B8*($C$3+1)))+($B8*($C$3+1)-INT($B8*($C$3+1)))*(LARGE(DEBIT_15HARIAN!$B$7:$B$31,INT($B8*($C$3+1))+1)-LARGE(DEBIT_15HARIAN!$B$7:$B$31,INT($B8*($C$3+1))))))) | D8: =IF($C$3<1,"",IF(INT($B8*($C$3+1))<1,LARGE(DEBIT_15HARIAN!$C$7:$C$31,1),IF(INT($B8*($C$3+1))>=$C$3,LARGE(DEBIT_15HARIAN!$C$7:$C$31,$C$3),LARGE(DEBIT_15HARIAN!$C$7:$C$31,INT($B8*($C$3+1)))+($B8*($C$3+1)-INT($B8*($C$3+1)))*(LARGE(DEBIT_15HARIAN!$C$7:$C$31,INT($B8*($C$3+1))+1)-LARGE(DEBIT_15HARIAN!$C$7:$C$31,INT($B8*($C$3+1))))))) | E8: =IF($C$3<1,"",IF(INT($B8*($C$3+1))<1,LARGE(DEBIT_15HARIAN!$D$7:$D$31,1),IF(INT($B8*($C$3+1))>=$C$3,LARGE(DEBIT_15HARIAN!$D$7:$D$31,$C$3),LARGE(DEBIT_15HARIAN!$D$7:$D$31,INT($B8*($C$3+1)))+($B8*($C$3+1)-INT($B8*($C$3+1)))*(LARGE(DEBIT_15HARIAN!$D$7:$D$31,INT($B8*($C$3+1))+1)-LARGE(DEBIT_15HARIAN!$D$7:$D$31,INT($B8*($C$3+1))))))) | F8: =IF($C$3<1,"",IF(INT($B8*($C$3+1))<1,LARGE(DEBIT_15HARIAN!$E$7:$E$31,1),IF(INT($B8*($C$3+1))>=$C$3,LARGE(DEBIT_15HARIAN!$E$7:$E$31,$C$3),LARGE(DEBIT_15HARIAN!$E$7:$E$31,INT($B8*($C$3+1)))+($B8*($C$3+1)-INT($B8*($C$3+1)))*(LARGE(DEBIT_15HARIAN!$E$7:$E$31,INT($B8*($C$3+1))+1)-LARGE(DEBIT_15HARIAN!$E$7:$E$31,INT($B8*($C$3+1))))))) | G8: =IF($C$3<1,"",IF(INT($B8*($C$3+1))<1,LARGE(DEBIT_15HARIAN!$F$7:$F$31,1),IF(INT($B8*($C$3+1))>=$C$3,LARGE(DEBIT_15HARIAN!$F$7:$F$31,$C$3),LARGE(DEBIT_15HARIAN!$F$7:$F$31,INT($B8*($C$3+1)))+($B8*($C$3+1)-INT($B8*($C$3+1)))*(LARGE(DEBIT_15HARIAN!$F$7:$F$31,INT($B8*($C$3+1))+1)-LARGE(DEBIT_15HARIAN!$F$7:$F$31,INT($B8*($C$3+1))))))) | H8: =IF($C$3<1,"",IF(INT($B8*($C$3+1))<1,LARGE(DEBIT_15HARIAN!$G$7:$G$31,1),IF(INT($B8*($C$3+1))>=$C$3,LARGE(DEBIT_15HARIAN!$G$7:$G$31,$C$3),LARGE(DEBIT_15HARIAN!$G$7:$G$31,INT($B8*($C$3+1)))+($B8*($C$3+1)-INT($B8*($C$3+1)))*(LARGE(DEBIT_15HARIAN!$G$7:$G$31,INT($B8*($C$3+1))+1)-LARGE(DEBIT_15HARIAN!$G$7:$G$31,INT($B8*($C$3+1))))))) | I8: =IF($C$3<1,"",IF(INT($B8*($C$3+1))<1,LARGE(DEBIT_15HARIAN!$H$7:$H$31,1),IF(INT($B8*($C$3+1))>=$C$3,LARGE(DEBIT_15HARIAN!$H$7:$H$31,$C$3),LARGE(DEBIT_15HARIAN!$H$7:$H$31,INT($B8*($C$3+1)))+($B8*($C$3+1)-INT($B8*($C$3+1)))*(LARGE(DEBIT_15HARIAN!$H$7:$H$31,INT($B8*($C$3+1))+1)-LARGE(DEBIT_15HARIAN!$H$7:$H$31,INT($B8*($C$3+1))))))) | J8: =IF($C$3<1,"",IF(INT($B8*($C$3+1))<1,LARGE(DEBIT_15HARIAN!$I$7:$I$31,1),IF(INT($B8*($C$3+1))>=$C$3,LARGE(DEBIT_15HARIAN!$I$7:$I$31,$C$3),LARGE(DEBIT_15HARIAN!$I$7:$I$31,INT($B8*($C$3+1)))+($B8*($C$3+1)-INT($B8*($C$3+1)))*(LARGE(DEBIT_15HARIAN!$I$7:$I$31,INT($B8*($C$3+1))+1)-LARGE(DEBIT_15HARIAN!$I$7:$I$31,INT($B8*($C$3+1))))))) | K8: =IF($C$3<1,"",IF(INT($B8*($C$3+1))<1,LARGE(DEBIT_15HARIAN!$J$7:$J$31,1),IF(INT($B8*($C$3+1))>=$C$3,LARGE(DEBIT_15HARIAN!$J$7:$J$31,$C$3),LARGE(DEBIT_15HARIAN!$J$7:$J$31,INT($B8*($C$3+1)))+($B8*($C$3+1)-INT($B8*($C$3+1)))*(LARGE(DEBIT_15HARIAN!$J$7:$J$31,INT($B8*($C$3+1))+1)-LARGE(DEBIT_15HARIAN!$J$7:$J$31,INT($B8*($C$3+1))))))) | L8: =IF($C$3<1,"",IF(INT($B8*($C$3+1))<1,LARGE(DEBIT_15HARIAN!$K$7:$K$31,1),IF(INT($B8*($C$3+1))>=$C$3,LARGE(DEBIT_15HARIAN!$K$7:$K$31,$C$3),LARGE(DEBIT_15HARIAN!$K$7:$K$31,INT($B8*($C$3+1)))+($B8*($C$3+1)-INT($B8*($C$3+1)))*(LARGE(DEBIT_15HARIAN!$K$7:$K$31,INT($B8*($C$3+1))+1)-LARGE(DEBIT_15HARIAN!$K$7:$K$31,INT($B8*($C$3+1))))))) | M8: =IF($C$3<1,"",IF(INT($B8*($C$3+1))<1,LARGE(DEBIT_15HARIAN!$L$7:$L$31,1),IF(INT($B8*($C$3+1))>=$C$3,LARGE(DEBIT_15HARIAN!$L$7:$L$31,$C$3),LARGE(DEBIT_15HARIAN!$L$7:$L$31,INT($B8*($C$3+1)))+($B8*($C$3+1)-INT($B8*($C$3+1)))*(LARGE(DEBIT_15HARIAN!$L$7:$L$31,INT($B8*($C$3+1))+1)-LARGE(DEBIT_15HARIAN!$L$7:$L$31,INT($B8*($C$3+1))))))) | N8: =IF($C$3<1,"",IF(INT($B8*($C$3+1))<1,LARGE(DEBIT_15HARIAN!$M$7:$M$31,1),IF(INT($B8*($C$3+1))>=$C$3,LARGE(DEBIT_15HARIAN!$M$7:$M$31,$C$3),LARGE(DEBIT_15HARIAN!$M$7:$M$31,INT($B8*($C$3+1)))+($B8*($C$3+1)-INT($B8*($C$3+1)))*(LARGE(DEBIT_15HARIAN!$M$7:$M$31,INT($B8*($C$3+1))+1)-LARGE(DEBIT_15HARIAN!$M$7:$M$31,INT($B8*($C$3+1))))))) | O8: =IF($C$3<1,"",IF(INT($B8*($C$3+1))<1,LARGE(DEBIT_15HARIAN!$N$7:$N$31,1),IF(INT($B8*($C$3+1))>=$C$3,LARGE(DEBIT_15HARIAN!$N$7:$N$31,$C$3),LARGE(DEBIT_15HARIAN!$N$7:$N$31,INT($B8*($C$3+1)))+($B8*($C$3+1)-INT($B8*($C$3+1)))*(LARGE(DEBIT_15HARIAN!$N$7:$N$31,INT($B8*($C$3+1))+1)-LARGE(DEBIT_15HARIAN!$N$7:$N$31,INT($B8*($C$3+1))))))) | P8: =IF($C$3<1,"",IF(INT($B8*($C$3+1))<1,LARGE(DEBIT_15HARIAN!$O$7:$O$31,1),IF(INT($B8*($C$3+1))>=$C$3,LARGE(DEBIT_15HARIAN!$O$7:$O$31,$C$3),LARGE(DEBIT_15HARIAN!$O$7:$O$31,INT($B8*($C$3+1)))+($B8*($C$3+1)-INT($B8*($C$3+1)))*(LARGE(DEBIT_15HARIAN!$O$7:$O$31,INT($B8*($C$3+1))+1)-LARGE(DEBIT_15HARIAN!$O$7:$O$31,INT($B8*($C$3+1))))))) | Q8: =IF($C$3<1,"",IF(INT($B8*($C$3+1))<1,LARGE(DEBIT_15HARIAN!$P$7:$P$31,1),IF(INT($B8*($C$3+1))>=$C$3,LARGE(DEBIT_15HARIAN!$P$7:$P$31,$C$3),LARGE(DEBIT_15HARIAN!$P$7:$P$31,INT($B8*($C$3+1)))+($B8*($C$3+1)-INT($B8*($C$3+1)))*(LARGE(DEBIT_15HARIAN!$P$7:$P$31,INT($B8*($C$3+1))+1)-LARGE(DEBIT_15HARIAN!$P$7:$P$31,INT($B8*($C$3+1))))))) | R8: =IF($C$3<1,"",IF(INT($B8*($C$3+1))<1,LARGE(DEBIT_15HARIAN!$Q$7:$Q$31,1),IF(INT($B8*($C$3+1))>=$C$3,LARGE(DEBIT_15HARIAN!$Q$7:$Q$31,$C$3),LARGE(DEBIT_15HARIAN!$Q$7:$Q$31,INT($B8*($C$3+1)))+($B8*($C$3+1)-INT($B8*($C$3+1)))*(LARGE(DEBIT_15HARIAN!$Q$7:$Q$31,INT($B8*($C$3+1))+1)-LARGE(DEBIT_15HARIAN!$Q$7:$Q$31,INT($B8*($C$3+1))))))) | S8: =IF($C$3<1,"",IF(INT($B8*($C$3+1))<1,LARGE(DEBIT_15HARIAN!$R$7:$R$31,1),IF(INT($B8*($C$3+1))>=$C$3,LARGE(DEBIT_15HARIAN!$R$7:$R$31,$C$3),LARGE(DEBIT_15HARIAN!$R$7:$R$31,INT($B8*($C$3+1)))+($B8*($C$3+1)-INT($B8*($C$3+1)))*(LARGE(DEBIT_15HARIAN!$R$7:$R$31,INT($B8*($C$3+1))+1)-LARGE(DEBIT_15HARIAN!$R$7:$R$31,INT($B8*($C$3+1))))))) | T8: =IF($C$3<1,"",IF(INT($B8*($C$3+1))<1,LARGE(DEBIT_15HARIAN!$S$7:$S$31,1),IF(INT($B8*($C$3+1))>=$C$3,LARGE(DEBIT_15HARIAN!$S$7:$S$31,$C$3),LARGE(DEBIT_15HARIAN!$S$7:$S$31,INT($B8*($C$3+1)))+($B8*($C$3+1)-INT($B8*($C$3+1)))*(LARGE(DEBIT_15HARIAN!$S$7:$S$31,INT($B8*($C$3+1))+1)-LARGE(DEBIT_15HARIAN!$S$7:$S$31,INT($B8*($C$3+1))))))) | U8: =IF($C$3<1,"",IF(INT($B8*($C$3+1))<1,LARGE(DEBIT_15HARIAN!$T$7:$T$31,1),IF(INT($B8*($C$3+1))>=$C$3,LARGE(DEBIT_15HARIAN!$T$7:$T$31,$C$3),LARGE(DEBIT_15HARIAN!$T$7:$T$31,INT($B8*($C$3+1)))+($B8*($C$3+1)-INT($B8*($C$3+1)))*(LARGE(DEBIT_15HARIAN!$T$7:$T$31,INT($B8*($C$3+1))+1)-LARGE(DEBIT_15HARIAN!$T$7:$T$31,INT($B8*($C$3+1))))))) | V8: =IF($C$3<1,"",IF(INT($B8*($C$3+1))<1,LARGE(DEBIT_15HARIAN!$U$7:$U$31,1),IF(INT($B8*($C$3+1))>=$C$3,LARGE(DEBIT_15HARIAN!$U$7:$U$31,$C$3),LARGE(DEBIT_15HARIAN!$U$7:$U$31,INT($B8*($C$3+1)))+($B8*($C$3+1)-INT($B8*($C$3+1)))*(LARGE(DEBIT_15HARIAN!$U$7:$U$31,INT($B8*($C$3+1))+1)-LARGE(DEBIT_15HARIAN!$U$7:$U$31,INT($B8*($C$3+1))))))) | W8: =IF($C$3<1,"",IF(INT($B8*($C$3+1))<1,LARGE(DEBIT_15HARIAN!$V$7:$V$31,1),IF(INT($B8*($C$3+1))>=$C$3,LARGE(DEBIT_15HARIAN!$V$7:$V$31,$C$3),LARGE(DEBIT_15HARIAN!$V$7:$V$31,INT($B8*($C$3+1)))+($B8*($C$3+1)-INT($B8*($C$3+1)))*(LARGE(DEBIT_15HARIAN!$V$7:$V$31,INT($B8*($C$3+1))+1)-LARGE(DEBIT_15HARIAN!$V$7:$V$31,INT($B8*($C$3+1))))))) | X8: =IF($C$3<1,"",IF(INT($B8*($C$3+1))<1,LARGE(DEBIT_15HARIAN!$W$7:$W$31,1),IF(INT($B8*($C$3+1))>=$C$3,LARGE(DEBIT_15HARIAN!$W$7:$W$31,$C$3),LARGE(DEBIT_15HARIAN!$W$7:$W$31,INT($B8*($C$3+1)))+($B8*($C$3+1)-INT($B8*($C$3+1)))*(LARGE(DEBIT_15HARIAN!$W$7:$W$31,INT($B8*($C$3+1))+1)-LARGE(DEBIT_15HARIAN!$W$7:$W$31,INT($B8*($C$3+1))))))) | Y8: =IF($C$3<1,"",IF(INT($B8*($C$3+1))<1,LARGE(DEBIT_15HARIAN!$X$7:$X$31,1),IF(INT($B8*($C$3+1))>=$C$3,LARGE(DEBIT_15HARIAN!$X$7:$X$31,$C$3),LARGE(DEBIT_15HARIAN!$X$7:$X$31,INT($B8*($C$3+1)))+($B8*($C$3+1)-INT($B8*($C$3+1)))*(LARGE(DEBIT_15HARIAN!$X$7:$X$31,INT($B8*($C$3+1))+1)-LARGE(DEBIT_15HARIAN!$X$7:$X$31,INT($B8*($C$3+1))))))) | Z8: =IF($C$3<1,"",IF(INT($B8*($C$3+1))<1,LARGE(DEBIT_15HARIAN!$Y$7:$Y$31,1),IF(INT($B8*($C$3+1))>=$C$3,LARGE(DEBIT_15HARIAN!$Y$7:$Y$31,$C$3),LARGE(DEBIT_15HARIAN!$Y$7:$Y$31,INT($B8*($C$3+1)))+($B8*($C$3+1)-INT($B8*($C$3+1)))*(LARGE(DEBIT_15HARIAN!$Y$7:$Y$31,INT($B8*($C$3+1))+1)-LARGE(DEBIT_15HARIAN!$Y$7:$Y$31,INT($B8*($C$3+1)))))))
